Workbook

Sheet DIAMETRE (CR,CS)
B1: DIAMETRE FIBRE COROUI | I1: DIAMETRE FIBRE COSOU
B2: D_1(mm) | C2: D_2(mm) | D2: D_3(mm) | E2: D_Moy(mm) | F2: S_(mm2) | G2: D_Moy Global(mm) | J2: D_1(mm) | K2: D_2(mm) | L2: D_3(mm) | M2: D_Moy(mm) | N2: S_(mm2) | O2: D_Moy Global(mm)
A3: Ech1 | B3: 0.205 | C3: 0.131 | D3: 0.18 | E3: =AVERAGE(B3:D3) -> 0.172 | F3: =3.14*E3*E3/4 -> 0.02322344 | G3: =AVERAGE(E3:E24) -> 0.19634848 | I3: Ech1 | J3: 0.477 | K3: 0.25 | L3: 0.36 | M3: =AVERAGE(J3:L3) -> 0.36233333 | N3: =3.14*M3*M3/4 -> 0.10305907 | O3: =AVERAGE(M3:M24) -> 0.26569697
A4: Ech2 | B4: 0.164 | C4: 0.135 | D4: 0.311 | E4: =AVERAGE(B4:D4) -> 0.20333333 | F4: =3.14*E4*E4/4 -> 0.032455389 | I4: Ech2 | J4: 0.38 | K4: 0.396 | L4: 0.436 | M4: =AVERAGE(J4:L4) -> 0.404 | N4: =3.14*M4*M4/4 -> 0.12812456
A5: Ech3 | B5: 0.166 | C5: 0.177 | D5: 0.221 | E5: =AVERAGE(B5:D5) -> 0.188 | F5: =3.14*E5*E5/4 -> 0.02774504 | I5: Ech3 | J5: 0.289 | K5: 0.23 | L5: 0.332 | M5: =AVERAGE(J5:L5) -> 0.28366667 | N5: =3.14*M5*M5/4 -> 0.063166421
A6: Ech4 | B6: 0.305 | C6: 0.349 | D6: 0.352 | E6: =AVERAGE(B6:D6) -> 0.33533333 | F6: =3.14*E6*E6/4 -> 0.088272029 | I6: Ech4 | J6: 0.101 | K6: 0.075 | L6: 0.117 | M6: =AVERAGE(J6:L6) -> 0.097666667 | N6: =3.14*M6*M6/4 -> 0.0074879406
A7: Ech5 | B7: 0.206 | C7: 0.387 | D7: 0.234 | E7: =AVERAGE(B7:D7) -> 0.27566667 | F7: =3.14*E7*E7/4 -> 0.059653807 | I7: Ech5 | J7: 0.257 | K7: 0.286 | L7: 0.24 | M7: =AVERAGE(J7:L7) -> 0.261 | N7: =3.14*M7*M7/4 -> 0.053474985
A8: Ech6 | B8: 0.268 | C8: 0.224 | D8: 0.242 | E8: =AVERAGE(B8:D8) -> 0.24466667 | F8: =3.14*E8*E8/4 -> 0.046991496 | I8: Ech6 | J8: 0.235 | K8: 0.281 | L8: 0.324 | M8: =AVERAGE(J8:L8) -> 0.28 | N8: =3.14*M8*M8/4 -> 0.061544
A9: Ech7 | B9: 0.177 | C9: 0.237 | D9: 0.27 | E9: =AVERAGE(B9:D9) -> 0.228 | F9: =3.14*E9*E9/4 -> 0.04080744 | I9: Ech7 | J9: 0.412 | K9: 0.36 | L9: 0.382 | M9: =AVERAGE(J9:L9) -> 0.38466667 | N9: =3.14*M9*M9/4 -> 0.11615523
A10: Ech8 | B10: 0.219 | C10: 0.049 | D10: 0.264 | E10: =AVERAGE(B10:D10) -> 0.17733333 | F10: =3.14*E10*E10/4 -> 0.024685982 | I10: Ech8 | J10: 0.327 | K10: 0.296 | L10: 0.262 | M10: =AVERAGE(J10:L10) -> 0.295 | N10: =3.14*M10*M10/4 -> 0.068314625
A11: Ech9 | B11: 0.543 | C11: 0.416 | D11: 0.354 | E11: =AVERAGE(B11:D11) -> 0.43766667 | F11: =3.14*E11*E11/4 -> 0.15036841 | I11: Ech9 | J11: 0.077 | K11: 0.079 | L11: 0.092 | M11: =AVERAGE(J11:L11) -> 0.082666667 | N11: =3.14*M11*M11/4 -> 0.0053645156
A12: Ech10 | B12: 0.242 | C12: 0.06 | D12: 0.221 | E12: =AVERAGE(B12:D12) -> 0.17433333 | F12: =3.14*E12*E12/4 -> 0.023857807 | I12: Ech10 | J12: 0.099 | K12: 0.261 | L12: 0.113 | M12: =AVERAGE(J12:L12) -> 0.15766667 | N12: =3.14*M12*M12/4 -> 0.019514141
A13: Ech11 | B13: 0.36 | C13: 0.494 | D13: 0.205 | E13: =AVERAGE(B13:D13) -> 0.353 | F13: =3.14*E13*E13/4 -> 0.097818065 | I13: Ech11 | J13: 0.394 | K13: 0.187 | L13: 0.121 | M13: =AVERAGE(J13:L13) -> 0.234 | N13: =3.14*M13*M13/4 -> 0.04298346
A14: Ech12 | B14: 0.152 | C14: 0.15 | D14: 0.161 | E14: =AVERAGE(B14:D14) -> 0.15433333 | F14: =3.14*E14*E14/4 -> 0.018697741 | I14: Ech12 | J14: 0.118 | K14: 0.106 | L14: 0.173 | M14: =AVERAGE(J14:L14) -> 0.13233333 | N14: =3.14*M14*M14/4 -> 0.013747007
A15: Ech13 | B15: 0.139 | C15: 0.19 | D15: 0.258 | E15: =AVERAGE(B15:D15) -> 0.19566667 | F15: =3.14*E15*E15/4 -> 0.030054074 | I15: Ech13 | J15: 0.252 | K15: 0.32 | L15: 0.095 | M15: =AVERAGE(J15:L15) -> 0.22233333 | N15: =3.14*M15*M15/4 -> 0.038804207
... A24: Ech22 | B24: 0.224 | C24: 0.291 | D24: 0.193 | E24: =AVERAGE(B24:D24) -> 0.236 | F24: =3.14*E24*E24/4 -> 0.04372136 | I24: Ech22 | J24: 0.087 | K24: 0.138 | L24: 0.05 | M24: =AVERAGE(J24:L24) -> 0.091666667 | N24: =3.14*M24*M24/4 -> 0.0065961806

Sheet COROUI
A1: Elong.(mm) - Ech 1 | B1: Force(N) - Ech 1 | C1: Def | D1: Cont | E1: Cont(max) | F1: Def rupt | G1: E(mpa) | I1: Elong.(mm) - Ech 2 | J1: Force(N) - Ech 2 | K1: Def | L1: Cont | M1: Cont(max) | N1: Def rupt | O1: E(mpa) | Q1: Elong.(mm) - Ech 3 | R1: Force(N) - Ech 3 | S1: Def | T1: Cont | U1: Cont(max) | V1: Def rupt | W1: E(mpa) | Y1: Elong.(mm) - Ech 4 | Z1: Elong.(mm) - Ech 4 | AA1: Force(N) - Ech 4 | AB1: Def | AC1: Cont | AD1: Cont(max) | AE1: Def rupt | AF1: E(mpa) | AH1: Elong.(mm) - Ech 5 | AI1: Elong.(mm) - Ech 5 | AJ1: Force(N) - Ech 5 | AK1: Def | AL1: Cont | AM1: Cont(max) | AN1: Def rupt | AO1: E(mpa) | AQ1: Elong.(mm) - Ech 6 | AR1: Force(N) - Ech 6 | AS1: Def | AT1: Cont | AU1: Cont(max) | AV1: Def rupt | AW1: E(mpa) | AY1: Elong.(mm) - Ech 7 | AZ1: Force(N) - Ech 7 | BA1: Def | BB1: Cont | BC1: Cont(max) | BD1: Def rupt | BE1: E(mpa) | BG1: Elong.(mm) - Ech 8 | BH1: Force(N) - Ech 8 | BI1: Def | BJ1: Cont | BK1: Cont(max) | BL1: Def rupt | BM1: E(mpa) | BO1: Elong.(mm) - Ech 9 | BP1: Force(N) - Ech 9 | BQ1: Def | BR1: Cont | BS1: Cont(max) | BT1: Def rupt | BU1: E(mpa) | BW1: Elong.(mm) - Ech 10 | BX1: Force(N) - Ech 10 | BY1: Def | BZ1: Cont | CA1: Cont(max) | CB1: Def rupt | CC1: E(mpa) | CE1: Elong.(mm) - Ech 11 | CF1: Force(N) - Ech 11 | CG1: Def | CH1: Cont | CI1: Cont(max) | CJ1: Def rupt | CK1: E(mpa) | CM1: Elong.(mm) - Ech 12 | CN1: Elong.(mm) - Ech 12 | CO1: Force(N) - Ech 12 | CP1: Def | CQ1: Cont | CR1: Cont(max) | CS1: Def rupt | CT1: E(mpa) | CV1: Elong.(mm) - Ech 13 | CW1: Force(N) - Ech 13 | CX1: Def | CY1: Cont | CZ1: Cont(max) | DA1: Def rupt | DB1: E(mpa) | DD1: Elong.(mm) - Ech 14 | DE1: Force(N) - Ech 14 | DF1: Def | DG1: Cont | DH1: Cont(max) | DI1: Def rupt | DJ1: E(mpa) | DL1: Elong.(mm) - Ech 15 | DM1: Force(N) - Ech 15 | DN1: Def | DO1: Cont | DP1: Cont(max) | DQ1: Def rupt | DR1: E(mpa) | DT1: Elong.(mm) - Ech 16 | DU1: Force(N) - Ech 16 | DV1: Def | DW1: Cont | DX1: Cont(max) | DY1: Def rupt | DZ1: E(mpa) | EB1: Elong.(mm) - Ech 17 | EC1: Force(N) - Ech 17 | ED1: Def | EE1: Cont | EF1: Cont(max) | EG1: Def rupt | EH1: E(mpa) | EJ1: Elong.(mm) - Ech 18 | EK1: Force(N) - Ech 18 | EL1: Def | EM1: Cont | EN1: Cont(max) | EO1: Def rupt | EP1: E(mpa) | ER1: Elong.(mm) - Ech 19 | ES1: Force(N) - Ech 19 | ET1: Def | EU1: Cont | EV1: Cont(max) | EW1: Def rupt | EX1: E(mpa) | EZ1: Elong.(mm) - Ech 20 | FA1: Elong.(mm) - Ech 20 | FB1: Force(N) - Ech 20 | FC1: Def | FD1: Cont | FE1: Cont(max) | FF1: Def rupt | FG1: E(mpa) | FI1: Elong.(mm) - Ech 21 | FJ1: Force(N) - Ech 21 | FK1: Def | FL1: Cont | FM1: Cont(max) | FN1: Def rupt | FO1: E(mpa) | FQ1: Elong.(mm) - Ech 22 | FR1: Elong.(mm) - Ech 22 | FS1: Force(N) - Ech 22 | FT1: Def | FU1: Cont | FV1: Cont(max) | FW1: Def rupt | FX1: E(mpa)
A2: 0 | B2: 0 | C2: =A2/20 -> 0 | D2: =B2/0.023 -> 0 | E2: =MAX(D2:D329) -> 22.73913 | F2: =C5 -> 0.01425 | G2: 2712.6 | I2: 0 | J2: 0 | K2: =I2/20 -> 0 | L2: =J2/0.032 -> 0 | M2: =MAX(L2:L329) -> 79.40625 | N2: =K7 -> 0.02295 | O2: 8186.2 | Q2: 0 | R2: 0 | S2: =Q2/20 -> 0 | T2: =R2/0.028 -> 0 | U2: =MAX(T2:T329) -> 51.142857 | V2: =S9 -> 0.0281 | W2: 2532.3 | Y2: 0 | Z2: =Y4-0.195 -> 0 | AA2: 0 | AB2: =Z2/20 -> 0 | AC2: =AA2/0.088 -> 0 | AD2: =MAX(AC2:AC329) -> 18.420455 | AE2: =AB10 -> 0.029 | AF2: 679.98 | AH2: 0 | AI2: =AH3-0.155 -> 0 | AJ2: 0 | AK2: =AI2/20 -> 0 | AL2: =AJ2/0.06 -> 0 | AM2: =MAX(AL2:AL329) -> 43.933333 | AN2: =AK8 -> 0.02125 | AO2: 1643.4 | AQ2: 0 | AR2: 0 | AS2: =AQ2/20 -> 0 | AT2: =AR2/0.047 -> 0 | AU2: =MAX(AT2:AT329) -> 80.595745 | AV2: =AS8 -> 0.02175 | AW2: 5635 | AY2: 0 | AZ2: 0 | BA2: =AY2/20 -> 0 | BB2: =AZ2/0.041 -> 0 | BC2: =MAX(BB2:BB329) -> 102.92683 | BD2: =BA9 -> 0.02775 | BE2: 4946.5 | BG2: 0 | BH2: 0 | BI2: =BG2/20 -> 0 | BJ2: =BH2/0.025 -> 0 | BK2: =MAX(BJ2:BJ329) -> 244.04 | BL2: =BI16 -> 0.05465 | BM2: 5260.6 | BO2: 0 | BP2: 0 | BQ2: =BO2/20 -> 0 | BR2: =BP2/0.015 -> 0 | BS2: =MAX(BR2:BR329) -> 76.533333 | BT2: =BQ7 -> 0.02275 | BU2: 3474 | BW2: 0 | BX2: 0 | BY2: =BW2/20 -> 0 | BZ2: =BX2/0.24 -> 0 | CA2: =MAX(BZ2:BZ329) -> 16.233333 | CB2: =BY15 -> 0.05025 | CC2: 369.89 | CE2: 0 | CF2: 0 | CG2: =CE2/20 -> 0 | CH2: =CF2/0.098 -> 0 | CI2: =MAX(CH2:CH329) -> 15.295918 | CJ2: =CG10 -> 0.03375 | CK2: 629.37 | CM2: 0 | CN2: =CM4-0.231 -> 0 | CO2: 0 | CP2: =CN2/20 -> 0 | CQ2: =CO2/0.019 -> 0 | CR2: =MAX(CQ2:CQ329) -> 58.894737 | CS2: =CP8 -> 0.0207 | CT2: 3988.8 | CV2: 0 | CW2: 0 | CX2: =CV2/20 -> 0 | CY2: =CW2/0.03 -> 0 | CZ2: =MAX(CY2:CY329) -> 161.83333 | DA2: =CX14 -> 0.0495 | DB2: 4034.9 | DD2: 0 | DE2: 0 | DF2: =DD2/20 -> 0 | DG2: =DE2/0.017 -> 0 | DH2: =MAX(DG2:DG329) -> 252.52941 | DI2: =DF9 -> 0.02905 | DJ2: 11467 | DL2: 0 | DM2: 0 | DN2: =DL2/20 -> 0 | DO2: =DM2/0.007 -> 0 | DP2: =MAX(DO2:DO329) -> 560.14286 | DQ2: =DN19 -> 0.059 | DR2: 13840 | DT2: 0 | DU2: 0 | DV2: =DT2/20 -> 0 | DW2: =DU2/0.008 -> 0 | DX2: =MAX(DW2:DW329) -> 455.5 | DY2: =DV15 -> 0.049 | DZ2: 15077 | EB2: 0 | EC2: 0 | ED2: =EB2/20 -> 0 | EE2: =EC2/0.015 -> 0 | EF2: =MAX(EE2:EE329) -> 224.4 | EG2: =ED12 -> 0.03955 | EH2: 8195.7 | EJ2: 0 | EK2: 0 | EL2: =EJ2/20 -> 0 | EM2: =EK2/0.01 -> 0 | EN2: =MAX(EM2:EM329) -> 264.3 | EO2: =EL7 -> 0.0223 | EP2: 19089 | ER2: 0 | ES2: 0 | ET2: =ER2/20 -> 0 | EU2: =ES2/0.022 -> 0 | EV2: =MAX(EU2:EU329) -> 180.31818 | EW2: =ET7 -> 0.0235 | EX2: 13449 | EZ2: 0 | FA2: =EZ3-0.155 -> 0 | FB2: 0 | FC2: =FA2/20 -> 0 | FD2: =FB2/0.002 -> 0 | FE2: =MAX(FD2:FD329) -> 806.5 | FF2: =FC6 -> 0.015 | FG2: 49307 | FI2: 0 | FJ2: 0 | FK2: =FI2/20 -> 0 | FL2: =FJ2/0.012 -> 0 | FM2: =MAX(FL2:FL329) -> 453.16667 | FN2: =FK7 -> 0.01975 | FO2: 30189 | FQ2: 0.004 | FR2: =FQ2-0.004 -> 0 | FS2: 0 | FT2: =FR2/20 -> 0 | FU2: =FS2/0.044 -> 0 | FV2: =MAX(FU2:FU329) -> 55.295455 | FW2: =FT10 -> 0.0368 | FX2: 2354.2
A3: 0.16 | B3: 0.133 | C3: =A3/20 -> 0.008 | D3: =B3/0.023 -> 5.7826087 | I3: 0.16 | J3: 0.236 | K3: =I3/20 -> 0.008 | L3: =J3/0.032 -> 7.375 | Q3: 0.152 | R3: 0.079 | S3: =Q3/20 -> 0.0076 | T3: =R3/0.028 -> 2.8214286 | Y3: 0.085 | Z3: =Y5-0.195 -> 0.084 | AA3: 0.086 | AB3: =Z3/20 -> 0.0042 | AC3: =AA3/0.088 -> 0.97727273 | AH3: 0.155 | AI3: =AH4-0.155 -> 0.055 | AJ3: 0.103 | AK3: =AI3/20 -> 0.00275 | AL3: =AJ3/0.06 -> 1.7166667 | AQ3: 0.165 | AR3: 0.4 | AS3: =AQ3/20 -> 0.00825 | AT3: =AR3/0.047 -> 8.5106383 | AY3: 0.14 | AZ3: 0.192 | BA3: =AY3/20 -> 0.007 | BB3: =AZ3/0.041 -> 4.6829268 | BG3: 0.152 | BH3: 0.084 | BI3: =BG3/20 -> 0.0076 | BJ3: =BH3/0.025 -> 3.36 | BO3: 0.156 | BP3: 0.101 | BQ3: =BO3/20 -> 0.0078 | BR3: =BP3/0.015 -> 6.7333333 | BW3: 0.154 | BX3: 0.126 | BY3: =BW3/20 -> 0.0077 | BZ3: =BX3/0.24 -> 0.525 | CE3: 0.167 | CF3: 0.113 | CG3: =CE3/20 -> 0.00835 | CH3: =CF3/0.098 -> 1.1530612 | CM3: 0.16 | CN3: =CM5-0.231 -> 0.069 | CO3: 0.101 | CP3: =CN3/20 -> 0.00345 | CQ3: =CO3/0.019 -> 5.3157895 | CV3: 0.158 | CW3: 0.172 | CX3: =CV3/20 -> 0.0079 | CY3: =CW3/0.03 -> 5.7333333 | DD3: 0.155 | DE3: 0.317 | DF3: =DD3/20 -> 0.00775 | DG3: =DE3/0.017 -> 18.647059 | DL3: 0.152 | DM3: 0.153 | DN3: =DL3/20 -> 0.0076 | DO3: =DM3/0.007 -> 21.857143 | DT3: 0.142 | DU3: 0.172 | DV3: =DT3/20 -> 0.0071 | DW3: =DU3/0.008 -> 21.5 | EB3: 0.159 | EC3: 0.135 | ED3: =EB3/20 -> 0.00795 | EE3: =EC3/0.015 -> 9 | EJ3: 0.155 | EK3: 0.295 | EL3: =EJ3/20 -> 0.00775 | EM3: =EK3/0.01 -> 29.5 | ER3: 0.169 | ES3: 0.63 | ET3: =ER3/20 -> 0.00845 | EU3: =ES3/0.022 -> 28.636364 | EZ3: 0.155 | FA3: =EZ4-0.155 -> 0.069 | FB3: 0.155 | FC3: =FA3/20 -> 0.00345 | FD3: =FB3/0.002 -> 77.5 | FI3: 0.114 | FJ3: 0.417 | FK3: =FI3/20 -> 0.0057 | FL3: =FJ3/0.012 -> 34.75 | FQ3: 0.228 | FR3: =FQ3-0.004 -> 0.224 | FS3: 0.179 | FT3: =FR3/20 -> 0.0112 | FU3: =FS3/0.044 -> 4.0681818
A4: 0.224 | B4: 0.329 | C4: =A4/20 -> 0.0112 | D4: =B4/0.023 -> 14.304348 | I4: 0.255 | J4: 0.646 | K4: =I4/20 -> 0.01275 | L4: =J4/0.032 -> 20.1875 | Q4: 0.222 | R4: 0.224 | S4: =Q4/20 -> 0.0111 | T4: =R4/0.028 -> 8 | Y4: 0.195 | Z4: =Y6-0.195 -> 0.148 | AA4: 0.209 | AB4: =Z4/20 -> 0.0074 | AC4: =AA4/0.088 -> 2.375 | AH4: 0.21 | AI4: =AH5-0.155 -> 0.125 | AJ4: 0.337 | AK4: =AI4/20 -> 0.00625 | AL4: =AJ4/0.06 -> 5.6166667 | AQ4: 0.165 | AR4: 0.797 | AS4: =AQ4/20 -> 0.00825 | AT4: =AR4/0.047 -> 16.957447 | AY4: 0.212 | AZ4: 0.537 | BA4: =AY4/20 -> 0.0106 | BB4: =AZ4/0.041 -> 13.097561 | BG4: 0.224 | BH4: 0.251 | BI4: =BG4/20 -> 0.0112 | BJ4: =BH4/0.025 -> 10.04 | BO4: 0.237 | BP4: 0.275 | BQ4: =BO4/20 -> 0.01185 | BR4: =BP4/0.015 -> 18.333333 | BW4: 0.222 | BX4: 0.326 | BY4: =BW4/20 -> 0.0111 | BZ4: =BX4/0.24 -> 1.3583333 | CE4: 0.235 | CF4: 0.265 | CG4: =CE4/20 -> 0.01175 | CH4: =CF4/0.098 -> 2.7040816 | CM4: 0.231 | CN4: =CM6-0.231 -> 0.148 | CO4: 0.277 | CP4: =CN4/20 -> 0.0074 | CQ4: =CO4/0.019 -> 14.578947 | CV4: 0.223 | CW4: 0.442 | CX4: =CV4/20 -> 0.01115 | CY4: =CW4/0.03 -> 14.733333 | DD4: 0.236 | DE4: 0.787 | DF4: =DD4/20 -> 0.0118 | DG4: =DE4/0.017 -> 46.294118 | DL4: 0.222 | DM4: 0.385 | DN4: =DL4/20 -> 0.0111 | DO4: =DM4/0.007 -> 55 | DT4: 0.212 | DU4: 0.459 | DV4: =DT4/20 -> 0.0106 | DW4: =DU4/0.008 -> 57.375 | EB4: 0.224 | EC4: 0.358 | ED4: =EB4/20 -> 0.0112 | EE4: =EC4/0.015 -> 23.866667 | EJ4: 0.217 | EK4: 0.788 | EL4: =EJ4/20 -> 0.01085 | EM4: =EK4/0.01 -> 78.8 | ER4: 0.22 | ES4: 1.457 | ET4: =ER4/20 -> 0.011 | EU4: =ES4/0.022 -> 66.227273 | EZ4: 0.224 | FA4: =EZ5-0.155 -> 0.145 | FB4: 0.452 | FC4: =FA4/20 -> 0.00725 | FD4: =FB4/0.002 -> 226 | FI4: 0.184 | FJ4: 1.158 | FK4: =FI4/20 -> 0.0092 | FL4: =FJ4/0.012 -> 96.5 | FQ4: 0.3 | FR4: =FQ4-0.004 -> 0.296 | FS4: 0.432 | FT4: =FR4/20 -> 0.0148 | FU4: =FS4/0.044 -> 9.8181818
A5: 0.285 | B5: 0.523 | C5: =A5/20 -> 0.01425 | D5: =B5/0.023 -> 22.73913 | I5: 0.32 | J5: 1.163 | K5: =I5/20 -> 0.016 | L5: =J5/0.032 -> 36.34375 | Q5: 0.295 | R5: 0.427 | S5: =Q5/20 -> 0.01475 | T5: =R5/0.028 -> 15.25 | Y5: 0.279 | Z5: =Y7-0.195 -> 0.21 | AA5: 0.375 | AB5: =Z5/20 -> 0.0105 | AC5: =AA5/0.088 -> 4.2613636 | AH5: 0.28 | AI5: =AH6-0.155 -> 0.217 | AJ5: 0.741 | AK5: =AI5/20 -> 0.01085 | AL5: =AJ5/0.06 -> 12.35 | AQ5: 0.302 | AR5: 1.467 | AS5: =AQ5/20 -> 0.0151 | AT5: =AR5/0.047 -> 31.212766 | AY5: 0.276 | AZ5: 1.04 | BA5: =AY5/20 -> 0.0138 | BB5: =AZ5/0.041 -> 25.365854 | BG5: 0.224 | BH5: 0.417 | BI5: =BG5/20 -> 0.0112 | BJ5: =BH5/0.025 -> 16.68 | BO5: 0.32 | BP5: 0.528 | BQ5: =BO5/20 -> 0.016 | BR5: =BP5/0.015 -> 35.2 | BW5: 0.295 | BX5: 0.586 | BY5: =BW5/20 -> 0.01475 | BZ5: =BX5/0.24 -> 2.4416667 | CE5: 0.31 | CF5: 0.464 | CG5: =CE5/20 -> 0.0155 | CH5: =CF5/0.098 -> 4.7346939 | CM5: 0.3 | CN5: =CM7-0.231 -> 0.215 | CO5: 0.518 | CP5: =CN5/20 -> 0.01075 | CQ5: =CO5/0.019 -> 27.263158 | CV5: 0.302 | CW5: 0.822 | CX5: =CV5/20 -> 0.0151 | CY5: =CW5/0.03 -> 27.4 | DD5: 0.3 | DE5: 1.381 | DF5: =DD5/20 -> 0.015 | DG5: =DE5/0.017 -> 81.235294 | DL5: 0.28 | DM5: 0.669 | DN5: =DL5/20 -> 0.014 | DO5: =DM5/0.007 -> 95.571429 | DT5: 0.283 | DU5: 0.827 | DV5: =DT5/20 -> 0.01415 | DW5: =DU5/0.008 -> 103.375 | EB5: 0.309 | EC5: 0.695 | ED5: =EB5/20 -> 0.01545 | EE5: =EC5/0.015 -> 46.333333 | EJ5: 0.282 | EK5: 1.447 | EL5: =EJ5/20 -> 0.0141 | EM5: =EK5/0.01 -> 144.7 | ER5: 0.299 | ES5: 2.538 | ET5: =ER5/20 -> 0.01495 | EU5: =ES5/0.022 -> 115.36364 | EZ5: 0.3 | FA5: =EZ6-0.155 -> 0.23 | FB5: 0.946 | FC5: =FA5/20 -> 0.0115 | FD5: =FB5/0.002 -> 473 | FI5: 0.254 | FJ5: 2.303 | FK5: =FI5/20 -> 0.0127 | FL5: =FJ5/0.012 -> 191.91667 | FQ5: 0.362 | FR5: =FQ5-0.004 -> 0.358 | FS5: 0.741 | FT5: =FR5/20 -> 0.0179 | FU5: =FS5/0.044 -> 16.840909
A6: 0.35 | B6: 0.522 | C6: =A6/20 -> 0.0175 | D6: =B6/0.023 -> 22.695652 | I6: 0.377 | J6: 1.778 | K6: =I6/20 -> 0.01885 | L6: =J6/0.032 -> 55.5625 | Q6: 0.357 | R6: 0.682 | S6: =Q6/20 -> 0.01785 | T6: =R6/0.028 -> 24.357143 | Y6: 0.343 | Z6: =Y8-0.195 -> 0.28 | AA6: 0.589 | AB6: =Z6/20 -> 0.014 | AC6: =AA6/0.088 -> 6.6931818 | AH6: 0.372 | AI6: =AH7-0.155 -> 0.3 | AJ6: 1.322 | AK6: =AI6/20 -> 0.015 | AL6: =AJ6/0.06 -> 22.033333 | AQ6: 0.365 | AR6: 2.266 | AS6: =AQ6/20 -> 0.01825 | AT6: =AR6/0.047 -> 48.212766 | AY6: 0.34 | AZ6: 1.7 | BA6: =AY6/20 -> 0.017 | BB6: =AZ6/0.041 -> 41.463415 | BG6: 0.342 | BH6: 0.721 | BI6: =BG6/20 -> 0.0171 | BJ6: =BH6/0.025 -> 28.84 | BO6: 0.32 | BP6: 0.78 | BQ6: =BO6/20 -> 0.016 | BR6: =BP6/0.015 -> 52 | BW6: 0.343 | BX6: 0.891 | BY6: =BW6/20 -> 0.01715 | BZ6: =BX6/0.24 -> 3.7125 | CE6: 0.372 | CF6: 0.704 | CG6: =CE6/20 -> 0.0186 | CH6: =CF6/0.098 -> 7.1836735 | CM6: 0.379 | CN6: =CM8-0.231 -> 0.274 | CO6: 0.827 | CP6: =CN6/20 -> 0.0137 | CQ6: =CO6/0.019 -> 43.526316 | CV6: 0.378 | CW6: 1.297 | CX6: =CV6/20 -> 0.0189 | CY6: =CW6/0.03 -> 43.233333 | DD6: 0.36 | DE6: 2.097 | DF6: =DD6/20 -> 0.018 | DG6: =DE6/0.017 -> 123.35294 | DL6: 0.341 | DM6: 1.003 | DN6: =DL6/20 -> 0.01705 | DO6: =DM6/0.007 -> 143.28571 | DT6: 0.343 | DU6: 1.268 | DV6: =DT6/20 -> 0.01715 | DW6: =DU6/0.008 -> 158.5 | EB6: 0.38 | EC6: 1.118 | ED6: =EB6/20 -> 0.019 | EE6: =EC6/0.015 -> 74.533333 | EJ6: 0.37 | EK6: 2.327 | EL6: =EJ6/20 -> 0.0185 | EM6: =EK6/0.01 -> 232.7 | ER6: 0.39 | ES6: 3.933 | ET6: =ER6/20 -> 0.0195 | EU6: =ES6/0.022 -> 178.77273 | EZ6: 0.385 | FA6: =EZ7-0.155 -> 0.3 | FB6: 1.613 | FC6: =FA6/20 -> 0.015 | FD6: =FB6/0.002 -> 806.5 | FI6: 0.325 | FJ6: 3.847 | FK6: =FI6/20 -> 0.01625 | FL6: =FJ6/0.012 -> 320.58333 | FQ6: 0.43 | FR6: =FQ6-0.004 -> 0.426 | FS6: 1.128 | FT6: =FR6/20 -> 0.0213 | FU6: =FS6/0.044 -> 25.636364
A7: 0.422 | B7: 0.522 | C7: =A7/20 -> 0.0211 | D7: =B7/0.023 -> 22.695652 | I7: 0.459 | J7: 2.541 | K7: =I7/20 -> 0.02295 | L7: =J7/0.032 -> 79.40625 | Q7: 0.357 | R7: 0.937 | S7: =Q7/20 -> 0.01785 | T7: =R7/0.028 -> 33.464286 | Y7: 0.405 | Z7: =Y9-0.195 -> 0.352 | AA7: 0.849 | AB7: =Z7/20 -> 0.0176 | AC7: =AA7/0.088 -> 9.6477273 | AH7: 0.455 | AI7: =AH8-0.155 -> 0.36 | AJ7: 2.038 | AK7: =AI7/20 -> 0.018 | AL7: =AJ7/0.06 -> 33.966667 | AQ7: 0.435 | AR7: 3.227 | AS7: =AQ7/20 -> 0.02175 | AT7: =AR7/0.047 -> 68.659574 | AY7: 0.402 | AZ7: 2.504 | BA7: =AY7/20 -> 0.0201 | BB7: =AZ7/0.041 -> 61.073171 | BG7: 0.422 | BH7: 1.138 | BI7: =BG7/20 -> 0.0211 | BJ7: =BH7/0.025 -> 45.52 | BO7: 0.455 | BP7: 1.148 | BQ7: =BO7/20 -> 0.02275 | BR7: =BP7/0.015 -> 76.533333 | BW7: 0.411 | BX7: 1.268 | BY7: =BW7/20 -> 0.02055 | BZ7: =BX7/0.24 -> 5.2833333 | CE7: 0.447 | CF7: 0.969 | CG7: =CE7/20 -> 0.02235 | CH7: =CF7/0.098 -> 9.8877551 | CM7: 0.446 | CN7: =CM9-0.231 -> 0.337 | CO7: 1.091 | CP7: =CN7/20 -> 0.01685 | CQ7: =CO7/0.019 -> 57.421053 | CV7: 0.455 | CW7: 1.864 | CX7: =CV7/20 -> 0.02275 | CY7: =CW7/0.03 -> 62.133333 | DD7: 0.429 | DE7: 2.94 | DF7: =DD7/20 -> 0.02145 | DG7: =DE7/0.017 -> 172.94118 | DL7: 0.411 | DM7: 1.388 | DN7: =DL7/20 -> 0.02055 | DO7: =DM7/0.007 -> 198.28571 | DT7: 0.408 | DU7: 1.781 | DV7: =DT7/20 -> 0.0204 | DW7: =DU7/0.008 -> 222.625 | EB7: 0.44 | EC7: 1.595 | ED7: =EB7/20 -> 0.022 | EE7: =EC7/0.015 -> 106.33333 | EJ7: 0.446 | EK7: 2.643 | EL7: =EJ7/20 -> 0.0223 | EM7: =EK7/0.01 -> 264.3 | ER7: 0.47 | ES7: 3.967 | ET7: =ER7/20 -> 0.0235 | EU7: =ES7/0.022 -> 180.31818 | EZ7: 0.455 | FA7: =EZ8-0.155 -> 0.382 | FB7: 1.613 | FC7: =FA7/20 -> 0.0191 | FD7: =FB7/0.002 -> 806.5 | FI7: 0.395 | FJ7: 5.438 | FK7: =FI7/20 -> 0.01975 | FL7: =FJ7/0.012 -> 453.16667 | FQ7: 0.502 | FR7: =FQ7-0.004 -> 0.498 | FS7: 1.586 | FT7: =FR7/20 -> 0.0249 | FU7: =FS7/0.044 -> 36.045455
A8: 0.485 | B8: 0.39 | C8: =A8/20 -> 0.02425 | D8: =B8/0.023 -> 16.956522 | I8: 0.527 | J8: 2.305 | K8: =I8/20 -> 0.02635 | L8: =J8/0.032 -> 72.03125 | Q8: 0.48 | R8: 1.197 | S8: =Q8/20 -> 0.024 | T8: =R8/0.028 -> 42.75 | Y8: 0.475 | Z8: =Y10-0.195 -> 0.445 | AA8: 1.099 | AB8: =Z8/20 -> 0.02225 | AC8: =AA8/0.088 -> 12.488636 | AH8: 0.515 | AI8: =AH9-0.155 -> 0.425 | AJ8: 2.636 | AK8: =AI8/20 -> 0.02125 | AL8: =AJ8/0.06 -> 43.933333 | AQ8: 0.435 | AR8: 3.788 | AS8: =AQ8/20 -> 0.02175 | AT8: =AR8/0.047 -> 80.595745 | AY8: 0.469 | AZ8: 3.315 | BA8: =AY8/20 -> 0.02345 | BB8: =AZ8/0.041 -> 80.853659 | BG8: 0.48 | BH8: 1.574 | BI8: =BG8/20 -> 0.024 | BJ8: =BH8/0.025 -> 62.96 | BO8: 0.524 | BP8: 1.048 | BQ8: =BO8/20 -> 0.0262 | BR8: =BP8/0.015 -> 69.866667 | BW8: 0.48 | BX8: 1.589 | BY8: =BW8/20 -> 0.024 | BZ8: =BX8/0.24 -> 6.6208333 | CE8: 0.522 | CF8: 1.153 | CG8: =CE8/20 -> 0.0261 | CH8: =CF8/0.098 -> 11.765306 | CM8: 0.505 | CN8: =CM10-0.231 -> 0.414 | CO8: 1.119 | CP8: =CN8/20 -> 0.0207 | CQ8: =CO8/0.019 -> 58.894737 | CV8: 0.515 | CW8: 2.322 | CX8: =CV8/20 -> 0.02575 | CY8: =CW8/0.03 -> 77.4 | DD8: 0.514 | DE8: 3.631 | DF8: =DD8/20 -> 0.0257 | DG8: =DE8/0.017 -> 213.58824 | DL8: 0.482 | DM8: 1.656 | DN8: =DL8/20 -> 0.0241 | DO8: =DM8/0.007 -> 236.57143 | DT8: 0.477 | DU8: 2.204 | DV8: =DT8/20 -> 0.02385 | DW8: =DU8/0.008 -> 275.5 | EB8: 0.502 | EC8: 1.998 | ED8: =EB8/20 -> 0.0251 | EE8: =EC8/0.015 -> 133.2 | EJ8: 0.507 | EK8: 2.349 | EL8: =EJ8/20 -> 0.02535 | EM8: =EK8/0.01 -> 234.9 | ER8: 0.547 | ES8: 3.529 | ET8: =ER8/20 -> 0.02735 | EU8: =ES8/0.022 -> 160.40909 | EZ8: 0.537 | FA8: =EZ9-0.155 -> 0.472 | FB8: 1.462 | FC8: =FA8/20 -> 0.0236 | FD8: =FB8/0.002 -> 731 | FI8: 0.46 | FJ8: 5.019 | FK8: =FI8/20 -> 0.023 | FL8: =FJ8/0.012 -> 418.25 | FQ8: 0.58 | FR8: =FQ8-0.004 -> 0.576 | FS8: 1.903 | FT8: =FR8/20 -> 0.0288 | FU8: =FS8/0.044 -> 43.25
A9: 0.554 | B9: 0.194 | C9: =A9/20 -> 0.0277 | D9: =B9/0.023 -> 8.4347826 | I9: 0.587 | J9: 1.893 | K9: =I9/20 -> 0.02935 | L9: =J9/0.032 -> 59.15625 | Q9: 0.562 | R9: 1.432 | S9: =Q9/20 -> 0.0281 | T9: =R9/0.028 -> 51.142857 | Y9: 0.547 | Z9: =Y11-0.195 -> 0.517 | AA9: 1.359 | AB9: =Z9/20 -> 0.02585 | AC9: =AA9/0.088 -> 15.443182 | AH9: 0.58 | AI9: =AH10-0.155 -> 0.506 | AJ9: 2.491 | AK9: =AI9/20 -> 0.0253 | AL9: =AJ9/0.06 -> 41.516667 | AQ9: 0.562 | AR9: 3.523 | AS9: =AQ9/20 -> 0.0281 | AT9: =AR9/0.047 -> 74.957447 | AY9: 0.555 | AZ9: 4.22 | BA9: =AY9/20 -> 0.02775 | BB9: =AZ9/0.041 -> 102.92683 | BG9: 0.56 | BH9: 2.06 | BI9: =BG9/20 -> 0.028 | BJ9: =BH9/0.025 -> 82.4 | BO9: 0.587 | BP9: 0.875 | BQ9: =BO9/20 -> 0.02935 | BR9: =BP9/0.015 -> 58.333333 | BW9: 0.562 | BX9: 1.903 | BY9: =BW9/20 -> 0.0281 | BZ9: =BX9/0.24 -> 7.9291667 | CE9: 0.6 | CF9: 1.337 | CG9: =CE9/20 -> 0.03 | CH9: =CF9/0.098 -> 13.642857 | CM9: 0.568 | CN9: =CM11-0.231 -> 0.474 | CO9: 0.942 | CP9: =CN9/20 -> 0.0237 | CQ9: =CO9/0.019 -> 49.578947 | CV9: 0.602 | CW9: 2.771 | CX9: =CV9/20 -> 0.0301 | CY9: =CW9/0.03 -> 92.366667 | DD9: 0.581 | DE9: 4.293 | DF9: =DD9/20 -> 0.02905 | DG9: =DE9/0.017 -> 252.52941 | DL9: 0.561 | DM9: 1.9 | DN9: =DL9/20 -> 0.02805 | DO9: =DM9/0.007 -> 271.42857 | DT9: 0.55 | DU9: 2.575 | DV9: =DT9/20 -> 0.0275 | DW9: =DU9/0.008 -> 321.875 | EB9: 0.57 | EC9: 2.369 | ED9: =EB9/20 -> 0.0285 | EE9: =EC9/0.015 -> 157.93333 | EJ9: 0.57 | EK9: 1.857 | EL9: =EJ9/20 -> 0.0285 | EM9: =EK9/0.01 -> 185.7 | ER9: 0.619 | ES9: 2.896 | ET9: =ER9/20 -> 0.03095 | EU9: =ES9/0.022 -> 131.63636 | EZ9: 0.627 | FA9: =EZ10-0.155 -> 0.55 | FB9: 1.163 | FC9: =FA9/20 -> 0.0275 | FD9: =FB9/0.002 -> 581.5 | FI9: 0.546 | FJ9: 4.281 | FK9: =FI9/20 -> 0.0273 | FL9: =FJ9/0.012 -> 356.75 | FQ9: 0.58 | FR9: =FQ9-0.004 -> 0.576 | FS9: 2.151 | FT9: =FR9/20 -> 0.0288 | FU9: =FS9/0.044 -> 48.886364
A10: 0.625 | B10: 0.001 | C10: =A10/20 -> 0.03125 | D10: =B10/0.023 -> 0.043478261 | I10: 0.652 | J10: 1.376 | K10: =I10/20 -> 0.0326 | L10: =J10/0.032 -> 43 | Q10: 0.64 | R10: 1.334 | S10: =Q10/20 -> 0.032 | T10: =R10/0.028 -> 47.642857 | Y10: 0.64 | Z10: =Y12-0.195 -> 0.58 | AA10: 1.621 | AB10: =Z10/20 -> 0.029 | AC10: =AA10/0.088 -> 18.420455 | AH10: 0.661 | AI10: =AH11-0.155 -> 0.567 | AJ10: 2.087 | AK10: =AI10/20 -> 0.02835 | AL10: =AJ10/0.06 -> 34.783333 | AQ10: 0.635 | AR10: 2.991 | AS10: =AQ10/20 -> 0.03175 | AT10: =AR10/0.047 -> 63.638298 | AY10: 0.62 | AZ10: 4.129 | BA10: =AY10/20 -> 0.031 | BB10: =AZ10/0.041 -> 100.70732 | BG10: 0.641 | BH10: 2.68 | BI10: =BG10/20 -> 0.03205 | BJ10: =BH10/0.025 -> 107.2 | BO10: 0.667 | BP10: 0.621 | BQ10: =BO10/20 -> 0.03335 | BR10: =BP10/0.015 -> 41.4 | BW10: 0.642 | BX10: 2.236 | BY10: =BW10/20 -> 0.0321 | BZ10: =BX10/0.24 -> 9.3166667 | CE10: 0.675 | CF10: 1.499 | CG10: =CE10/20 -> 0.03375 | CH10: =CF10/0.098 -> 15.295918 | CM10: 0.645 | CN10: =CM12-0.231 -> 0.54 | CO10: 0.702 | CP10: =CN10/20 -> 0.027 | CQ10: =CO10/0.019 -> 36.947368 | CV10: 0.68 | CW10: 3.193 | CX10: =CV10/20 -> 0.034 | CY10: =CW10/0.03 -> 106.43333 | DD10: 0.645 | DE10: 3.7 | DF10: =DD10/20 -> 0.03225 | DG10: =DE10/0.017 -> 217.64706 | DL10: 0.632 | DM10: 2.131 | DN10: =DL10/20 -> 0.0316 | DO10: =DM10/0.007 -> 304.42857 | DT10: 0.617 | DU10: 2.93 | DV10: =DT10/20 -> 0.03085 | DW10: =DU10/0.008 -> 366.25 | EB10: 0.645 | EC10: 2.714 | ED10: =EB10/20 -> 0.03225 | EE10: =EC10/0.015 -> 180.93333 | EJ10: 0.631 | EK10: 1.197 | EL10: =EJ10/20 -> 0.03155 | EM10: =EK10/0.01 -> 119.7 | ER10: 0.682 | ES10: 2.006 | ET10: =ER10/20 -> 0.0341 | EU10: =ES10/0.022 -> 91.181818 | EZ10: 0.705 | FC10: =FA10/20 -> 0 | FD10: =FB10/0.002 -> 0 | FI10: 0.612 | FJ10: 3.134 | FK10: =FI10/20 -> 0.0306 | FL10: =FJ10/0.012 -> 261.16667 | FQ10: 0.74 | FR10: =FQ10-0.004 -> 0.736 | FS10: 2.433 | FT10: =FR10/20 -> 0.0368 | FU10: =FS10/0.044 -> 55.295455
I11: 0.652 | J11: 0.76 | K11: =I11/20 -> 0.0326 | L11: =J11/0.032 -> 23.75 | Q11: 0.712 | R11: 1.079 | S11: =Q11/20 -> 0.0356 | T11: =R11/0.028 -> 38.535714 | Y11: 0.712 | Z11: =Y13-0.195 -> 0.642 | AA11: 1.411 | AB11: =Z11/20 -> 0.0321 | AC11: =AA11/0.088 -> 16.034091 | AH11: 0.722 | AI11: =AH12-0.155 -> 0.63 | AJ11: 1.508 | AK11: =AI11/20 -> 0.0315 | AL11: =AJ11/0.06 -> 25.133333 | AQ11: 0.697 | AR11: 2.342 | AS11: =AQ11/20 -> 0.03485 | AT11: =AR11/0.047 -> 49.829787 | AY11: 0.685 | AZ11: 3.47 | BA11: =AY11/20 -> 0.03425 | BB11: =AZ11/0.041 -> 84.634146 | BG11: 0.641 | BH11: 3.161 | BI11: =BG11/20 -> 0.03205 | BJ11: =BH11/0.025 -> 126.44 | BO11: 0.727 | BP11: 0.369 | BQ11: =BO11/20 -> 0.03635 | BR11: =BP11/0.015 -> 24.6 | BW11: 0.71 | BX11: 2.577 | BY11: =BW11/20 -> 0.0355 | BZ11: =BX11/0.24 -> 10.7375 | CE11: 0.752 | CF11: 1.26 | CG11: =CE11/20 -> 0.0376 | CH11: =CF11/0.098 -> 12.857143 | CM11: 0.705 | CN11: =CM13-0.231 -> 0.54 | CO11: 0.395 | CP11: =CN11/20 -> 0.027 | CQ11: =CO11/0.019 -> 20.789474 | CV11: 0.744 | CW11: 3.594 | CX11: =CV11/20 -> 0.0372 | CY11: =CW11/0.03 -> 119.8 | DD11: 0.708 | DE11: 2.982 | DF11: =DD11/20 -> 0.0354 | DG11: =DE11/0.017 -> 175.41176 | DL11: 0.694 | DM11: 2.347 | DN11: =DL11/20 -> 0.0347 | DO11: =DM11/0.007 -> 335.28571 | DT11: 0.675 | DU11: 3.268 | DV11: =DT11/20 -> 0.03375 | DW11: =DU11/0.008 -> 408.5 | EB11: 0.712 | EC11: 3.033 | ED11: =EB11/20 -> 0.0356 | EE11: =EC11/0.015 -> 202.2 | FI11: 0.667 | FJ11: 1.589 | FK11: =FI11/20 -> 0.03335 | FL11: =FJ11/0.012 -> 132.41667 | FQ11: 0.8 | FR11: =FQ11-0.004 -> 0.796 | FS11: 2.048 | FT11: =FR11/20 -> 0.0398 | FU11: =FS11/0.044 -> 46.545455
Q12: 0.776 | R12: 0.825 | S12: =Q12/20 -> 0.0388 | T12: =R12/0.028 -> 29.464286 | Y12: 0.775 | Z12: =Y14-0.195 -> 0.642 | AA12: 1.148 | AB12: =Z12/20 -> 0.0321 | AC12: =AA12/0.088 -> 13.045455 | AH12: 0.785 | AI12: =AH13-0.155 -> 0.702 | AJ12: 0.789 | AK12: =AI12/20 -> 0.0351 | AL12: =AJ12/0.06 -> 13.15 | AQ12: 0.766 | AR12: 1.518 | AS12: =AQ12/20 -> 0.0383 | AT12: =AR12/0.047 -> 32.297872 | AY12: 0.747 | AZ12: 2.666 | BA12: =AY12/20 -> 0.03735 | BB12: =AZ12/0.041 -> 65.02439 | BG12: 0.784 | BH12: 3.764 | BI12: =BG12/20 -> 0.0392 | BJ12: =BH12/0.025 -> 150.56 | BW12: 0.775 | BX12: 2.891 | BY12: =BW12/20 -> 0.03875 | BZ12: =BX12/0.24 -> 12.045833 | CE12: 0.817 | CF12: 0.993 | CG12: =CE12/20 -> 0.04085 | CH12: =CF12/0.098 -> 10.132653 | CM12: 0.771 | CV12: 0.847 | CW12: 4.012 | CX12: =CV12/20 -> 0.04235 | CY12: =CW12/0.03 -> 133.73333 | DD12: 0.769 | DE12: 2.138 | DF12: =DD12/20 -> 0.03845 | DG12: =DE12/0.017 -> 125.76471 | DL12: 0.772 | DM12: 2.563 | DN12: =DL12/20 -> 0.0386 | DO12: =DM12/0.007 -> 366.14286 | DT12: 0.755 | DU12: 3.384 | DV12: =DT12/20 -> 0.03775 | DW12: =DU12/0.008 -> 423 | EB12: 0.791 | EC12: 3.366 | ED12: =EB12/20 -> 0.03955 | EE12: =EC12/0.015 -> 224.4 | FQ12: 0.889 | FR12: =FQ12-0.004 -> 0.885 | FS12: 1.589 | FT12: =FR12/20 -> 0.04425 | FU12: =FS12/0.044 -> 36.113636
Q13: 0.862 | R13: 0.489 | S13: =Q13/20 -> 0.0431 | T13: =R13/0.028 -> 17.464286 | Y13: 0.837 | Z13: =Y15-0.195 -> 0.763 | AA13: 0.814 | AB13: =Z13/20 -> 0.03815 | AC13: =AA13/0.088 -> 9.25 | AH13: 0.857 | AQ13: 0.835 | AR13: 0.692 | AS13: =AQ13/20 -> 0.04175 | AT13: =AR13/0.047 -> 14.723404 | AY13: 0.827 | AZ13: 1.666 | BA13: =AY13/20 -> 0.04135 | BB13: =AZ13/0.041 -> 40.634146 | BG13: 0.862 | BH13: 4.384 | BI13: =BG13/20 -> 0.0431 | BJ13: =BH13/0.025 -> 175.36 | BW13: 0.867 | BX13: 3.234 | BY13: =BW13/20 -> 0.04335 | BZ13: =BX13/0.24 -> 13.475 | CE13: 0.872 | CF13: 0.697 | CG13: =CE13/20 -> 0.0436 | CH13: =CF13/0.098 -> 7.1122449 | CM13: 0.771 | CV13: 0.915 | CW13: 4.441 | CX13: =CV13/20 -> 0.04575 | CY13: =CW13/0.03 -> 148.03333 | DD13: 0.84 | DE13: 1.131 | DF13: =DD13/20 -> 0.042 | DG13: =DE13/0.017 -> 66.529412 | DL13: 0.852 | DM13: 2.773 | DN13: =DL13/20 -> 0.0426 | DO13: =DM13/0.007 -> 396.14286 | DT13: 0.836 | DU13: 3.48 | DV13: =DT13/20 -> 0.0418 | DW13: =DU13/0.008 -> 435 | EB13: 0.852 | EC13: 2.83 | ED13: =EB13/20 -> 0.0426 | EE13: =EC13/0.015 -> 188.66667 | FQ13: 0.957 | FR13: =FQ13-0.004 -> 0.953 | FS13: 1.092 | FT13: =FR13/20 -> 0.04765 | FU13: =FS13/0.044 -> 24.818182
Q14: 0.934 | R14: 0.106 | S14: =Q14/20 -> 0.0467 | T14: =R14/0.028 -> 3.7857143 | Y14: 0.837 | Z14: =Y16-0.195 -> 0.822 | AA14: 0.429 | AB14: =Z14/20 -> 0.0411 | AC14: =AA14/0.088 -> 4.875 | AQ14: 0.9 | AR14: 0.697 | AS14: =AQ14/20 -> 0.045 | AT14: =AR14/0.047 -> 14.829787 | AY14: 0.902 | AZ14: 0.413 | BA14: =AY14/20 -> 0.0451 | BB14: =AZ14/0.041 -> 10.073171 | BG14: 0.948 | BH14: 4.97 | BI14: =BG14/20 -> 0.0474 | BJ14: =BH14/0.025 -> 198.8 | BW14: 0.935 | BX14: 3.573 | BY14: =BW14/20 -> 0.04675 | BZ14: =BX14/0.24 -> 14.8875 | CV14: 0.99 | CW14: 4.855 | CX14: =CV14/20 -> 0.0495 | CY14: =CW14/0.03 -> 161.83333 | DL14: 0.925 | DM14: 2.974 | DN14: =DL14/20 -> 0.04625 | DO14: =DM14/0.007 -> 424.85714 | DT14: 0.915 | DU14: 3.567 | DV14: =DT14/20 -> 0.04575 | DW14: =DU14/0.008 -> 445.875 | EB14: 0.915 | EC14: 2.237 | ED14: =EB14/20 -> 0.04575 | EE14: =EC14/0.015 -> 149.13333
Y15: 0.958 | AQ15: 0.972 | AR15: 0.7 | AS15: =AQ15/20 -> 0.0486 | AT15: =AR15/0.047 -> 14.893617 | BG15: 1.019 | BH15: 5.47 | BI15: =BG15/20 -> 0.05095 | BJ15: =BH15/0.025 -> 218.8 | BW15: 1.005 | BX15: 3.896 | BY15: =BW15/20 -> 0.05025 | BZ15: =BX15/0.24 -> 16.233333 | CV15: 1.055 | CW15: 4.159 | CX15: =CV15/20 -> 0.05275 | CY15: =CW15/0.03 -> 138.63333 | DL15: 0.994 | DM15: 3.183 | DN15: =DL15/20 -> 0.0497 | DO15: =DM15/0.007 -> 454.71429 | DT15: 0.98 | DU15: 3.644 | DV15: =DT15/20 -> 0.049 | DW15: =DU15/0.008 -> 455.5 | EB15: 0.976 | EC15: 1.555 | ED15: =EB15/20 -> 0.0488 | EE15: =EC15/0.015 -> 103.66667
Y16: 1.017 | BG16: 1.093 | BH16: 6.101 | BI16: =BG16/20 -> 0.05465 | BJ16: =BH16/0.025 -> 244.04 | BW16: 1.08 | BX16: 3.47 | BY16: =BW16/20 -> 0.054 | BZ16: =BX16/0.24 -> 14.458333 | CV16: 1.118 | CW16: 3.283 | CX16: =CV16/20 -> 0.0559 | CY16: =CW16/0.03 -> 109.43333 | DL16: 1.06 | DM16: 3.394 | DN16: =DL16/20 -> 0.053 | DO16: =DM16/0.007 -> 484.85714 | DT16: 1.042 | DU16: 2.864 | DV16: =DT16/20 -> 0.0521 | DW16: =DU16/0.008 -> 358 | EB16: 1.055 | EC16: 0.812 | ED16: =EB16/20 -> 0.05275 | EE16: =EC16/0.015 -> 54.133333
BG17: 1.166 | BH17: 6.083 | BI17: =BG17/20 -> 0.0583 | BJ17: =BH17/0.025 -> 243.32 | BW17: 1.159 | BX17: 2.78 | BY17: =BW17/20 -> 0.05795 | BZ17: =BX17/0.24 -> 11.583333 | CV17: 1.18 | CW17: 2.3 | CX17: =CV17/20 -> 0.059 | CY17: =CW17/0.03 -> 76.666667 | DL17: 1.115 | DM17: 3.575 | DN17: =DL17/20 -> 0.05575 | DO17: =DM17/0.007 -> 510.71429 | DT17: 1.107 | DU17: 2.236 | DV17: =DT17/20 -> 0.05535 | DW17: =DU17/0.008 -> 279.5
BG18: 1.239 | BH18: 4.945 | BI18: =BG18/20 -> 0.06195 | BJ18: =BH18/0.025 -> 197.8 | BW18: 1.235 | BX18: 1.991 | BY18: =BW18/20 -> 0.06175 | BZ18: =BX18/0.24 -> 8.2958333 | CV18: 1.262 | CW18: 1.241 | CX18: =CV18/20 -> 0.0631 | CY18: =CW18/0.03 -> 41.366667 | DL18: 1.18 | DM18: 3.772 | DN18: =DL18/20 -> 0.059 | DO18: =DM18/0.007 -> 538.85714 | DT18: 1.179 | DU18: 1.545 | DV18: =DT18/20 -> 0.05895 | DW18: =DU18/0.008 -> 193.125
BG19: 1.307 | BH19: 3.707 | BI19: =BG19/20 -> 0.06535 | BJ19: =BH19/0.025 -> 148.28 | BW19: 1.31 | BX19: 1.138 | BY19: =BW19/20 -> 0.0655 | BZ19: =BX19/0.24 -> 4.7416667 | DL19: 1.18 | DM19: 3.921 | DN19: =DL19/20 -> 0.059 | DO19: =DM19/0.007 -> 560.14286
BG20: 1.372 | BH20: 2.42 | BI20: =BG20/20 -> 0.0686 | BJ20: =BH20/0.025 -> 96.8 | BW20: 1.387 | BX20: 0.222 | BY20: =BW20/20 -> 0.06935 | BZ20: =BX20/0.24 -> 0.925 | DL20: 1.3 | DM20: 3.198 | DN20: =DL20/20 -> 0.065 | DO20: =DM20/0.007 -> 456.85714
DL21: 1.38 | DM21: 2.437 | DN21: =DL21/20 -> 0.069 | DO21: =DM21/0.007 -> 348.14286
DL22: 1.461 | DM22: 1.655 | DN22: =DL22/20 -> 0.07305 | DO22: =DM22/0.007 -> 236.42857

Sheet COSOU
A1: Elong.(mm) - Ech 1 | B1: Force(N) - Ech 1 | C1: Def | D1: Cont | E1: Cont(max) | F1: Def rupt | G1: E(mpa) | I1: Elong.(mm) - Ech 2 | J1: Force(N) - Ech 2 | K1: Def | L1: Cont | M1: Cont(max) | N1: Def rupt | O1: E(mpa) | Q1: Elong.(mm) - Ech 3 | R1: Force(N) - Ech 3 | S1: Def | T1: Cont | U1: Cont(max) | V1: Def rupt | W1: E(mpa) | Y1: Elong.(mm) - Ech 4 | Z1: Force(N) - Ech 4 | AA1: Def | AB1: Cont | AC1: Cont(max) | AD1: Def rupt | AE1: E(mpa) | AG1: Elong.(mm) - Ech 5 | AH1: Force(N) - Ech 5 | AI1: Def | AJ1: Cont | AK1: Cont(max) | AL1: Def rupt | AM1: E(mpa) | AO1: Elong.(mm) - Ech 6 | AP1: Force(N) - Ech 6 | AQ1: Def | AR1: Cont | AS1: Cont(max) | AT1: Def rupt | AU1: E(mpa) | AW1: Elong.(mm) - Ech 7 | AX1: Elong.(mm) - Ech 7 | AY1: Force(N) - Ech 7 | AZ1: Def | BA1: Cont | BB1: Cont(max) | BC1: Def rupt | BD1: E(mpa) | BF1: Elong.(mm) - Ech 8 | BG1: Force(N) - Ech 8 | BH1: Def | BI1: Cont | BJ1: Cont(max) | BK1: Def rupt | BL1: E(mpa) | BN1: Elong.(mm) - Ech 9 | BO1: Force(N) - Ech 9 | BP1: Def | BQ1: Cont | BR1: Cont(max) | BS1: Def rupt | BT1: E(mpa) | BV1: Elong.(mm) - Ech 10 | BW1: Force(N) - Ech 10 | BX1: Def | BY1: Cont | BZ1: Cont(max) | CA1: Def rupt | CB1: E(mpa) | CD1: Elong.(mm) - Ech 11 | CE1: Force(N) - Ech 11 | CF1: Def | CG1: Cont | CH1: Cont(max) | CI1: Def rupt | CJ1: E(mpa) | CL1: Elong.(mm) - Ech 12 | CM1: Elong.(mm) - Ech 12 | CN1: Force(N) - Ech 12 | CO1: Def | CP1: Cont | CQ1: Cont(max) | CR1: Def rupt | CS1: E(mpa) | CU1: Elong.(mm) - Ech 13 | CV1: Elong.(mm) - Ech 13 | CW1: Force(N) - Ech 13 | CX1: Def | CY1: Cont | CZ1: Cont(max) | DA1: Def rupt | DB1: E(mpa) | DD1: Elong.(mm) - Ech 14 | DE1: Force(N) - Ech 14 | DF1: Def | DG1: Cont | DH1: Cont(max) | DI1: Def rupt | DJ1: E(mpa) | DL1: Elong.(mm) - Ech 15 | DM1: Force(N) - Ech 15 | DN1: Def | DO1: Cont | DP1: Cont(max) | DQ1: Def rupt | DR1: E(mpa) | DT1: Elong.(mm) - Ech 16 | DU1: Force(N) - Ech 16 | DV1: Def | DW1: Cont | DX1: Cont(max) | DY1: Def rupt | DZ1: E(mpa) | EB1: Elong.(mm) - Ech 17 | EC1: Force(N) - Ech 17 | ED1: Def | EE1: Cont | EF1: Cont(max) | EG1: Def rupt | EH1: E(mpa) | EJ1: Elong.(mm) - Ech 18 | EK1: Force(N) - Ech 18 | EL1: Def | EM1: Cont | EN1: Cont(max) | EO1: Def rupt | EP1: E(mpa) | ER1: Elong.(mm) - Ech 19 | ES1: Force(N) - Ech 19 | ET1: Def | EU1: Cont | EV1: Cont(max) | EW1: Def rupt | EX1: E(mpa) | EZ1: Elong.(mm) - Ech 20 | FA1: Elong.(mm) - Ech 20 | FB1: Force(N) - Ech 20 | FC1: Def | FD1: Cont | FE1: Cont(max) | FF1: Def rupt | FG1: E(mpa) | FI1: Elong.(mm) - Ech 21 | FJ1: Force(N) - Ech 21 | FK1: Def | FL1: Cont | FM1: Cont(max) | FN1: Def rupt | FO1: E(mpa) | FQ1: Elong.(mm) - Ech 22 | FR1: Force(N) - Ech 22 | FS1: Def | FT1: Cont | FU1: Cont(max) | FV1: Def rupt | FW1: E(mpa)
A2: 0 | B2: 0 | C2: =A2/20 -> 0 | D2: =B2/0.103 -> 0 | E2: =MAX(D2:D17) -> 15.737864 | F2: =C13 -> 0.04995 | G2: 421.29 | I2: 0 | J2: 0 | K2: =I2/20 -> 0 | L2: =J2/0.128 -> 0 | M2: =MAX(L2:L329) -> 19 | N2: =K12 -> 0.04185 | O2: 613.25 | Q2: 0 | R2: 0 | S2: =Q2/20 -> 0 | T2: =R2/0.063 -> 0 | U2: =MAX(T2:T329) -> 51.761905 | V2: =S11 -> 0.0349 | W2: 2337.4 | Y2: 0 | Z2: 0 | AA2: =Y2/20 -> 0 | AB2: =Z2/0.007 -> 0 | AC2: =MAX(AB2:AB329) -> 386 | AD2: =AA10 -> 0.03135 | AE2: 17252 | AG2: 0 | AH2: 0 | AI2: =AG2/20 -> 0 | AJ2: =AH2/0.053 -> 0 | AK2: =MAX(AJ2:AJ329) -> 69.301887 | AL2: =AI11 -> 0.03605 | AM2: 2729.6 | AO2: 0 | AP2: 0 | AQ2: =AO2/20 -> 0 | AR2: =AP2/0.062 -> 0 | AS2: =MAX(AR2:AR329) -> 41.693548 | AT2: =AQ11 -> 0.03595 | AU2: 1355 | AW2: 0 | AX2: =AW3-0.081 -> 0 | AY2: 0 | AZ2: =AX2/20 -> 0 | BA2: =AY2/0.116 -> 0 | BB2: =MAX(BA2:BA329) -> 27.422414 | BC2: =AZ19 -> 0.05955 | BD2: 481.26 | BF2: 0 | BG2: 0 | BH2: =BF2/20 -> 0 | BI2: =BG2/0.068 -> 0 | BJ2: =MAX(BI2:BI329) -> 15.176471 | BK2: =BH7 -> 0.02285 | BL2: 926.96 | BN2: 0 | BO2: 0 | BP2: =BN2/20 -> 0 | BQ2: =BO2/0.005 -> 0 | BR2: =MAX(BQ2:BQ329) -> 944.4 | BS2: =BP17 -> 0.05675 | BT2: 15789 | BV2: 0 | BW2: 0 | BX2: =BV2/20 -> 0 | BY2: =BW2/0.02 -> 0 | BZ2: =MAX(BY2:BY329) -> 67.1 | CA2: =BX11 -> 0.03585 | CB2: 2772.6 | CD2: 0 | CE2: 0 | CF2: =CD2/20 -> 0 | CG2: =CE2/0.043 -> 0 | CH2: =MAX(CG2:CG329) -> 52.139535 | CI2: =CF12 -> 0.0405 | CJ2: 2317.3 | CL2: 0 | CM2: =CL3-0.109 -> 0 | CN2: 0 | CO2: =CM2/20 -> 0 | CP2: =CN2/0.014 -> 0 | CQ2: =MAX(CP2:CP13) -> 89.5 | CR2: =CO10 -> 0.02855 | CS2: 3472.6 | CU2: 0 | CV2: =CU3-0.142 -> 0 | CW2: 0 | CX2: =CV2/20 -> 0 | CY2: =CW2/0.039 -> 0 | CZ2: =MAX(CY2:CY11) -> 15.794872 | DA2: =CX9 -> 0.0225 | DB2: 906.74 | DD2: 0 | DE2: 0 | DF2: =DD2/20 -> 0 | DG2: =DE2/0.121 -> 0 | DH2: =MAX(DG2:DG329) -> 9.5867769 | DI2: =DF11 -> 0.034 | DJ2: 285.31 | DL2: 0 | DM2: 0 | DN2: =DL2/20 -> 0 | DO2: =DM2/0.031 -> 0 | DP2: =MAX(DO2:DO329) -> 54.516129 | DQ2: =DN7 -> 0.0207 | DR2: 4041.2 | DT2: 0 | DU2: 0 | DV2: =DT2/20 -> 0 | DW2: =DU2/0.161 -> 0 | DX2: =MAX(DW2:DW329) -> 6.2173913 | DY2: =DV10 -> 0.0326 | DZ2: 247.97 | EB2: 0 | EC2: 0 | ED2: =EB2/20 -> 0 | EE2: =EC2/0.054 -> 0 | EF2: =MAX(EE2:EE329) -> 15.166667 | EG2: =ED10 -> 0.03135 | EH2: 98.947 | EJ2: 0 | EK2: 0 | EL2: =EJ2/20 -> 0 | EM2: =EK2/0.013 -> 0 | EN2: =MAX(EM2:EM329) -> 188.61538 | EO2: =EL16 -> 0.0525 | EP2: 4633.8 | ER2: 0 | ES2: 0 | ET2: =ER2/20 -> 0 | EU2: =ES2/0.375 -> 0 | EV2: =MAX(EU2:EU329) -> 3.296 | EW2: =ET12 -> 0.0403 | EX2: 121.38 | EZ2: 0 | FA2: =EZ3-0.154 -> 0 | FB2: 0 | FC2: =FA2/20 -> 0 | FD2: =FC2/0.014 -> 0 | FE2: =MAX(FD2:FD12) -> 2.5285714 | FF2: =FC12 -> 0.0354 | FG2: 71.429 | FI2: 0 | FJ2: 0 | FK2: =FI2/20 -> 0 | FL2: =FJ2/0.07 -> 0 | FM2: =MAX(FL2:FL329) -> 21.228571 | FN2: =FK9 -> 0.03055 | FO2: 985.7 | FQ2: 0 | FR2: 0 | FS2: =FQ2/20 -> 0 | FT2: =FR2/0.007 -> 0 | FU2: =MAX(FT2:FT329) -> 169 | FV2: =FS10 -> 0.02985 | FW2: 8086.4
A3: 0.277 | B3: 0.094 | C3: =A3/20 -> 0.01385 | D3: =B3/0.103 -> 0.91262136 | I3: 0.237 | J3: 0.13 | K3: =I3/20 -> 0.01185 | L3: =J3/0.128 -> 1.015625 | Q3: 0.15 | R3: 0.172 | S3: =Q3/20 -> 0.0075 | T3: =R3/0.063 -> 2.7301587 | Y3: 0.155 | Z3: 0.113 | AA3: =Y3/20 -> 0.00775 | AB3: =Z3/0.007 -> 16.142857 | AG3: 0.15 | AH3: 0.155 | AI3: =AG3/20 -> 0.0075 | AJ3: =AH3/0.053 -> 2.9245283 | AO3: 0.145 | AP3: 0.162 | AQ3: =AO3/20 -> 0.00725 | AR3: =AP3/0.062 -> 2.6129032 | AW3: 0.081 | AX3: =AW4-0.081 -> 0.089 | AY3: 0.084 | AZ3: =AX3/20 -> 0.00445 | BA3: =AY3/0.116 -> 0.72413793 | BF3: 0.161 | BG3: 0.126 | BH3: =BF3/20 -> 0.00805 | BI3: =BG3/0.068 -> 1.8529412 | BN3: 0.155 | BO3: 0.217 | BP3: =BN3/20 -> 0.00775 | BQ3: =BO3/0.005 -> 43.4 | BV3: 0.152 | BW3: 0.118 | BX3: =BV3/20 -> 0.0076 | BY3: =BW3/0.02 -> 5.9 | CD3: 0.201 | CE3: 0.199 | CF3: =CD3/20 -> 0.01005 | CG3: =CE3/0.043 -> 4.627907 | CL3: 0.109 | CM3: =CL4-0.109 -> 0.098 | CN3: 0.069 | CO3: =CM3/20 -> 0.0049 | CP3: =CN3/0.014 -> 4.9285714 | CU3: 0.142 | CV3: =CU4-0.142 -> 0.069 | CW3: 0.057 | CX3: =CV3/20 -> 0.00345 | CY3: =CW3/0.039 -> 1.4615385 | DD3: 0.148 | DE3: 0.101 | DF3: =DD3/20 -> 0.0074 | DG3: =DE3/0.121 -> 0.83471074 | DL3: 0.15 | DM3: 0.179 | DN3: =DL3/20 -> 0.0075 | DO3: =DM3/0.031 -> 5.7741935 | DT3: 0.152 | DU3: 0.059 | DV3: =DT3/20 -> 0.0076 | DW3: =DU3/0.161 -> 0.36645963 | EB3: 0.152 | EC3: 0.054 | ED3: =EB3/20 -> 0.0076 | EE3: =EC3/0.054 -> 1 | EJ3: 0.163 | EK3: 0.094 | EL3: =EJ3/20 -> 0.00815 | EM3: =EK3/0.013 -> 7.2307692 | ER3: 0.19 | ES3: 0.113 | ET3: =ER3/20 -> 0.0095 | EU3: =ES3/0.375 -> 0.30133333 | EZ3: 0.154 | FA3: =EZ4-0.154 -> 0.067 | FB3: 0.025 | FC3: =FA3/20 -> 0.00335 | FD3: =FC3/0.014 -> 0.23928571 | FI3: 0.16 | FJ3: 0.089 | FK3: =FI3/20 -> 0.008 | FL3: =FJ3/0.07 -> 1.2714286 | FQ3: 0.092 | FR3: 0.064 | FS3: =FQ3/20 -> 0.0046 | FT3: =FR3/0.007 -> 9.1428571
A4: 0.343 | B4: 0.218 | C4: =A4/20 -> 0.01715 | D4: =B4/0.103 -> 2.1165049 | I4: 0.301 | J4: 0.32 | K4: =I4/20 -> 0.01505 | L4: =J4/0.128 -> 2.5 | Q4: 0.219 | R4: 0.434 | S4: =Q4/20 -> 0.01095 | T4: =R4/0.063 -> 6.8888889 | Y4: 0.221 | Z4: 0.302 | AA4: =Y4/20 -> 0.01105 | AB4: =Z4/0.007 -> 43.142857 | AG4: 0.224 | AH4: 0.41 | AI4: =AG4/20 -> 0.0112 | AJ4: =AH4/0.053 -> 7.7358491 | AO4: 0.212 | AP4: 0.391 | AQ4: =AO4/20 -> 0.0106 | AR4: =AP4/0.062 -> 6.3064516 | AW4: 0.17 | AX4: =AW5-0.081 -> 0.154 | AY4: 0.206 | AZ4: =AX4/20 -> 0.0077 | BA4: =AY4/0.116 -> 1.7758621 | BF4: 0.229 | BG4: 0.302 | BH4: =BF4/20 -> 0.01145 | BI4: =BG4/0.068 -> 4.4411765 | BN4: 0.219 | BO4: 0.53 | BP4: =BN4/20 -> 0.01095 | BQ4: =BO4/0.005 -> 106 | BV4: 0.222 | BW4: 0.268 | BX4: =BV4/20 -> 0.0111 | BY4: =BW4/0.02 -> 13.4 | CD4: 0.267 | CE4: 0.464 | CF4: =CD4/20 -> 0.01335 | CG4: =CE4/0.043 -> 10.790698 | CL4: 0.207 | CM4: =CL5-0.109 -> 0.161 | CN4: 0.17 | CO4: =CM4/20 -> 0.00805 | CP4: =CN4/0.014 -> 12.142857 | CU4: 0.211 | CV4: =CU5-0.142 -> 0.121 | CW4: 0.143 | CX4: =CV4/20 -> 0.00605 | CY4: =CW4/0.039 -> 3.6666667 | DD4: 0.215 | DE4: 0.229 | DF4: =DD4/20 -> 0.01075 | DG4: =DE4/0.121 -> 1.892562 | DL4: 0.215 | DM4: 0.472 | DN4: =DL4/20 -> 0.01075 | DO4: =DM4/0.031 -> 15.225806 | DT4: 0.224 | DU4: 0.157 | DV4: =DT4/20 -> 0.0112 | DW4: =DU4/0.161 -> 0.97515528 | EB4: 0.222 | EC4: 0.145 | ED4: =EB4/20 -> 0.0111 | EE4: =EC4/0.054 -> 2.6851852 | EJ4: 0.229 | EK4: 0.238 | EL4: =EJ4/20 -> 0.01145 | EM4: =EK4/0.013 -> 18.307692 | ER4: 0.262 | ES4: 0.261 | ET4: =ER4/20 -> 0.0131 | EU4: =ES4/0.375 -> 0.696 | EZ4: 0.221 | FA4: =EZ5-0.154 -> 0.067 | FB4: 0.049 | FC4: =FA4/20 -> 0.00335 | FD4: =FC4/0.014 -> 0.23928571 | FI4: 0.242 | FJ4: 0.238 | FK4: =FI4/20 -> 0.0121 | FL4: =FJ4/0.07 -> 3.4 | FQ4: 0.186 | FR4: 0.189 | FS4: =FQ4/20 -> 0.0093 | FT4: =FR4/0.007 -> 27
A5: 0.407 | B5: 0.369 | C5: =A5/20 -> 0.02035 | D5: =B5/0.103 -> 3.5825243 | I5: 0.379 | J5: 0.559 | K5: =I5/20 -> 0.01895 | L5: =J5/0.128 -> 4.3671875 | Q5: 0.219 | R5: 0.696 | S5: =Q5/20 -> 0.01095 | T5: =R5/0.063 -> 11.047619 | Y5: 0.283 | Z5: 0.562 | AA5: =Y5/20 -> 0.01415 | AB5: =Z5/0.007 -> 80.285714 | AG5: 0.282 | AH5: 0.741 | AI5: =AG5/20 -> 0.0141 | AJ5: =AH5/0.053 -> 13.981132 | AO5: 0.286 | AP5: 0.664 | AQ5: =AO5/20 -> 0.0143 | AR5: =AP5/0.062 -> 10.709677 | AW5: 0.235 | AX5: =AW6-0.081 -> 0.233 | AY5: 0.381 | AZ5: =AX5/20 -> 0.01165 | BA5: =AY5/0.116 -> 3.2844828 | BF5: 0.3 | BG5: 0.54 | BH5: =BF5/20 -> 0.015 | BI5: =BG5/0.068 -> 7.9411765 | BN5: 0.285 | BO5: 0.919 | BP5: =BN5/20 -> 0.01425 | BQ5: =BO5/0.005 -> 183.8 | BV5: 0.285 | BW5: 0.442 | BX5: =BV5/20 -> 0.01425 | BY5: =BW5/0.02 -> 22.1 | CD5: 0.333 | CE5: 0.758 | CF5: =CD5/20 -> 0.01665 | CG5: =CE5/0.043 -> 17.627907 | CL5: 0.27 | CM5: =CL6-0.109 -> 0.232 | CN5: 0.307 | CO5: =CM5/20 -> 0.0116 | CP5: =CN5/0.014 -> 21.928571 | CU5: 0.263 | CV5: =CU6-0.142 -> 0.193 | CW5: 0.243 | CX5: =CV5/20 -> 0.00965 | CY5: =CW5/0.039 -> 6.2307692 | DD5: 0.299 | DE5: 0.385 | DF5: =DD5/20 -> 0.01495 | DG5: =DE5/0.121 -> 3.1818182 | DL5: 0.28 | DM5: 0.888 | DN5: =DL5/20 -> 0.014 | DO5: =DM5/0.031 -> 28.645161 | DT5: 0.29 | DU5: 0.288 | DV5: =DT5/20 -> 0.0145 | DW5: =DU5/0.161 -> 1.7888199 | EB5: 0.282 | EC5: 0.265 | ED5: =EB5/20 -> 0.0141 | EE5: =EC5/0.054 -> 4.9074074 | EJ5: 0.299 | EK5: 0.435 | EL5: =EJ5/20 -> 0.01495 | EM5: =EK5/0.013 -> 33.461538 | ER5: 0.325 | ES5: 0.418 | ET5: =ER5/20 -> 0.01625 | EU5: =ES5/0.375 -> 1.1146667 | EZ5: 0.221 | FA5: =EZ6-0.154 -> 0.211 | FB5: 0.116 | FC5: =FA5/20 -> 0.01055 | FD5: =FC5/0.014 -> 0.75357143 | FI5: 0.311 | FJ5: 0.435 | FK5: =FI5/20 -> 0.01555 | FL5: =FJ5/0.07 -> 6.2142857 | FQ5: 0.263 | FR5: 0.364 | FS5: =FQ5/20 -> 0.01315 | FT5: =FR5/0.007 -> 52
A6: 0.49 | B6: 0.55 | C6: =A6/20 -> 0.0245 | D6: =B6/0.103 -> 5.3398058 | I6: 0.449 | J6: 0.856 | K6: =I6/20 -> 0.02245 | L6: =J6/0.128 -> 6.6875 | Q6: 0.34 | R6: 1.134 | S6: =Q6/20 -> 0.017 | T6: =R6/0.063 -> 18 | Y6: 0.345 | Z6: 0.903 | AA6: =Y6/20 -> 0.01725 | AB6: =Z6/0.007 -> 129 | AG6: 0.342 | AH6: 1.163 | AI6: =AG6/20 -> 0.0171 | AJ6: =AH6/0.053 -> 21.943396 | AO6: 0.372 | AP6: 1.015 | AQ6: =AO6/20 -> 0.0186 | AR6: =AP6/0.062 -> 16.370968 | AW6: 0.314 | AX6: =AW7-0.081 -> 0.304 | AY6: 0.589 | AZ6: =AX6/20 -> 0.0152 | BA6: =AY6/0.116 -> 5.0775862 | BF6: 0.384 | BG6: 0.841 | BH6: =BF6/20 -> 0.0192 | BI6: =BG6/0.068 -> 12.367647 | BN6: 0.345 | BO6: 1.369 | BP6: =BN6/20 -> 0.01725 | BQ6: =BO6/0.005 -> 273.8 | BV6: 0.343 | BW6: 0.629 | BX6: =BV6/20 -> 0.01715 | BY6: =BW6/0.02 -> 31.45 | CD6: 0.387 | CE6: 1.079 | CF6: =CD6/20 -> 0.01935 | CG6: =CE6/0.043 -> 25.093023 | CL6: 0.341 | CM6: =CL7-0.109 -> 0.301 | CN6: 0.471 | CO6: =CM6/20 -> 0.01505 | CP6: =CN6/0.014 -> 33.642857 | CU6: 0.335 | CV6: =CU7-0.142 -> 0.243 | CW6: 0.354 | CX6: =CV6/20 -> 0.01215 | CY6: =CW6/0.039 -> 9.0769231 | DD6: 0.34 | DE6: 0.564 | DF6: =DD6/20 -> 0.017 | DG6: =DE6/0.121 -> 4.661157 | DL6: 0.351 | DM6: 1.432 | DN6: =DL6/20 -> 0.01755 | DO6: =DM6/0.031 -> 46.193548 | DT6: 0.365 | DU6: 0.454 | DV6: =DT6/20 -> 0.01825 | DW6: =DU6/0.161 -> 2.8198758 | EB6: 0.342 | EC6: 0.398 | ED6: =EB6/20 -> 0.0171 | EE6: =EC6/0.054 -> 7.3703704 | EJ6: 0.36 | EK6: 0.665 | EL6: =EJ6/20 -> 0.018 | EM6: =EK6/0.013 -> 51.153846 | ER6: 0.395 | ES6: 0.609 | ET6: =ER6/20 -> 0.01975 | EU6: =ES6/0.375 -> 1.624 | EZ6: 0.365 | FA6: =EZ7-0.154 -> 0.288 | FB6: 0.18 | FC6: =FA6/20 -> 0.0144 | FD6: =FC6/0.014 -> 1.0285714 | FI6: 0.39 | FJ6: 0.683 | FK6: =FI6/20 -> 0.0195 | FL6: =FJ6/0.07 -> 9.7571429 | FQ6: 0.337 | FR6: 0.57 | FS6: =FQ6/20 -> 0.01685 | FT6: =FR6/0.007 -> 81.428571
A7: 0.565 | B7: 0.76 | C7: =A7/20 -> 0.02825 | D7: =B7/0.103 -> 7.3786408 | I7: 0.51 | J7: 1.192 | K7: =I7/20 -> 0.0255 | L7: =J7/0.128 -> 9.3125 | Q7: 0.41 | R7: 1.672 | S7: =Q7/20 -> 0.0205 | T7: =R7/0.063 -> 26.539683 | Y7: 0.422 | Z7: 1.356 | AA7: =Y7/20 -> 0.0211 | AB7: =Z7/0.007 -> 193.71429 | AG7: 0.435 | AH7: 1.721 | AI7: =AG7/20 -> 0.02175 | AJ7: =AH7/0.053 -> 32.471698 | AO7: 0.44 | AP7: 1.425 | AQ7: =AO7/20 -> 0.022 | AR7: =AP7/0.062 -> 22.983871 | AW7: 0.385 | AX7: =AW8-0.081 -> 0.367 | AY7: 0.829 | AZ7: =AX7/20 -> 0.01835 | BA7: =AY7/0.116 -> 7.1465517 | BF7: 0.457 | BG7: 1.032 | BH7: =BF7/20 -> 0.02285 | BI7: =BG7/0.068 -> 15.176471 | BN7: 0.426 | BO7: 1.888 | BP7: =BN7/20 -> 0.0213 | BQ7: =BO7/0.005 -> 377.6 | BV7: 0.42 | BW7: 0.849 | BX7: =BV7/20 -> 0.021 | BY7: =BW7/0.02 -> 42.45 | CD7: 0.45 | CE7: 1.435 | CF7: =CD7/20 -> 0.0225 | CG7: =CE7/0.043 -> 33.372093 | CL7: 0.41 | CM7: =CL8-0.109 -> 0.363 | CN7: 0.668 | CO7: =CM7/20 -> 0.01815 | CP7: =CN7/0.014 -> 47.714286 | CU7: 0.385 | CV7: =CU8-0.142 -> 0.308 | CW7: 0.483 | CX7: =CV7/20 -> 0.0154 | CY7: =CW7/0.039 -> 12.384615 | DD7: 0.42 | DE7: 0.753 | DF7: =DD7/20 -> 0.021 | DG7: =DE7/0.121 -> 6.2231405 | DL7: 0.414 | DM7: 1.69 | DN7: =DL7/20 -> 0.0207 | DO7: =DM7/0.031 -> 54.516129 | DT7: 0.437 | DU7: 0.633 | DV7: =DT7/20 -> 0.02185 | DW7: =DU7/0.161 -> 3.931677 | EB7: 0.427 | EC7: 0.557 | ED7: =EB7/20 -> 0.02135 | EE7: =EC7/0.054 -> 10.314815 | EJ7: 0.418 | EK7: 0.925 | EL7: =EJ7/20 -> 0.0209 | EM7: =EK7/0.013 -> 71.153846 | ER7: 0.48 | ES7: 0.824 | ET7: =ER7/20 -> 0.024 | EU7: =ES7/0.375 -> 2.1973333 | EZ7: 0.442 | FA7: =EZ8-0.154 -> 0.346 | FB7: 0.251 | FC7: =FA7/20 -> 0.0173 | FD7: =FC7/0.014 -> 1.2357143 | FI7: 0.469 | FJ7: 0.993 | FK7: =FI7/20 -> 0.02345 | FL7: =FJ7/0.07 -> 14.185714 | FQ7: 0.407 | FR7: 0.795 | FS7: =FQ7/20 -> 0.02035 | FT7: =FR7/0.007 -> 113.57143
A8: 0.651 | B8: 0.903 | C8: =A8/20 -> 0.03255 | D8: =B8/0.103 -> 8.7669903 | I8: 0.582 | J8: 1.452 | K8: =I8/20 -> 0.0291 | L8: =J8/0.128 -> 11.34375 | Q8: 0.475 | R8: 2.136 | S8: =Q8/20 -> 0.02375 | T8: =R8/0.063 -> 33.904762 | Y8: 0.485 | Z8: 1.782 | AA8: =Y8/20 -> 0.02425 | AB8: =Z8/0.007 -> 254.57143 | AG8: 0.507 | AH8: 2.266 | AI8: =AG8/20 -> 0.02535 | AJ8: =AH8/0.053 -> 42.754717 | AO8: 0.44 | AP8: 1.672 | AQ8: =AO8/20 -> 0.022 | AR8: =AP8/0.062 -> 26.967742 | AW8: 0.448 | AX8: =AW9-0.081 -> 0.434 | AY8: 1.018 | AZ8: =AX8/20 -> 0.0217 | BA8: =AY8/0.116 -> 8.7758621 | BF8: 0.527 | BG8: 0.91 | BH8: =BF8/20 -> 0.02635 | BI8: =BG8/0.068 -> 13.382353 | BN8: 0.495 | BO8: 2.229 | BP8: =BN8/20 -> 0.02475 | BQ8: =BO8/0.005 -> 445.8 | BV8: 0.499 | BW8: 0.984 | BX8: =BV8/20 -> 0.02495 | BY8: =BW8/0.02 -> 49.2 | CD8: 0.51 | CE8: 1.624 | CF8: =CD8/20 -> 0.0255 | CG8: =CE8/0.043 -> 37.767442 | CL8: 0.472 | CM8: =CL9-0.109 -> 0.436 | CN8: 0.851 | CO8: =CM8/20 -> 0.0218 | CP8: =CN8/0.014 -> 60.785714 | CU8: 0.45 | CV8: =CU9-0.142 -> 0.392 | CW8: 0.574 | CX8: =CV8/20 -> 0.0196 | CY8: =CW8/0.039 -> 14.717949 | DD8: 0.495 | DE8: 0.866 | DF8: =DD8/20 -> 0.02475 | DG8: =DE8/0.121 -> 7.1570248 | DL8: 0.5 | DM8: 1.513 | DN8: =DL8/20 -> 0.025 | DO8: =DM8/0.031 -> 48.806452 | DT8: 0.504 | DU8: 0.778 | DV8: =DT8/20 -> 0.0252 | DW8: =DU8/0.161 -> 4.8322981 | EB8: 0.495 | EC8: 0.682 | ED8: =EB8/20 -> 0.02475 | EE8: =EC8/0.054 -> 12.62963 | EJ8: 0.502 | EK8: 1.133 | EL8: =EJ8/20 -> 0.0251 | EM8: =EK8/0.013 -> 87.153846 | ER8: 0.545 | ES8: 0.962 | ET8: =ER8/20 -> 0.02725 | EU8: =ES8/0.375 -> 2.5653333 | EZ8: 0.5 | FA8: =EZ9-0.154 -> 0.428 | FB8: 0.299 | FC8: =FA8/20 -> 0.0214 | FD8: =FC8/0.014 -> 1.5285714 | FI8: 0.545 | FJ8: 1.27 | FK8: =FI8/20 -> 0.02725 | FL8: =FJ8/0.07 -> 18.142857 | FQ8: 0.474 | FR8: 0.994 | FS8: =FQ8/20 -> 0.0237 | FT8: =FR8/0.007 -> 142
A9: 0.727 | B9: 1.054 | C9: =A9/20 -> 0.03635 | D9: =B9/0.103 -> 10.23301 | I9: 0.652 | J9: 1.702 | K9: =I9/20 -> 0.0326 | L9: =J9/0.128 -> 13.296875 | Q9: 0.545 | R9: 2.631 | S9: =Q9/20 -> 0.02725 | T9: =R9/0.063 -> 41.761905 | Y9: 0.547 | Z9: 2.212 | AA9: =Y9/20 -> 0.02735 | AB9: =Z9/0.007 -> 316 | AG9: 0.589 | AH9: 2.861 | AI9: =AG9/20 -> 0.02945 | AJ9: =AH9/0.053 -> 53.981132 | AO9: 0.562 | AP9: 1.959 | AQ9: =AO9/20 -> 0.0281 | AR9: =AP9/0.062 -> 31.596774 | AW9: 0.515 | AX9: =AW10-0.081 -> 0.509 | AY9: 1.214 | AZ9: =AX9/20 -> 0.02545 | BA9: =AY9/0.116 -> 10.465517 | BF9: 0.595 | BG9: 0.731 | BH9: =BF9/20 -> 0.02975 | BI9: =BG9/0.068 -> 10.75 | BN9: 0.564 | BO9: 2.523 | BP9: =BN9/20 -> 0.0282 | BQ9: =BO9/0.005 -> 504.6 | BV9: 0.555 | BW9: 1.094 | BX9: =BV9/20 -> 0.02775 | BY9: =BW9/0.02 -> 54.7 | CD9: 0.573 | CE9: 1.782 | CF9: =CD9/20 -> 0.02865 | CG9: =CE9/0.043 -> 41.44186 | CL9: 0.545 | CM9: =CL10-0.109 -> 0.51 | CN9: 1.047 | CO9: =CM9/20 -> 0.0255 | CP9: =CN9/0.014 -> 74.785714 | CU9: 0.534 | CV9: =CU10-0.142 -> 0.45 | CW9: 0.616 | CX9: =CV9/20 -> 0.0225 | CY9: =CW9/0.039 -> 15.794872 | DD9: 0.552 | DE9: 0.971 | DF9: =DD9/20 -> 0.0276 | DG9: =DE9/0.121 -> 8.0247934 | DL9: 0.57 | DM9: 1.222 | DN9: =DL9/20 -> 0.0285 | DO9: =DM9/0.031 -> 39.419355 | DT9: 0.578 | DU9: 0.898 | DV9: =DT9/20 -> 0.0289 | DW9: =DU9/0.161 -> 5.5776398 | EB9: 0.561 | EC9: 0.785 | ED9: =EB9/20 -> 0.02805 | EE9: =EC9/0.054 -> 14.537037 | EJ9: 0.57 | EK9: 1.322 | EL9: =EJ9/20 -> 0.0285 | EM9: =EK9/0.013 -> 101.69231 | ER9: 0.617 | ES9: 1.087 | ET9: =ER9/20 -> 0.03085 | EU9: =ES9/0.375 -> 2.8986667 | EZ9: 0.582 | FA9: =EZ10-0.154 -> 0.506 | FB9: 0.363 | FC9: =FA9/20 -> 0.0253 | FD9: =FC9/0.014 -> 1.8071429 | FI9: 0.611 | FJ9: 1.486 | FK9: =FI9/20 -> 0.03055 | FL9: =FJ9/0.07 -> 21.228571 | FQ9: 0.537 | FR9: 1.111 | FS9: =FQ9/20 -> 0.02685 | FT9: =FR9/0.007 -> 158.71429
A10: 0.794 | B10: 1.207 | C10: =A10/20 -> 0.0397 | D10: =B10/0.103 -> 11.718447 | I10: 0.715 | J10: 1.952 | K10: =I10/20 -> 0.03575 | L10: =J10/0.128 -> 15.25 | Q10: 0.622 | R10: 3.227 | S10: =Q10/20 -> 0.0311 | T10: =R10/0.063 -> 51.222222 | Y10: 0.627 | Z10: 2.702 | AA10: =Y10/20 -> 0.03135 | AB10: =Z10/0.007 -> 386 | AG10: 0.665 | AH10: 3.492 | AI10: =AG10/20 -> 0.03325 | AJ10: =AH10/0.053 -> 65.886792 | AO10: 0.645 | AP10: 2.278 | AQ10: =AO10/20 -> 0.03225 | AR10: =AP10/0.062 -> 36.741935 | AW10: 0.59 | AX10: =AW11-0.081 -> 0.578 | AY10: 1.411 | AZ10: =AX10/20 -> 0.0289 | BA10: =AY10/0.116 -> 12.163793 | BF10: 0.66 | BG10: 0.496 | BH10: =BF10/20 -> 0.033 | BI10: =BG10/0.068 -> 7.2941176 | BN10: 0.631 | BO10: 2.793 | BP10: =BN10/20 -> 0.03155 | BQ10: =BO10/0.005 -> 558.6 | BV10: 0.617 | BW10: 1.214 | BX10: =BV10/20 -> 0.03085 | BY10: =BW10/0.02 -> 60.7 | CD10: 0.657 | CE10: 1.959 | CF10: =CD10/20 -> 0.03285 | CG10: =CE10/0.043 -> 45.55814 | CL10: 0.619 | CM10: =CL11-0.109 -> 0.571 | CN10: 1.253 | CO10: =CM10/20 -> 0.02855 | CP10: =CN10/0.014 -> 89.5 | CU10: 0.592 | CV10: =CU11-0.142 -> 0.513 | CW10: 0.515 | CX10: =CV10/20 -> 0.02565 | CY10: =CW10/0.039 -> 13.205128 | DD10: 0.615 | DE10: 1.067 | DF10: =DD10/20 -> 0.03075 | DG10: =DE10/0.121 -> 8.8181818 | DL10: 0.637 | DM10: 0.802 | DN10: =DL10/20 -> 0.03185 | DO10: =DM10/0.031 -> 25.870968 | DT10: 0.652 | DU10: 1.001 | DV10: =DT10/20 -> 0.0326 | DW10: =DU10/0.161 -> 6.2173913 | EB10: 0.627 | EC10: 0.819 | ED10: =EB10/20 -> 0.03135 | EE10: =EC10/0.054 -> 15.166667 | EJ10: 0.57 | EK10: 1.454 | EL10: =EJ10/20 -> 0.0285 | EM10: =EK10/0.013 -> 111.84615 | ER10: 0.689 | ES10: 1.214 | ET10: =ER10/20 -> 0.03445 | EU10: =ES10/0.375 -> 3.2373333 | EZ10: 0.66 | FA10: =EZ11-0.154 -> 0.583 | FB10: 0.299 | FC10: =FA10/20 -> 0.02915 | FD10: =FC10/0.014 -> 2.0821429 | FI10: 0.667 | FJ10: 1.29 | FK10: =FI10/20 -> 0.03335 | FL10: =FJ10/0.07 -> 18.428571 | FQ10: 0.597 | FR10: 1.183 | FS10: =FQ10/20 -> 0.02985 | FT10: =FR10/0.007 -> 169
A11: 0.864 | B11: 1.364 | C11: =A11/20 -> 0.0432 | D11: =B11/0.103 -> 13.242718 | I11: 0.777 | J11: 2.188 | K11: =I11/20 -> 0.03885 | L11: =J11/0.128 -> 17.09375 | Q11: 0.698 | R11: 3.261 | S11: =Q11/20 -> 0.0349 | T11: =R11/0.063 -> 51.761905 | Y11: 0.693 | Z11: 2.413 | AA11: =Y11/20 -> 0.03465 | AB11: =Z11/0.007 -> 344.71429 | AG11: 0.721 | AH11: 3.673 | AI11: =AG11/20 -> 0.03605 | AJ11: =AH11/0.053 -> 69.301887 | AO11: 0.719 | AP11: 2.585 | AQ11: =AO11/20 -> 0.03595 | AR11: =AP11/0.062 -> 41.693548 | AW11: 0.659 | AX11: =AW12-0.081 -> 0.578 | AY11: 1.567 | AZ11: =AX11/20 -> 0.0289 | BA11: =AY11/0.116 -> 13.508621 | BN11: 0.698 | BO11: 3.053 | BP11: =BN11/20 -> 0.0349 | BQ11: =BO11/0.005 -> 610.6 | BV11: 0.717 | BW11: 1.342 | BX11: =BV11/20 -> 0.03585 | BY11: =BW11/0.02 -> 67.1 | CD11: 0.732 | CE11: 2.153 | CF11: =CD11/20 -> 0.0366 | CG11: =CE11/0.043 -> 50.069767 | CL11: 0.68 | CM11: =CL12-0.109 -> 0.64 | CN11: 1.089 | CO11: =CM11/20 -> 0.032 | CP11: =CN11/0.014 -> 77.785714 | CU11: 0.655 | CV11: =CU12-0.142 -> 0.588 | CW11: 0.405 | CX11: =CV11/20 -> 0.0294 | CY11: =CW11/0.039 -> 10.384615 | DD11: 0.68 | DE11: 1.16 | DF11: =DD11/20 -> 0.034 | DG11: =DE11/0.121 -> 9.5867769 | DT11: 0.717 | DU11: 0.927 | DV11: =DT11/20 -> 0.03585 | DW11: =DU11/0.161 -> 5.757764 | EB11: 0.682 | EC11: 0.69 | ED11: =EB11/20 -> 0.0341 | EE11: =EC11/0.054 -> 12.777778 | EJ11: 0.695 | EK11: 1.614 | EL11: =EJ11/20 -> 0.03475 | EM11: =EK11/0.013 -> 124.15385 | ER11: 0.75 | ES11: 1.231 | ET11: =ER11/20 -> 0.0375 | EU11: =ES11/0.375 -> 3.2826667 | EZ11: 0.737 | FA11: =EZ12-0.154 -> 0.643 | FB11: 0.233 | FC11: =FA11/20 -> 0.03215 | FD11: =FC11/0.014 -> 2.2964286 | FI11: 0.73 | FJ11: 1.042 | FK11: =FI11/20 -> 0.0365 | FL11: =FJ11/0.07 -> 14.885714 | FQ11: 0.68 | FR11: 0.976 | FS11: =FQ11/20 -> 0.034 | FT11: =FR11/0.007 -> 139.42857
A12: 0.931 | B12: 1.525 | C12: =A12/20 -> 0.04655 | D12: =B12/0.103 -> 14.805825 | I12: 0.837 | J12: 2.432 | K12: =I12/20 -> 0.04185 | L12: =J12/0.128 -> 19 | Q12: 0.767 | R12: 2.722 | S12: =Q12/20 -> 0.03835 | T12: =R12/0.063 -> 43.206349 | Y12: 0.752 | Z12: 1.96 | AA12: =Y12/20 -> 0.0376 | AB12: =Z12/0.007 -> 280 | AG12: 0.789 | AH12: 3.114 | AI12: =AG12/20 -> 0.03945 | AJ12: =AH12/0.053 -> 58.754717 | AO12: 0.805 | AP12: 2.175 | AQ12: =AO12/20 -> 0.04025 | AR12: =AP12/0.062 -> 35.080645 | AW12: 0.659 | AX12: =AW13-0.081 -> 0.704 | AY12: 1.771 | AZ12: =AX12/20 -> 0.0352 | BA12: =AY12/0.116 -> 15.267241 | BN12: 0.777 | BO12: 3.303 | BP12: =BN12/20 -> 0.03885 | BQ12: =BO12/0.005 -> 660.6 | BV12: 0.791 | BW12: 1.121 | BX12: =BV12/20 -> 0.03955 | BY12: =BW12/0.02 -> 56.05 | CD12: 0.81 | CE12: 2.242 | CF12: =CD12/20 -> 0.0405 | CG12: =CE12/0.043 -> 52.139535 | CL12: 0.749 | CM12: =CL13-0.109 -> 0.708 | CN12: 0.895 | CO12: =CM12/20 -> 0.0354 | CP12: =CN12/0.014 -> 63.928571 | CU12: 0.73 | DD12: 0.774 | DE12: 0.972 | DF12: =DD12/20 -> 0.0387 | DG12: =DE12/0.121 -> 8.0330579 | DT12: 0.79 | DU12: 0.748 | DV12: =DT12/20 -> 0.0395 | DW12: =DU12/0.161 -> 4.6459627 | EB12: 0.752 | EC12: 0.53 | ED12: =EB12/20 -> 0.0376 | EE12: =EC12/0.054 -> 9.8148148 | EJ12: 0.762 | EK12: 1.768 | EL12: =EJ12/20 -> 0.0381 | EM12: =EK12/0.013 -> 136 | ER12: 0.806 | ES12: 1.236 | ET12: =ER12/20 -> 0.0403 | EU12: =ES12/0.375 -> 3.296 | EZ12: 0.797 | FA12: =EZ13-0.154 -> 0.708 | FB12: 0.162 | FC12: =FA12/20 -> 0.0354 | FD12: =FC12/0.014 -> 2.5285714 | FI12: 0.795 | FJ12: 0.731 | FK12: =FI12/20 -> 0.03975 | FL12: =FJ12/0.07 -> 10.442857 | FQ12: 0.75 | FR12: 0.751 | FS12: =FQ12/20 -> 0.0375 | FT12: =FR12/0.007 -> 107.28571
A13: 0.999 | B13: 1.621 | C13: =A13/20 -> 0.04995 | D13: =B13/0.103 -> 15.737864 | I13: 0.91 | J13: 2.043 | K13: =I13/20 -> 0.0455 | L13: =J13/0.128 -> 15.960938 | Q13: 0.839 | R13: 2.087 | S13: =Q13/20 -> 0.04195 | T13: =R13/0.063 -> 33.126984 | Y13: 0.828 | Z13: 1.42 | AA13: =Y13/20 -> 0.0414 | AB13: =Z13/0.007 -> 202.85714 | AG13: 0.855 | AH13: 2.416 | AI13: =AG13/20 -> 0.04275 | AJ13: =AH13/0.053 -> 45.584906 | AO13: 0.867 | AP13: 1.766 | AQ13: =AO13/20 -> 0.04335 | AR13: =AP13/0.062 -> 28.483871 | AW13: 0.785 | AX13: =AW14-0.081 -> 0.766 | AY13: 1.984 | AZ13: =AX13/20 -> 0.0383 | BA13: =AY13/0.116 -> 17.103448 | BN13: 0.85 | BO13: 3.587 | BP13: =BN13/20 -> 0.0425 | BQ13: =BO13/0.005 -> 717.4 | BV13: 0.875 | BW13: 0.871 | BX13: =BV13/20 -> 0.04375 | BY13: =BW13/0.02 -> 43.55 | CD13: 0.875 | CE13: 2.217 | CF13: =CD13/20 -> 0.04375 | CG13: =CE13/0.043 -> 51.55814 | CL13: 0.817 | CM13: =CL14-0.109 -> 0.775 | CN13: 0.64 | CO13: =CM13/20 -> 0.03875 | CP13: =CN13/0.014 -> 45.714286 | DD13: 0.856 | DE13: 0.755 | DF13: =DD13/20 -> 0.0428 | DG13: =DE13/0.121 -> 6.2396694 | DT13: 0.855 | DU13: 0.545 | DV13: =DT13/20 -> 0.04275 | DW13: =DU13/0.161 -> 3.3850932 | EB13: 0.822 | EC13: 0.351 | ED13: =EB13/20 -> 0.0411 | EE13: =EC13/0.054 -> 6.5 | EJ13: 0.831 | EK13: 1.927 | EL13: =EJ13/20 -> 0.04155 | EM13: =EK13/0.013 -> 148.23077 | ER13: 0.881 | ES13: 0.986 | ET13: =ER13/20 -> 0.04405 | EU13: =ES13/0.375 -> 2.6293333 | EZ13: 0.862 | FQ13: 0.81 | FR13: 0.486 | FS13: =FQ13/20 -> 0.0405 | FT13: =FR13/0.007 -> 69.428571
A14: 1.07 | B14: 1.346 | C14: =A14/20 -> 0.0535 | D14: =B14/0.103 -> 13.067961 | I14: 0.975 | J14: 1.601 | K14: =I14/20 -> 0.04875 | L14: =J14/0.128 -> 12.507812 | Q14: 0.937 | R14: 1.329 | S14: =Q14/20 -> 0.04685 | T14: =R14/0.063 -> 21.095238 | AO14: 0.925 | AP14: 1.251 | AQ14: =AO14/20 -> 0.04625 | AR14: =AP14/0.062 -> 20.177419 | AW14: 0.847 | AX14: =AW15-0.081 -> 0.846 | AY14: 2.193 | AZ14: =AX14/20 -> 0.0423 | BA14: =AY14/0.116 -> 18.905172 | BN14: 0.916 | BO14: 3.867 | BP14: =BN14/20 -> 0.0458 | BQ14: =BO14/0.005 -> 773.4 | BV14: 0.932 | BW14: 0.608 | BX14: =BV14/20 -> 0.0466 | BY14: =BW14/0.02 -> 30.4 | CD14: 0.875 | CE14: 2.158 | CF14: =CD14/20 -> 0.04375 | CG14: =CE14/0.043 -> 50.186047 | CL14: 0.884 | DD14: 0.92 | DE14: 0.523 | DF14: =DD14/20 -> 0.046 | DG14: =DE14/0.121 -> 4.3223141 | EJ14: 0.91 | EK14: 2.092 | EL14: =EJ14/20 -> 0.0455 | EM14: =EK14/0.013 -> 160.92308 | ER14: 0.955 | ES14: 0.719 | ET14: =ER14/20 -> 0.04775 | EU14: =ES14/0.375 -> 1.9173333
A15: 1.137 | B15: 1.04 | C15: =A15/20 -> 0.05685 | D15: =B15/0.103 -> 10.097087 | I15: 1.032 | J15: 1.114 | K15: =I15/20 -> 0.0516 | L15: =J15/0.128 -> 8.703125 | AW15: 0.927 | AX15: =AW16-0.081 -> 0.919 | AY15: 2.403 | AZ15: =AX15/20 -> 0.04595 | BA15: =AY15/0.116 -> 20.715517 | BN15: 0.985 | BO15: 4.139 | BP15: =BN15/20 -> 0.04925 | BQ15: =BO15/0.005 -> 827.8 | CD15: 0.997 | CE15: 1.685 | CF15: =CD15/20 -> 0.04985 | CG15: =CE15/0.043 -> 39.186047 | EJ15: 0.975 | EK15: 2.281 | EL15: =EJ15/20 -> 0.04875 | EM15: =EK15/0.013 -> 175.46154 | ER15: 1.022 | ES15: 0.432 | ET15: =ER15/20 -> 0.0511 | EU15: =ES15/0.375 -> 1.152
