Workbook

Sheet DIAMETRE (CR,CS)
B1: DIAMETRE FIBRE COROUI | J1: DIAMETRE FIBRE COSOU
B2: D_1(mm) | C2: D_2(mm) | D2: D_3(mm) | E2: D_Moy(mm) | F2: S_(mm2) | G2: D_Moy Global(mm) | J2: D_1(mm) | K2: D_2(mm) | L2: D_3(mm) | M2: D_Moy(mm) | N2: S_(mm2) | O2: D_Moy Global(mm)
A3: ECH1 | B3: 0.205 | C3: 0.131 | D3: 0.18 | E3: =AVERAGE(B3:D3) -> 0.172 | F3: =3.14159265358979*E3*E3/4 -> 0.023235219 | G3: =AVERAGE(E3:E24) -> 0.19634848 | I3: ECH1 | J3: 0.477 | K3: 0.25 | L3: 0.36 | M3: =AVERAGE(J3:L3) -> 0.36233333 | N3: =3.14159265358979*M3*M3/4 -> 0.10311135 | O3: =AVERAGE(M3:M24) -> 0.26569697
A4: ECH2 | B4: 0.164 | C4: 0.135 | D4: 0.311 | E4: =AVERAGE(B4:D4) -> 0.20333333 | F4: =3.14159265358979*E4*E4/4 -> 0.032471851 | I4: ECH2 | J4: 0.38 | K4: 0.396 | L4: 0.436 | M4: =AVERAGE(J4:L4) -> 0.404 | N4: =3.14159265358979*M4*M4/4 -> 0.12818955
A5: ECH3 | B5: 0.166 | C5: 0.177 | D5: 0.221 | E5: =AVERAGE(B5:D5) -> 0.188 | F5: =3.14159265358979*E5*E5/4 -> 0.027759113 | I5: ECH3 | J5: 0.289 | K5: 0.23 | L5: 0.332 | M5: =AVERAGE(J5:L5) -> 0.28366667 | N5: =3.14159265358979*M5*M5/4 -> 0.063198459
A6: ECH4 | B6: 0.305 | C6: 0.349 | D6: 0.352 | E6: =AVERAGE(B6:D6) -> 0.33533333 | F6: =3.14159265358979*E6*E6/4 -> 0.088316802 | I6: ECH4 | J6: 0.101 | K6: 0.075 | L6: 0.117 | M6: =AVERAGE(J6:L6) -> 0.097666667 | N6: =3.14159265358979*M6*M6/4 -> 0.0074917385
A7: ECH5 | B7: 0.206 | C7: 0.387 | D7: 0.234 | E7: =AVERAGE(B7:D7) -> 0.27566667 | F7: =3.14159265358979*E7*E7/4 -> 0.059684064 | I7: ECH5 | J7: 0.257 | K7: 0.286 | L7: 0.24 | M7: =AVERAGE(J7:L7) -> 0.261 | N7: =3.14159265358979*M7*M7/4 -> 0.053502108
A8: ECH6 | B8: 0.268 | C8: 0.224 | D8: 0.242 | E8: =AVERAGE(B8:D8) -> 0.24466667 | F8: =3.14159265358979*E8*E8/4 -> 0.04701533 | I8: ECH6 | J8: 0.235 | K8: 0.281 | L8: 0.324 | M8: =AVERAGE(J8:L8) -> 0.28 | N8: =3.14159265358979*M8*M8/4 -> 0.061575216
A9: ECH7 | B9: 0.177 | C9: 0.237 | D9: 0.27 | E9: =AVERAGE(B9:D9) -> 0.228 | F9: =3.14159265358979*E9*E9/4 -> 0.040828138 | I9: ECH7 | J9: 0.412 | K9: 0.36 | L9: 0.382 | M9: =AVERAGE(J9:L9) -> 0.38466667 | N9: =3.14159265358979*M9*M9/4 -> 0.11621414
A10: ECH8 | B10: 0.219 | C10: 0.049 | D10: 0.264 | E10: =AVERAGE(B10:D10) -> 0.17733333 | F10: =3.14159265358979*E10*E10/4 -> 0.024698503 | I10: ECH8 | J10: 0.327 | K10: 0.296 | L10: 0.262 | M10: =AVERAGE(J10:L10) -> 0.295 | N10: =3.14159265358979*M10*M10/4 -> 0.068349275
A11: ECH9 | B11: 0.543 | C11: 0.416 | D11: 0.354 | E11: =AVERAGE(B11:D11) -> 0.43766667 | F11: =3.14159265358979*E11*E11/4 -> 0.15044468 | I11: ECH9 | J11: 0.077 | K11: 0.079 | L11: 0.092 | M11: =AVERAGE(J11:L11) -> 0.082666667 | N11: =3.14159265358979*M11*M11/4 -> 0.0053672365
A12: ECH10 | B12: 0.242 | C12: 0.06 | D12: 0.221 | E12: =AVERAGE(B12:D12) -> 0.17433333 | F12: =3.14159265358979*E12*E12/4 -> 0.023869908 | I12: ECH10 | J12: 0.099 | K12: 0.261 | L12: 0.113 | M12: =AVERAGE(J12:L12) -> 0.15766667 | N12: =3.14159265358979*M12*M12/4 -> 0.019524038
A13: ECH11 | B13: 0.36 | C13: 0.494 | D13: 0.205 | E13: =AVERAGE(B13:D13) -> 0.353 | F13: =3.14159265358979*E13*E13/4 -> 0.09786768 | I13: ECH11 | J13: 0.394 | K13: 0.187 | L13: 0.121 | M13: =AVERAGE(J13:L13) -> 0.234 | N13: =3.14159265358979*M13*M13/4 -> 0.043005262
A14: ECH12 | B14: 0.152 | C14: 0.15 | D14: 0.161 | E14: =AVERAGE(B14:D14) -> 0.15433333 | F14: =3.14159265358979*E14*E14/4 -> 0.018707224 | I14: ECH12 | J14: 0.118 | K14: 0.106 | L14: 0.173 | M14: =AVERAGE(J14:L14) -> 0.13233333 | N14: =3.14159265358979*M14*M14/4 -> 0.01375398
A15: ECH13 | B15: 0.139 | C15: 0.19 | D15: 0.258 | E15: =AVERAGE(B15:D15) -> 0.19566667 | F15: =3.14159265358979*E15*E15/4 -> 0.030069318 | I15: ECH13 | J15: 0.252 | K15: 0.32 | L15: 0.095 | M15: =AVERAGE(J15:L15) -> 0.22233333 | N15: =3.14159265358979*M15*M15/4 -> 0.038823889
... A24: ECH22 | B24: 0.224 | C24: 0.291 | D24: 0.193 | E24: =AVERAGE(B24:D24) -> 0.236 | F24: =3.14159265358979*E24*E24/4 -> 0.043743536 | I24: ECH22 | J24: 0.087 | K24: 0.138 | L24: 0.05 | M24: =AVERAGE(J24:L24) -> 0.091666667 | N24: =3.14159265358979*M24*M24/4 -> 0.0065995262

Sheet COROUI
A1: Elong.(mm) - ECH1 | B1: Force(N) - ECH1 | C1: Def | D1: Cont | E1: Cont(max) | F1: Def rupt | G1: E(mpa) | I1: Elong.(mm) - ECH2 | J1: Force(N) - ECH2 | K1: Def | L1: Cont | M1: Cont(max) | N1: Def rupt | O1: E(mpa) | Q1: Elong.(mm) - ECH3 | R1: Force(N) - ECH3 | S1: Def | T1: Cont | U1: Cont(max) | V1: Def rupt | W1: E(mpa) | Y1: Elong.(mm) - ECH4 | Z1: Force(N) - ECH4 | AA1: Def | AB1: Cont | AC1: Cont(max) | AD1: Def rupt | AE1: E(mpa) | AG1: Elong.(mm) - ECH5 | AH1: Force(N) - ECH5 | AI1: Def | AJ1: Cont | AK1: Cont(max) | AL1: Def rupt | AM1: E(mpa) | AO1: Elong.(mm) - ECH6 | AP1: Force(N) - ECH6 | AQ1: Def | AR1: Cont | AS1: Cont(max) | AT1: Def rupt | AU1: E(mpa) | AW1: Elong.(mm) - ECH7 | AX1: Force(N) - ECH7 | AY1: Def | AZ1: Cont | BA1: Cont(max) | BB1: Def rupt | BC1: E(mpa) | BE1: Elong.(mm) - ECH8 | BF1: Force(N) - ECH8 | BG1: Def | BH1: Cont | BI1: Cont(max) | BJ1: Def rupt | BK1: E(mpa) | BM1: Elong.(mm) - ECH9 | BN1: Force(N) - ECH9 | BO1: Def | BP1: Cont | BQ1: Cont(max) | BR1: Def rupt | BS1: E(mpa) | BU1: Elong.(mm) - ECH10 | BV1: Force(N) - ECH10 | BW1: Def | BX1: Cont | BY1: Cont(max) | BZ1: Def rupt | CA1: E(mpa) | CC1: Elong.(mm) - ECH11 | CD1: Force(N) - ECH11 | CE1: Def | CF1: Cont | CG1: Cont(max) | CH1: Def rupt | CI1: E(mpa) | CK1: Elong.(mm) - ECH12 | CL1: Force(N) - ECH12 | CM1: Def | CN1: Cont | CO1: Cont(max) | CP1: Def rupt | CQ1: E(mpa) | CS1: Elong.(mm) - ECH13 | CT1: Force(N) - ECH13 | CU1: Def | CV1: Cont | CW1: Cont(max) | CX1: Def rupt | CY1: E(mpa) | DA1: Elong.(mm) - ECH14 | DB1: Force(N) - ECH14 | DC1: Def | DD1: Cont | DE1: Cont(max) | DF1: Def rupt | DG1: E(mpa) | DI1: Elong.(mm) - ECH15 | DJ1: Force(N) - ECH15 | DK1: Def | DL1: Cont | DM1: Cont(max) | DN1: Def rupt | DO1: E(mpa) | DQ1: Elong.(mm) - ECH16 | DR1: Force(N) - ECH16 | DS1: Def | DT1: Cont | DU1: Cont(max) | DV1: Def rupt | DW1: E(mpa) | DY1: Elong.(mm) - ECH17 | DZ1: Force(N) - ECH17 | EA1: Def | EB1: Cont | EC1: Cont(max) | ED1: Def rupt | EE1: E(mpa) | EG1: Elong.(mm) - ECH18 | EH1: Force(N) - ECH18 | EI1: Def | EJ1: Cont | EK1: Cont(max) | EL1: Def rupt | EM1: E(mpa) | EO1: Elong.(mm) - ECH19 | EP1: Force(N) - ECH19 | EQ1: Def | ER1: Cont | ES1: Cont(max) | ET1: Def rupt | EU1: E(mpa) | EW1: Elong.(mm) - ECH20 | EX1: Force(N) - ECH20 | EY1: Def | EZ1: Cont | FA1: Cont(max) | FB1: Def rupt | FC1: E(mpa) | FE1: Elong.(mm) - ECH21 | FF1: Force(N) - ECH21 | FG1: Def | FH1: Cont | FI1: Cont(max) | FJ1: Def rupt | FK1: E(mpa) | FM1: Elong.(mm) - ECH22 | FN1: Force(N) - ECH22 | FO1: Def | FP1: Cont | FQ1: Cont(max) | FR1: Def rupt | FS1: E(mpa)
A2: 0 | B2: 0 | C2: =A2/20 -> 0 | D2: =B2/'DIAMETRE (CR,CS)'!$F$3 -> 0 | E2: =MAX(D2:D10) -> 22.508933 | F2: =INDEX(C2:C10,MATCH(E2,D2:D10,0)) -> 0.01425 | G2: =SLOPE(D2:D6,C2:C6) -> 1433.2824 | I2: 0 | J2: 0 | K2: =I2/20 -> 0 | L2: =J2/'DIAMETRE (CR,CS)'!$F$4 -> 0 | M2: =MAX(L2:L11) -> 78.252392 | N2: =INDEX(K2:K11,MATCH(M2,L2:L11,0)) -> 0.02295 | O2: =SLOPE(L4:L7,K4:K7) -> 5798.3427 | Q2: 0 | R2: 0 | S2: =Q2/20 -> 0 | T2: =R2/'DIAMETRE (CR,CS)'!$F$5 -> 0 | U2: =MAX(T2:T14) -> 51.586663 | V2: =INDEX(S2:S14,MATCH(U2,T2:T14,0)) -> 0.0281 | W2: =SLOPE(T3:T6,S3:S6) -> 2098.1405 | Y2: 0 | Z2: 0 | AA2: =Y2/20 -> 0 | AB2: =Z2/'DIAMETRE (CR,CS)'!$F$6 -> 0 | AC2: =MAX(AB2:AB14) -> 9.3074023 | AD2: =INDEX(AA2:AA14,MATCH(AC2,AB2:AB14,0)) -> 0.04185 | AE2: =SLOPE(AB2:AB11,AA2:AA11) -> 210.42701 | AG2: 0 | AH2: 0 | AI2: =AG2/20 -> 0 | AJ2: =AH2/'DIAMETRE (CR,CS)'!$F$7 -> 0 | AK2: =MAX(AJ2:AJ12) -> 11.761934 | AL2: =INDEX(AI2:AI12,MATCH(AK2,AJ2:AJ12,0)) -> 0.03925 | AM2: =SLOPE(AJ2:AJ11,AI2:AI11) -> 310.10971 | AO2: 0 | AP2: 0 | AQ2: =AO2/20 -> 0 | AR2: =AP2/'DIAMETRE (CR,CS)'!$F$8 -> 0 | AS2: =MAX(AR2:AR15) -> 80.569465 | AT2: =INDEX(AQ2:AQ15,MATCH(AS2,AR2:AR15,0)) -> 0.02175 | AU2: =SLOPE(AR3:AR7,AQ3:AQ7) -> 3926.8278 | AW2: 0 | AX2: 0 | AY2: =AW2/20 -> 0 | AZ2: =AX2/'DIAMETRE (CR,CS)'!$F$9 -> 0 | BA2: =MAX(AZ2:AZ14) -> 103.36009 | BB2: =INDEX(AY2:AY14,MATCH(BA2,AZ2:AZ14,0)) -> 0.02775 | BC2: =SLOPE(AZ3:AZ9,AY3:AY9) -> 4967.3487 | BE2: 0 | BF2: 0 | BG2: =BE2/20 -> 0 | BH2: =BF2/'DIAMETRE (CR,CS)'!$F$10 -> 0 | BI2: =MAX(BH2:BH20) -> 247.01902 | BJ2: =INDEX(BG2:BG20,MATCH(BI2,BH2:BH20,0)) -> 0.05465 | BK2: =SLOPE(BH3:BH12,BG3:BG12) -> 4865.5698 | BM2: 0 | BN2: 0 | BO2: =BM2/20 -> 0 | BP2: =BN2/'DIAMETRE (CR,CS)'!$F$11 -> 0 | BQ2: =MAX(BP2:BP11) -> 7.630712 | BR2: =INDEX(BO2:BO11,MATCH(BQ2,BP2:BP11,0)) -> 0.02275 | BS2: =SLOPE(BP3:BP7,BO3:BO7) -> 480.79276 | BU2: 0 | BV2: 0 | BW2: =BU2/20 -> 0 | BX2: =BV2/'DIAMETRE (CR,CS)'!$F$12 -> 0 | BY2: =MAX(BX2:BX20) -> 163.21806 | BZ2: =INDEX(BW2:BW20,MATCH(BY2,BX2:BX20,0)) -> 0.05025 | CA2: =SLOPE(BX2:BX11,BW2:BW11) -> 3339.7371 | CC2: 0 | CD2: 0 | CE2: =CC2/20 -> 0 | CF2: =CD2/'DIAMETRE (CR,CS)'!$F$13 -> 0 | CG2: =MAX(CF2:CF13) -> 15.316599 | CH2: =INDEX(CE2:CE13,MATCH(CG2,CF2:CF13,0)) -> 0.03375 | CI2: =SLOPE(CF3:CF10,CE3:CE10) -> 582.60411 | CK2: 0 | CL2: 0 | CM2: =CK2/20 -> 0 | CN2: =CL2/'DIAMETRE (CR,CS)'!$F$14 -> 0 | CO2: =MAX(CN2:CN11) -> 28.865854 | CP2: =INDEX(CM2:CM11,MATCH(CO2,CN2:CN11,0)) -> 0.03225 | CQ2: =SLOPE(CN2:CN11,CM2:CM11) -> 913.71459 | CS2: 0 | CT2: 0 | CU2: =CS2/20 -> 0 | CV2: =CT2/'DIAMETRE (CR,CS)'!$F$15 -> 0 | CW2: =MAX(CV2:CV18) -> 161.46026 | CX2: =INDEX(CU2:CU18,MATCH(CW2,CV2:CV18,0)) -> 0.0495 | CY2: =SLOPE(CV2:CV11,CU2:CU11) -> 3545.3148 | DA2: 0 | DB2: 0 | DC2: =DA2/20 -> 0 | DD2: =DB2/'DIAMETRE (CR,CS)'!$F$16 -> 0 | DE2: =MAX(DD2:DD13) -> 257.60284 | DF2: =INDEX(DC2:DC13,MATCH(DE2,DD2:DD13,0)) -> 0.02905 | DG2: =SLOPE(DD3:DD9,DC3:DC9) -> 11697.519 | DI2: 0 | DJ2: 0 | DK2: =DI2/20 -> 0 | DL2: =DJ2/'DIAMETRE (CR,CS)'!$F$17 -> 0 | DM2: =MAX(DL2:DL22) -> 534.261 | DN2: =INDEX(DK2:DK22,MATCH(DM2,DL2:DL22,0)) -> 0.059 | DO2: =SLOPE(DL2:DL11,DK2:DK11) -> 10286.18 | DQ2: 0 | DR2: 0 | DS2: =DQ2/20 -> 0 | DT2: =DR2/'DIAMETRE (CR,CS)'!$F$18 -> 0 | DU2: =MAX(DT2:DT18) -> 437.3348 | DV2: =INDEX(DS2:DS18,MATCH(DU2,DT2:DT18,0)) -> 0.049 | DW2: =SLOPE(DT3:DT12,DS3:DS12) -> 13673.066 | DY2: 0 | DZ2: 0 | EA2: =DY2/20 -> 0 | EB2: =DZ2/'DIAMETRE (CR,CS)'!$F$19 -> 0 | EC2: =MAX(EB2:EB16) -> 221.8169 | ED2: =INDEX(EA2:EA16,MATCH(EC2,EB2:EB16,0)) -> 0.03955 | EE2: =SLOPE(EB3:EB12,EA3:EA12) -> 7148.9565 | EG2: 0 | EH2: 0 | EI2: =EG2/20 -> 0 | EJ2: =EH2/'DIAMETRE (CR,CS)'!$F$20 -> 0 | EK2: =MAX(EJ2:EJ10) -> 254.45536 | EL2: =INDEX(EI2:EI10,MATCH(EK2,EJ2:EJ10,0)) -> 0.0223 | EM2: =SLOPE(EJ3:EJ7,EI3:EI7) -> 16303.422 | EO2: 0 | EP2: 0 | EQ2: =EO2/20 -> 0 | ER2: =EP2/'DIAMETRE (CR,CS)'!$F$21 -> 0 | ES2: =MAX(ER2:ER10) -> 183.29733 | ET2: =INDEX(EQ2:EQ10,MATCH(ES2,ER2:ER10,0)) -> 0.0235 | EU2: =SLOPE(ER3:ER6,EQ3:EQ6) -> 13671.353 | EW2: 0 | EX2: 0 | EY2: =EW2/20 -> 0 | EZ2: =EX2/'DIAMETRE (CR,CS)'!$F$22 -> 0 | FA2: =MAX(EZ2:EZ9) -> 225.98644 | FB2: =INDEX(EY2:EY9,MATCH(FA2,EZ2:EZ9,0)) -> 0.03135 | FC2: =SLOPE(EZ2:EZ9,EY2:EY9) -> 7624.8567 | FE2: 0 | FF2: 0 | FG2: =FE2/20 -> 0 | FH2: =FF2/'DIAMETRE (CR,CS)'!$F$23 -> 0 | FI2: =MAX(FH2:FH11) -> 455.18546 | FJ2: =INDEX(FG2:FG11,MATCH(FI2,FH2:FH11,0)) -> 0.01975 | FK2: =SLOPE(FH3:FH7,FG3:FG7) -> 30323.618 | FM2: 0.004 | FN2: 0 | FO2: =FM2/20 -> 0.0002 | FP2: =FN2/'DIAMETRE (CR,CS)'!$F$24 -> 0 | FQ2: =MAX(FP2:FP13) -> 21.786076 | FR2: =INDEX(FO2:FO13,MATCH(FQ2,FP2:FP13,0)) -> 0.04785 | FS2: =SLOPE(FP2:FP11,FO2:FO11) -> 457.21041
A3: 0.16 | B3: 0.133 | C3: =A3/20 -> 0.008 | D3: =B3/'DIAMETRE (CR,CS)'!$F$3 -> 5.7240691 | I3: 0.16 | J3: 0.236 | K3: =I3/20 -> 0.008 | L3: =J3/'DIAMETRE (CR,CS)'!$F$4 -> 7.2678334 | Q3: 0.152 | R3: 0.079 | S3: =Q3/20 -> 0.0076 | T3: =R3/'DIAMETRE (CR,CS)'!$F$5 -> 2.8459123 | Y3: 0.085 | Z3: 0.084 | AA3: =Y3/20 -> 0.00425 | AB3: =Z3/'DIAMETRE (CR,CS)'!$F$6 -> 0.9511214 | AG3: 0.155 | AH3: 0.055 | AI3: =AG3/20 -> 0.00775 | AJ3: =AH3/'DIAMETRE (CR,CS)'!$F$7 -> 0.92151901 | AO3: 0.165 | AP3: 0.4 | AQ3: =AO3/20 -> 0.00825 | AR3: =AP3/'DIAMETRE (CR,CS)'!$F$8 -> 8.5078632 | AW3: 0.14 | AX3: 0.192 | AY3: =AW3/20 -> 0.007 | AZ3: =AX3/'DIAMETRE (CR,CS)'!$F$9 -> 4.7026391 | BE3: 0.152 | BF3: 0.084 | BG3: =BE3/20 -> 0.0076 | BH3: =BF3/'DIAMETRE (CR,CS)'!$F$10 -> 3.4010158 | BM3: 0.156 | BN3: 0.101 | BO3: =BM3/20 -> 0.0078 | BP3: =BN3/'DIAMETRE (CR,CS)'!$F$11 -> 0.67134313 | BU3: 0.154 | BV3: 0.126 | BW3: =BU3/20 -> 0.0077 | BX3: =BV3/'DIAMETRE (CR,CS)'!$F$12 -> 5.2786127 | CC3: 0.167 | CD3: 0.113 | CE3: =CC3/20 -> 0.00835 | CF3: =CD3/'DIAMETRE (CR,CS)'!$F$13 -> 1.1546202 | CK3: 0.16 | CL3: 0.069 | CM3: =CK3/20 -> 0.008 | CN3: =CL3/'DIAMETRE (CR,CS)'!$F$14 -> 3.6884146 | CS3: 0.158 | CT3: 0.172 | CU3: =CS3/20 -> 0.0079 | CV3: =CT3/'DIAMETRE (CR,CS)'!$F$15 -> 5.7201165 | DA3: 0.155 | DB3: 0.317 | DC3: =DA3/20 -> 0.00775 | DD3: =DB3/'DIAMETRE (CR,CS)'!$F$16 -> 19.021686 | DI3: 0.152 | DJ3: 0.153 | DK3: =DI3/20 -> 0.0076 | DL3: =DJ3/'DIAMETRE (CR,CS)'!$F$17 -> 20.847216 | DQ3: 0.142 | DR3: 0.172 | DS3: =DQ3/20 -> 0.0071 | DT3: =DR3/'DIAMETRE (CR,CS)'!$F$18 -> 20.642587 | DY3: 0.159 | DZ3: 0.135 | EA3: =DY3/20 -> 0.00795 | EB3: =DZ3/'DIAMETRE (CR,CS)'!$F$19 -> 8.8963997 | EG3: 0.155 | EH3: 0.295 | EI3: =EG3/20 -> 0.00775 | EJ3: =EH3/'DIAMETRE (CR,CS)'!$F$20 -> 28.401185 | EO3: 0.169 | EP3: 0.63 | EQ3: =EO3/20 -> 0.00845 | ER3: =EP3/'DIAMETRE (CR,CS)'!$F$21 -> 29.109483 | EW3: 0.155 | EX3: 0.069 | EY3: =EW3/20 -> 0.00775 | EZ3: =EX3/'DIAMETRE (CR,CS)'!$F$22 -> 28.351026 | FE3: 0.114 | FF3: 0.417 | FG3: =FE3/20 -> 0.0057 | FH3: =FF3/'DIAMETRE (CR,CS)'!$F$23 -> 34.904807 | FM3: 0.228 | FN3: 0.224 | FO3: =FM3/20 -> 0.0114 | FP3: =FN3/'DIAMETRE (CR,CS)'!$F$24 -> 5.1207566
A4: 0.224 | B4: 0.329 | C4: =A4/20 -> 0.0112 | D4: =B4/'DIAMETRE (CR,CS)'!$F$3 -> 14.159539 | I4: 0.255 | J4: 0.646 | K4: =I4/20 -> 0.01275 | L4: =J4/'DIAMETRE (CR,CS)'!$F$4 -> 19.894154 | Q4: 0.222 | R4: 0.224 | S4: =Q4/20 -> 0.0111 | T4: =R4/'DIAMETRE (CR,CS)'!$F$5 -> 8.0694222 | Y4: 0.195 | Z4: 0.148 | AA4: =Y4/20 -> 0.00975 | AB4: =Z4/'DIAMETRE (CR,CS)'!$F$6 -> 1.6757853 | AG4: 0.21 | AH4: 0.125 | AI4: =AG4/20 -> 0.0105 | AJ4: =AH4/'DIAMETRE (CR,CS)'!$F$7 -> 2.0943614 | AO4: 0.165 | AP4: 0.797 | AQ4: =AO4/20 -> 0.00825 | AR4: =AP4/'DIAMETRE (CR,CS)'!$F$8 -> 16.951917 | AW4: 0.212 | AX4: 0.537 | AY4: =AW4/20 -> 0.0106 | AZ4: =AX4/'DIAMETRE (CR,CS)'!$F$9 -> 13.152694 | BE4: 0.224 | BF4: 0.251 | BG4: =BE4/20 -> 0.0112 | BH4: =BF4/'DIAMETRE (CR,CS)'!$F$10 -> 10.162559 | BM4: 0.237 | BN4: 0.275 | BO4: =BM4/20 -> 0.01185 | BP4: =BN4/'DIAMETRE (CR,CS)'!$F$11 -> 1.8279145 | BU4: 0.222 | BV4: 0.326 | BW4: =BU4/20 -> 0.0111 | BX4: =BV4/'DIAMETRE (CR,CS)'!$F$12 -> 13.657363 | CC4: 0.235 | CD4: 0.265 | CE4: =CC4/20 -> 0.01175 | CF4: =CD4/'DIAMETRE (CR,CS)'!$F$13 -> 2.7077376 | CK4: 0.231 | CL4: 0.148 | CM4: =CK4/20 -> 0.01155 | CN4: =CL4/'DIAMETRE (CR,CS)'!$F$14 -> 7.9113821 | CS4: 0.223 | CT4: 0.442 | CU4: =CS4/20 -> 0.01115 | CV4: =CT4/'DIAMETRE (CR,CS)'!$F$15 -> 14.699369 | DA4: 0.236 | DB4: 0.787 | DC4: =DA4/20 -> 0.0118 | DD4: =DB4/'DIAMETRE (CR,CS)'!$F$16 -> 47.224187 | DI4: 0.222 | DJ4: 0.385 | DK4: =DI4/20 -> 0.0111 | DL4: =DJ4/'DIAMETRE (CR,CS)'!$F$17 -> 52.45868 | DQ4: 0.212 | DR4: 0.459 | DS4: =DQ4/20 -> 0.0106 | DT4: =DR4/'DIAMETRE (CR,CS)'!$F$18 -> 55.086903 | DY4: 0.224 | DZ4: 0.358 | EA4: =DY4/20 -> 0.0112 | EB4: =DZ4/'DIAMETRE (CR,CS)'!$F$19 -> 23.591934 | EG4: 0.217 | EH4: 0.788 | EI4: =EG4/20 -> 0.01085 | EJ4: =EH4/'DIAMETRE (CR,CS)'!$F$20 -> 75.864859 | EO4: 0.22 | EP4: 1.457 | EQ4: =EO4/20 -> 0.011 | ER4: =EP4/'DIAMETRE (CR,CS)'!$F$21 -> 67.321455 | EW4: 0.224 | EX4: 0.145 | EY4: =EW4/20 -> 0.0112 | EZ4: =EX4/'DIAMETRE (CR,CS)'!$F$22 -> 59.578243 | FE4: 0.184 | FF4: 1.158 | FG4: =FE4/20 -> 0.0092 | FH4: =FF4/'DIAMETRE (CR,CS)'!$F$23 -> 96.929894 | FM4: 0.3 | FN4: 0.296 | FO4: =FM4/20 -> 0.015 | FP4: =FN4/'DIAMETRE (CR,CS)'!$F$24 -> 6.766714
A5: 0.285 | B5: 0.523 | C5: =A5/20 -> 0.01425 | D5: =B5/'DIAMETRE (CR,CS)'!$F$3 -> 22.508933 | I5: 0.32 | J5: 1.163 | K5: =I5/20 -> 0.016 | L5: =J5/'DIAMETRE (CR,CS)'!$F$4 -> 35.815636 | Q5: 0.295 | R5: 0.427 | S5: =Q5/20 -> 0.01475 | T5: =R5/'DIAMETRE (CR,CS)'!$F$5 -> 15.382336 | Y5: 0.279 | Z5: 0.21 | AA5: =Y5/20 -> 0.01395 | AB5: =Z5/'DIAMETRE (CR,CS)'!$F$6 -> 2.3778035 | AG5: 0.28 | AH5: 0.217 | AI5: =AG5/20 -> 0.014 | AJ5: =AH5/'DIAMETRE (CR,CS)'!$F$7 -> 3.6358114 | AO5: 0.302 | AP5: 1.467 | AQ5: =AO5/20 -> 0.0151 | AR5: =AP5/'DIAMETRE (CR,CS)'!$F$8 -> 31.202588 | AW5: 0.276 | AX5: 1.04 | AY5: =AW5/20 -> 0.0138 | AZ5: =AX5/'DIAMETRE (CR,CS)'!$F$9 -> 25.472629 | BE5: 0.224 | BF5: 0.417 | BG5: =BE5/20 -> 0.0112 | BH5: =BF5/'DIAMETRE (CR,CS)'!$F$10 -> 16.883614 | BM5: 0.32 | BN5: 0.528 | BO5: =BM5/20 -> 0.016 | BP5: =BN5/'DIAMETRE (CR,CS)'!$F$11 -> 3.5095958 | BU5: 0.295 | BV5: 0.586 | BW5: =BU5/20 -> 0.01475 | BX5: =BV5/'DIAMETRE (CR,CS)'!$F$12 -> 24.549738 | CC5: 0.31 | CD5: 0.464 | CE5: =CC5/20 -> 0.0155 | CF5: =CD5/'DIAMETRE (CR,CS)'!$F$13 -> 4.7410953 | CK5: 0.3 | CL5: 0.215 | CM5: =CK5/20 -> 0.015 | CN5: =CL5/'DIAMETRE (CR,CS)'!$F$14 -> 11.492886 | CS5: 0.302 | CT5: 0.822 | CU5: =CS5/20 -> 0.0151 | CV5: =CT5/'DIAMETRE (CR,CS)'!$F$15 -> 27.336836 | DA5: 0.3 | DB5: 1.381 | DC5: =DA5/20 -> 0.015 | DD5: =DB5/'DIAMETRE (CR,CS)'!$F$16 -> 82.867347 | DI5: 0.28 | DJ5: 0.669 | DK5: =DI5/20 -> 0.014 | DL5: =DJ5/'DIAMETRE (CR,CS)'!$F$17 -> 91.155473 | DQ5: 0.283 | DR5: 0.827 | DS5: =DQ5/20 -> 0.01415 | DT5: =DR5/'DIAMETRE (CR,CS)'!$F$18 -> 99.252437 | DY5: 0.309 | DZ5: 0.695 | EA5: =DY5/20 -> 0.01545 | EB5: =DZ5/'DIAMETRE (CR,CS)'!$F$19 -> 45.799984 | EG5: 0.282 | EH5: 1.447 | EI5: =EG5/20 -> 0.0141 | EJ5: =EH5/'DIAMETRE (CR,CS)'!$F$20 -> 139.31022 | EO5: 0.299 | EP5: 2.538 | EQ5: =EO5/20 -> 0.01495 | ER5: =EP5/'DIAMETRE (CR,CS)'!$F$21 -> 117.26963 | EW5: 0.3 | EX5: 0.23 | EY5: =EW5/20 -> 0.015 | EZ5: =EX5/'DIAMETRE (CR,CS)'!$F$22 -> 94.503419 | FE5: 0.254 | FF5: 2.303 | FG5: =FE5/20 -> 0.0127 | FH5: =FF5/'DIAMETRE (CR,CS)'!$F$23 -> 192.77163 | FM5: 0.362 | FN5: 0.358 | FO5: =FM5/20 -> 0.0181 | FP5: =FN5/'DIAMETRE (CR,CS)'!$F$24 -> 8.1840663
A6: 0.35 | B6: 0.522 | C6: =A6/20 -> 0.0175 | D6: =B6/'DIAMETRE (CR,CS)'!$F$3 -> 22.465895 | I6: 0.377 | J6: 1.778 | K6: =I6/20 -> 0.01885 | L6: =J6/'DIAMETRE (CR,CS)'!$F$4 -> 54.755117 | Q6: 0.357 | R6: 0.682 | S6: =Q6/20 -> 0.01785 | T6: =R6/'DIAMETRE (CR,CS)'!$F$5 -> 24.568509 | Y6: 0.343 | Z6: 0.28 | AA6: =Y6/20 -> 0.01715 | AB6: =Z6/'DIAMETRE (CR,CS)'!$F$6 -> 3.1704047 | AG6: 0.372 | AH6: 0.3 | AI6: =AG6/20 -> 0.0186 | AJ6: =AH6/'DIAMETRE (CR,CS)'!$F$7 -> 5.0264673 | AO6: 0.365 | AP6: 2.266 | AQ6: =AO6/20 -> 0.01825 | AR6: =AP6/'DIAMETRE (CR,CS)'!$F$8 -> 48.197045 | AW6: 0.34 | AX6: 1.7 | AY6: =AW6/20 -> 0.017 | AZ6: =AX6/'DIAMETRE (CR,CS)'!$F$9 -> 41.637951 | BE6: 0.342 | BF6: 0.721 | BG6: =BE6/20 -> 0.0171 | BH6: =BF6/'DIAMETRE (CR,CS)'!$F$10 -> 29.192052 | BM6: 0.32 | BN6: 0.78 | BO6: =BM6/20 -> 0.016 | BP6: =BN6/'DIAMETRE (CR,CS)'!$F$11 -> 5.1846301 | BU6: 0.343 | BV6: 0.891 | BW6: =BU6/20 -> 0.01715 | BX6: =BV6/'DIAMETRE (CR,CS)'!$F$12 -> 37.327332 | CC6: 0.372 | CD6: 0.704 | CE6: =CC6/20 -> 0.0186 | CF6: =CD6/'DIAMETRE (CR,CS)'!$F$13 -> 7.193386 | CK6: 0.379 | CL6: 0.274 | CM6: =CK6/20 -> 0.01895 | CN6: =CL6/'DIAMETRE (CR,CS)'!$F$14 -> 14.646748 | CS6: 0.378 | CT6: 1.297 | CU6: =CS6/20 -> 0.0189 | CV6: =CT6/'DIAMETRE (CR,CS)'!$F$15 -> 43.133669 | DA6: 0.36 | DB6: 2.097 | DC6: =DA6/20 -> 0.018 | DD6: =DB6/'DIAMETRE (CR,CS)'!$F$16 -> 125.83116 | DI6: 0.341 | DJ6: 1.003 | DK6: =DI6/20 -> 0.01705 | DL6: =DJ6/'DIAMETRE (CR,CS)'!$F$17 -> 136.66508 | DQ6: 0.343 | DR6: 1.268 | DS6: =DQ6/20 -> 0.01715 | DT6: =DR6/'DIAMETRE (CR,CS)'!$F$18 -> 152.17907 | DY6: 0.38 | DZ6: 1.118 | EA6: =DY6/20 -> 0.019 | EB6: =DZ6/'DIAMETRE (CR,CS)'!$F$19 -> 73.675369 | EG6: 0.37 | EH6: 2.327 | EI6: =EG6/20 -> 0.0185 | EJ6: =EH6/'DIAMETRE (CR,CS)'!$F$20 -> 224.03239 | EO6: 0.39 | EP6: 3.933 | EQ6: =EO6/20 -> 0.0195 | ER6: =EP6/'DIAMETRE (CR,CS)'!$F$21 -> 181.72634 | EW6: 0.385 | EX6: 0.3 | EY6: =EW6/20 -> 0.01925 | EZ6: =EX6/'DIAMETRE (CR,CS)'!$F$22 -> 123.26533 | FE6: 0.325 | FF6: 3.847 | FG6: =FE6/20 -> 0.01625 | FH6: =FF6/'DIAMETRE (CR,CS)'!$F$23 -> 322.01149 | FM6: 0.43 | FN6: 0.426 | FO6: =FM6/20 -> 0.0215 | FP6: =FN6/'DIAMETRE (CR,CS)'!$F$24 -> 9.7385817
A7: 0.422 | B7: 0.522 | C7: =A7/20 -> 0.0211 | D7: =B7/'DIAMETRE (CR,CS)'!$F$3 -> 22.465895 | I7: 0.459 | J7: 2.541 | K7: =I7/20 -> 0.02295 | L7: =J7/'DIAMETRE (CR,CS)'!$F$4 -> 78.252392 | Q7: 0.357 | R7: 0.937 | S7: =Q7/20 -> 0.01785 | T7: =R7/'DIAMETRE (CR,CS)'!$F$5 -> 33.754681 | Y7: 0.405 | Z7: 0.352 | AA7: =Y7/20 -> 0.02025 | AB7: =Z7/'DIAMETRE (CR,CS)'!$F$6 -> 3.9856516 | AG7: 0.455 | AH7: 0.36 | AI7: =AG7/20 -> 0.02275 | AJ7: =AH7/'DIAMETRE (CR,CS)'!$F$7 -> 6.0317608 | AO7: 0.435 | AP7: 3.227 | AQ7: =AO7/20 -> 0.02175 | AR7: =AP7/'DIAMETRE (CR,CS)'!$F$8 -> 68.637187 | AW7: 0.402 | AX7: 2.504 | AY7: =AW7/20 -> 0.0201 | AZ7: =AX7/'DIAMETRE (CR,CS)'!$F$9 -> 61.330252 | BE7: 0.422 | BF7: 1.138 | BG7: =BE7/20 -> 0.0211 | BH7: =BF7/'DIAMETRE (CR,CS)'!$F$10 -> 46.075666 | BM7: 0.455 | BN7: 1.148 | BO7: =BM7/20 -> 0.02275 | BP7: =BN7/'DIAMETRE (CR,CS)'!$F$11 -> 7.630712 | BU7: 0.411 | BV7: 1.268 | BW7: =BU7/20 -> 0.02055 | BX7: =BV7/'DIAMETRE (CR,CS)'!$F$12 -> 53.121277 | CC7: 0.447 | CD7: 0.969 | CE7: =CC7/20 -> 0.02235 | CF7: =CD7/'DIAMETRE (CR,CS)'!$F$13 -> 9.9011237 | CK7: 0.446 | CL7: 0.337 | CM7: =CK7/20 -> 0.0223 | CN7: =CL7/'DIAMETRE (CR,CS)'!$F$14 -> 18.014431 | CS7: 0.455 | CT7: 1.864 | CU7: =CS7/20 -> 0.02275 | CV7: =CT7/'DIAMETRE (CR,CS)'!$F$15 -> 61.9901 | DA7: 0.429 | DB7: 2.94 | DC7: =DA7/20 -> 0.02145 | DD7: =DB7/'DIAMETRE (CR,CS)'!$F$16 -> 176.41564 | DI7: 0.411 | DJ7: 1.388 | DK7: =DI7/20 -> 0.02055 | DL7: =DJ7/'DIAMETRE (CR,CS)'!$F$17 -> 189.12376 | DQ7: 0.408 | DR7: 1.781 | DS7: =DQ7/20 -> 0.0204 | DT7: =DR7/'DIAMETRE (CR,CS)'!$F$18 -> 213.74678 | DY7: 0.44 | DZ7: 1.595 | EA7: =DY7/20 -> 0.022 | EB7: =DZ7/'DIAMETRE (CR,CS)'!$F$19 -> 105.10931 | EG7: 0.446 | EH7: 2.643 | EI7: =EG7/20 -> 0.0223 | EJ7: =EH7/'DIAMETRE (CR,CS)'!$F$20 -> 254.45536 | EO7: 0.47 | EP7: 3.967 | EQ7: =EO7/20 -> 0.0235 | ER7: =EP7/'DIAMETRE (CR,CS)'!$F$21 -> 183.29733 | EW7: 0.455 | EX7: 0.382 | EY7: =EW7/20 -> 0.02275 | EZ7: =EX7/'DIAMETRE (CR,CS)'!$F$22 -> 156.95785 | FE7: 0.395 | FF7: 5.438 | FG7: =FE7/20 -> 0.01975 | FH7: =FF7/'DIAMETRE (CR,CS)'!$F$23 -> 455.18546 | FM7: 0.502 | FN7: 0.498 | FO7: =FM7/20 -> 0.0251 | FP7: =FN7/'DIAMETRE (CR,CS)'!$F$24 -> 11.384539
A8: 0.485 | B8: 0.39 | C8: =A8/20 -> 0.02425 | D8: =B8/'DIAMETRE (CR,CS)'!$F$3 -> 16.784864 | I8: 0.527 | J8: 2.305 | K8: =I8/20 -> 0.02635 | L8: =J8/'DIAMETRE (CR,CS)'!$F$4 -> 70.984559 | Q8: 0.48 | R8: 1.197 | S8: =Q8/20 -> 0.024 | T8: =R8/'DIAMETRE (CR,CS)'!$F$5 -> 43.120975 | Y8: 0.475 | Z8: 0.445 | AA8: =Y8/20 -> 0.02375 | AB8: =Z8/'DIAMETRE (CR,CS)'!$F$6 -> 5.0386788 | AG8: 0.515 | AH8: 0.425 | AI8: =AG8/20 -> 0.02575 | AJ8: =AH8/'DIAMETRE (CR,CS)'!$F$7 -> 7.1208287 | AO8: 0.435 | AP8: 3.788 | AQ8: =AO8/20 -> 0.02175 | AR8: =AP8/'DIAMETRE (CR,CS)'!$F$8 -> 80.569465 | AW8: 0.469 | AX8: 3.315 | AY8: =AW8/20 -> 0.02345 | AZ8: =AX8/'DIAMETRE (CR,CS)'!$F$9 -> 81.194004 | BE8: 0.48 | BF8: 1.574 | BG8: =BE8/20 -> 0.024 | BH8: =BF8/'DIAMETRE (CR,CS)'!$F$10 -> 63.728558 | BM8: 0.524 | BN8: 1.048 | BO8: =BM8/20 -> 0.0262 | BP8: =BN8/'DIAMETRE (CR,CS)'!$F$11 -> 6.9660159 | BU8: 0.48 | BV8: 1.589 | BW8: =BU8/20 -> 0.024 | BX8: =BV8/'DIAMETRE (CR,CS)'!$F$12 -> 66.569171 | CC8: 0.522 | CD8: 1.153 | CE8: =CC8/20 -> 0.0261 | CF8: =CD8/'DIAMETRE (CR,CS)'!$F$13 -> 11.781213 | CK8: 0.505 | CL8: 0.414 | CM8: =CK8/20 -> 0.02525 | CN8: =CL8/'DIAMETRE (CR,CS)'!$F$14 -> 22.130488 | CS8: 0.515 | CT8: 2.322 | CU8: =CS8/20 -> 0.02575 | CV8: =CT8/'DIAMETRE (CR,CS)'!$F$15 -> 77.221572 | DA8: 0.514 | DB8: 3.631 | DC8: =DA8/20 -> 0.0257 | DD8: =DB8/'DIAMETRE (CR,CS)'!$F$16 -> 217.87932 | DI8: 0.482 | DJ8: 1.656 | DK8: =DI8/20 -> 0.0241 | DL8: =DJ8/'DIAMETRE (CR,CS)'!$F$17 -> 225.64045 | DQ8: 0.477 | DR8: 2.204 | DS8: =DQ8/20 -> 0.02385 | DT8: =DR8/'DIAMETRE (CR,CS)'!$F$18 -> 264.51315 | DY8: 0.502 | DZ8: 1.998 | EA8: =DY8/20 -> 0.0251 | EB8: =DZ8/'DIAMETRE (CR,CS)'!$F$19 -> 131.66672 | EG8: 0.507 | EH8: 2.349 | EI8: =EG8/20 -> 0.02535 | EJ8: =EH8/'DIAMETRE (CR,CS)'!$F$20 -> 226.15045 | EO8: 0.547 | EP8: 3.529 | EQ8: =EO8/20 -> 0.02735 | ER8: =EP8/'DIAMETRE (CR,CS)'!$F$21 -> 163.05931 | EW8: 0.537 | EX8: 0.472 | EY8: =EW8/20 -> 0.02685 | EZ8: =EX8/'DIAMETRE (CR,CS)'!$F$22 -> 193.93745 | FE8: 0.46 | FF8: 5.019 | FG8: =FE8/20 -> 0.023 | FH8: =FF8/'DIAMETRE (CR,CS)'!$F$23 -> 420.11325 | FM8: 0.58 | FN8: 0.576 | FO8: =FM8/20 -> 0.029 | FP8: =FN8/'DIAMETRE (CR,CS)'!$F$24 -> 13.16766
A9: 0.554 | B9: 0.194 | C9: =A9/20 -> 0.0277 | D9: =B9/'DIAMETRE (CR,CS)'!$F$3 -> 8.349394 | I9: 0.587 | J9: 1.893 | K9: =I9/20 -> 0.02935 | L9: =J9/'DIAMETRE (CR,CS)'!$F$4 -> 58.296646 | Q9: 0.562 | R9: 1.432 | S9: =Q9/20 -> 0.0281 | T9: =R9/'DIAMETRE (CR,CS)'!$F$5 -> 51.586663 | Y9: 0.547 | Z9: 0.517 | AA9: =Y9/20 -> 0.02735 | AB9: =Z9/'DIAMETRE (CR,CS)'!$F$6 -> 5.8539258 | AG9: 0.58 | AH9: 0.506 | AI9: =AG9/20 -> 0.029 | AJ9: =AH9/'DIAMETRE (CR,CS)'!$F$7 -> 8.4779749 | AO9: 0.562 | AP9: 3.523 | AQ9: =AO9/20 -> 0.0281 | AR9: =AP9/'DIAMETRE (CR,CS)'!$F$8 -> 74.933005 | AW9: 0.555 | AX9: 4.22 | AY9: =AW9/20 -> 0.02775 | AZ9: =AX9/'DIAMETRE (CR,CS)'!$F$9 -> 103.36009 | BE9: 0.56 | BF9: 2.06 | BG9: =BE9/20 -> 0.028 | BH9: =BF9/'DIAMETRE (CR,CS)'!$F$10 -> 83.405864 | BM9: 0.587 | BN9: 0.875 | BO9: =BM9/20 -> 0.02935 | BP9: =BN9/'DIAMETRE (CR,CS)'!$F$11 -> 5.8160915 | BU9: 0.562 | BV9: 1.903 | BW9: =BU9/20 -> 0.0281 | BX9: =BV9/'DIAMETRE (CR,CS)'!$F$12 -> 79.723809 | CC9: 0.6 | CD9: 1.337 | CE9: =CC9/20 -> 0.03 | CF9: =CD9/'DIAMETRE (CR,CS)'!$F$13 -> 13.661303 | CK9: 0.568 | CL9: 0.474 | CM9: =CK9/20 -> 0.0284 | CN9: =CL9/'DIAMETRE (CR,CS)'!$F$14 -> 25.337805 | CS9: 0.602 | CT9: 2.771 | CU9: =CS9/20 -> 0.0301 | CV9: =CT9/'DIAMETRE (CR,CS)'!$F$15 -> 92.153737 | DA9: 0.581 | DB9: 4.293 | DC9: =DA9/20 -> 0.02905 | DD9: =DB9/'DIAMETRE (CR,CS)'!$F$16 -> 257.60284 | DI9: 0.561 | DJ9: 1.9 | DK9: =DI9/20 -> 0.02805 | DL9: =DJ9/'DIAMETRE (CR,CS)'!$F$17 -> 258.88699 | DQ9: 0.55 | DR9: 2.575 | DS9: =DQ9/20 -> 0.0275 | DT9: =DR9/'DIAMETRE (CR,CS)'!$F$18 -> 309.03872 | DY9: 0.57 | DZ9: 2.369 | EA9: =DY9/20 -> 0.0285 | EB9: =DZ9/'DIAMETRE (CR,CS)'!$F$19 -> 156.11534 | EG9: 0.57 | EH9: 1.857 | EI9: =EG9/20 -> 0.0285 | EJ9: =EH9/'DIAMETRE (CR,CS)'!$F$20 -> 178.78305 | EO9: 0.619 | EP9: 2.896 | EQ9: =EO9/20 -> 0.03095 | ER9: =EP9/'DIAMETRE (CR,CS)'!$F$21 -> 133.81121 | EW9: 0.627 | EX9: 0.55 | EY9: =EW9/20 -> 0.03135 | EZ9: =EX9/'DIAMETRE (CR,CS)'!$F$22 -> 225.98644 | FE9: 0.546 | FF9: 4.281 | FG9: =FE9/20 -> 0.0273 | FH9: =FF9/'DIAMETRE (CR,CS)'!$F$23 -> 358.33927 | FM9: 0.58 | FN9: 0.576 | FO9: =FM9/20 -> 0.029 | FP9: =FN9/'DIAMETRE (CR,CS)'!$F$24 -> 13.16766
A10: 0.625 | B10: 0.001 | C10: =A10/20 -> 0.03125 | D10: =B10/'DIAMETRE (CR,CS)'!$F$3 -> 0.043038113 | I10: 0.652 | J10: 1.376 | K10: =I10/20 -> 0.0326 | L10: =J10/'DIAMETRE (CR,CS)'!$F$4 -> 42.375164 | Q10: 0.64 | R10: 1.334 | S10: =Q10/20 -> 0.032 | T10: =R10/'DIAMETRE (CR,CS)'!$F$5 -> 48.056291 | Y10: 0.64 | Z10: 0.58 | AA10: =Y10/20 -> 0.032 | AB10: =Z10/'DIAMETRE (CR,CS)'!$F$6 -> 6.5672668 | AG10: 0.661 | AH10: 0.567 | AI10: =AG10/20 -> 0.03305 | AJ10: =AH10/'DIAMETRE (CR,CS)'!$F$7 -> 9.5000232 | AO10: 0.635 | AP10: 2.991 | AQ10: =AO10/20 -> 0.03175 | AR10: =AP10/'DIAMETRE (CR,CS)'!$F$8 -> 63.617547 | AW10: 0.62 | AX10: 4.129 | AY10: =AW10/20 -> 0.031 | AZ10: =AX10/'DIAMETRE (CR,CS)'!$F$9 -> 101.13123 | BE10: 0.641 | BF10: 2.68 | BG10: =BE10/20 -> 0.03205 | BH10: =BF10/'DIAMETRE (CR,CS)'!$F$10 -> 108.5086 | BM10: 0.667 | BN10: 0.621 | BO10: =BM10/20 -> 0.03335 | BP10: =BN10/'DIAMETRE (CR,CS)'!$F$11 -> 4.1277632 | BU10: 0.642 | BV10: 2.236 | BW10: =BU10/20 -> 0.0321 | BX10: =BV10/'DIAMETRE (CR,CS)'!$F$12 -> 93.674428 | CC10: 0.675 | CD10: 1.499 | CE10: =CC10/20 -> 0.03375 | CF10: =CD10/'DIAMETRE (CR,CS)'!$F$13 -> 15.316599 | CK10: 0.645 | CL10: 0.54 | CM10: =CK10/20 -> 0.03225 | CN10: =CL10/'DIAMETRE (CR,CS)'!$F$14 -> 28.865854 | CS10: 0.68 | CT10: 3.193 | CU10: =CS10/20 -> 0.034 | CV10: =CT10/'DIAMETRE (CR,CS)'!$F$15 -> 106.18798 | DA10: 0.645 | DB10: 3.7 | DC10: =DA10/20 -> 0.03225 | DD10: =DB10/'DIAMETRE (CR,CS)'!$F$16 -> 222.01968 | DI10: 0.632 | DJ10: 2.131 | DK10: =DI10/20 -> 0.0316 | DL10: =DJ10/'DIAMETRE (CR,CS)'!$F$17 -> 290.3622 | DQ10: 0.617 | DR10: 2.93 | DS10: =DQ10/20 -> 0.03085 | DT10: =DR10/'DIAMETRE (CR,CS)'!$F$18 -> 351.64406 | DY10: 0.645 | DZ10: 2.714 | EA10: =DY10/20 -> 0.03225 | EB10: =DZ10/'DIAMETRE (CR,CS)'!$F$19 -> 178.85058 | EG10: 0.631 | EH10: 1.197 | EI10: =EG10/20 -> 0.03155 | EJ10: =EH10/'DIAMETRE (CR,CS)'!$F$20 -> 115.24142 | EO10: 0.682 | EP10: 2.006 | EQ10: =EO10/20 -> 0.0341 | ER10: =EP10/'DIAMETRE (CR,CS)'!$F$21 -> 92.68829 | FE10: 0.612 | FF10: 3.134 | FG10: =FE10/20 -> 0.0306 | FH10: =FF10/'DIAMETRE (CR,CS)'!$F$23 -> 262.33013 | FM10: 0.74 | FN10: 0.736 | FO10: =FM10/20 -> 0.037 | FP10: =FN10/'DIAMETRE (CR,CS)'!$F$24 -> 16.825343
I11: 0.652 | J11: 0.76 | K11: =I11/20 -> 0.0326 | L11: =J11/'DIAMETRE (CR,CS)'!$F$4 -> 23.404887 | Q11: 0.712 | R11: 1.079 | S11: =Q11/20 -> 0.0356 | T11: =R11/'DIAMETRE (CR,CS)'!$F$5 -> 38.870119 | Y11: 0.712 | Z11: 0.642 | AA11: =Y11/20 -> 0.0356 | AB11: =Z11/'DIAMETRE (CR,CS)'!$F$6 -> 7.269285 | AG11: 0.722 | AH11: 0.63 | AI11: =AG11/20 -> 0.0361 | AJ11: =AH11/'DIAMETRE (CR,CS)'!$F$7 -> 10.555581 | AO11: 0.697 | AP11: 2.342 | AQ11: =AO11/20 -> 0.03485 | AR11: =AP11/'DIAMETRE (CR,CS)'!$F$8 -> 49.813539 | AW11: 0.685 | AX11: 3.47 | AY11: =AW11/20 -> 0.03425 | AZ11: =AX11/'DIAMETRE (CR,CS)'!$F$9 -> 84.990405 | BE11: 0.641 | BF11: 3.161 | BG11: =BE11/20 -> 0.03205 | BH11: =BF11/'DIAMETRE (CR,CS)'!$F$10 -> 127.98346 | BM11: 0.727 | BN11: 0.369 | BO11: =BM11/20 -> 0.03635 | BP11: =BN11/'DIAMETRE (CR,CS)'!$F$11 -> 2.4527289 | BU11: 0.71 | BV11: 2.577 | BW11: =BU11/20 -> 0.0355 | BX11: =BV11/'DIAMETRE (CR,CS)'!$F$12 -> 107.9602 | CC11: 0.752 | CD11: 1.26 | CE11: =CC11/20 -> 0.0376 | CF11: =CD11/'DIAMETRE (CR,CS)'!$F$13 -> 12.874526 | CK11: 0.705 | CL11: 0.54 | CM11: =CK11/20 -> 0.03525 | CN11: =CL11/'DIAMETRE (CR,CS)'!$F$14 -> 28.865854 | CS11: 0.744 | CT11: 3.594 | CU11: =CS11/20 -> 0.0372 | CV11: =CT11/'DIAMETRE (CR,CS)'!$F$15 -> 119.52383 | DA11: 0.708 | DB11: 2.982 | DC11: =DA11/20 -> 0.0354 | DD11: =DB11/'DIAMETRE (CR,CS)'!$F$16 -> 178.93586 | DI11: 0.694 | DJ11: 2.347 | DK11: =DI11/20 -> 0.0347 | DL11: =DJ11/'DIAMETRE (CR,CS)'!$F$17 -> 319.79357 | DQ11: 0.675 | DR11: 3.268 | DS11: =DQ11/20 -> 0.03375 | DT11: =DR11/'DIAMETRE (CR,CS)'!$F$18 -> 392.20915 | DY11: 0.712 | DZ11: 3.033 | EA11: =DY11/20 -> 0.0356 | EB11: =DZ11/'DIAMETRE (CR,CS)'!$F$19 -> 199.87245 | FE11: 0.667 | FF11: 1.589 | FG11: =FE11/20 -> 0.03335 | FH11: =FF11/'DIAMETRE (CR,CS)'!$F$23 -> 133.00656 | FM11: 0.8 | FN11: 0.796 | FO11: =FM11/20 -> 0.04 | FP11: =FN11/'DIAMETRE (CR,CS)'!$F$24 -> 18.196974
Q12: 0.776 | R12: 0.825 | S12: =Q12/20 -> 0.0388 | T12: =R12/'DIAMETRE (CR,CS)'!$F$5 -> 29.71997 | Y12: 0.775 | Z12: 0.642 | AA12: =Y12/20 -> 0.03875 | AB12: =Z12/'DIAMETRE (CR,CS)'!$F$6 -> 7.269285 | AG12: 0.785 | AH12: 0.702 | AI12: =AG12/20 -> 0.03925 | AJ12: =AH12/'DIAMETRE (CR,CS)'!$F$7 -> 11.761934 | AO12: 0.766 | AP12: 1.518 | AQ12: =AO12/20 -> 0.0383 | AR12: =AP12/'DIAMETRE (CR,CS)'!$F$8 -> 32.287341 | AW12: 0.747 | AX12: 2.666 | AY12: =AW12/20 -> 0.03735 | AZ12: =AX12/'DIAMETRE (CR,CS)'!$F$9 -> 65.298104 | BE12: 0.784 | BF12: 3.764 | BG12: =BE12/20 -> 0.0392 | BH12: =BF12/'DIAMETRE (CR,CS)'!$F$10 -> 152.3979 | BU12: 0.775 | BV12: 2.891 | BW12: =BU12/20 -> 0.03875 | BX12: =BV12/'DIAMETRE (CR,CS)'!$F$12 -> 121.11484 | CC12: 0.817 | CD12: 0.993 | CE12: =CC12/20 -> 0.04085 | CF12: =CD12/'DIAMETRE (CR,CS)'!$F$13 -> 10.146353 | CS12: 0.847 | CT12: 4.012 | CU12: =CS12/20 -> 0.04235 | CV12: =CT12/'DIAMETRE (CR,CS)'!$F$15 -> 133.42504 | DA12: 0.769 | DB12: 2.138 | DC12: =DA12/20 -> 0.03845 | DD12: =DB12/'DIAMETRE (CR,CS)'!$F$16 -> 128.29137 | DI12: 0.772 | DJ12: 2.563 | DK12: =DI12/20 -> 0.0386 | DL12: =DJ12/'DIAMETRE (CR,CS)'!$F$17 -> 349.22493 | DQ12: 0.755 | DR12: 3.384 | DS12: =DQ12/20 -> 0.03775 | DT12: =DR12/'DIAMETRE (CR,CS)'!$F$18 -> 406.13089 | DY12: 0.791 | DZ12: 3.366 | EA12: =DY12/20 -> 0.03955 | EB12: =DZ12/'DIAMETRE (CR,CS)'!$F$19 -> 221.8169 | FM12: 0.889 | FN12: 0.885 | FO12: =FM12/20 -> 0.04445 | FP12: =FN12/'DIAMETRE (CR,CS)'!$F$24 -> 20.231561
Q13: 0.862 | R13: 0.489 | S13: =Q13/20 -> 0.0431 | T13: =R13/'DIAMETRE (CR,CS)'!$F$5 -> 17.615837 | Y13: 0.837 | Z13: 0.763 | AA13: =Y13/20 -> 0.04185 | AB13: =Z13/'DIAMETRE (CR,CS)'!$F$6 -> 8.6393527 | AO13: 0.835 | AP13: 0.692 | AQ13: =AO13/20 -> 0.04175 | AR13: =AP13/'DIAMETRE (CR,CS)'!$F$8 -> 14.718603 | AW13: 0.827 | AX13: 1.666 | AY13: =AW13/20 -> 0.04135 | AZ13: =AX13/'DIAMETRE (CR,CS)'!$F$9 -> 40.805192 | BE13: 0.862 | BF13: 4.384 | BG13: =BE13/20 -> 0.0431 | BH13: =BF13/'DIAMETRE (CR,CS)'!$F$10 -> 177.50063 | BU13: 0.867 | BV13: 3.234 | BW13: =BU13/20 -> 0.04335 | BX13: =BV13/'DIAMETRE (CR,CS)'!$F$12 -> 135.48439 | CC13: 0.872 | CD13: 0.697 | CE13: =CC13/20 -> 0.0436 | CF13: =CD13/'DIAMETRE (CR,CS)'!$F$13 -> 7.1218609 | CS13: 0.915 | CT13: 4.441 | CU13: =CS13/20 -> 0.04575 | CV13: =CT13/'DIAMETRE (CR,CS)'!$F$15 -> 147.69208 | DA13: 0.84 | DB13: 1.131 | DC13: =DA13/20 -> 0.042 | DD13: =DB13/'DIAMETRE (CR,CS)'!$F$16 -> 67.866017 | DI13: 0.852 | DJ13: 2.773 | DK13: =DI13/20 -> 0.0426 | DL13: =DJ13/'DIAMETRE (CR,CS)'!$F$17 -> 377.83876 | DQ13: 0.836 | DR13: 3.48 | DS13: =DQ13/20 -> 0.0418 | DT13: =DR13/'DIAMETRE (CR,CS)'!$F$18 -> 417.65233 | DY13: 0.852 | DZ13: 2.83 | EA13: =DY13/20 -> 0.0426 | EB13: =DZ13/'DIAMETRE (CR,CS)'!$F$19 -> 186.4949 | FM13: 0.957 | FN13: 0.953 | FO13: =FM13/20 -> 0.04785 | FP13: =FN13/'DIAMETRE (CR,CS)'!$F$24 -> 21.786076
Q14: 0.934 | R14: 0.106 | S14: =Q14/20 -> 0.0467 | T14: =R14/'DIAMETRE (CR,CS)'!$F$5 -> 3.8185659 | Y14: 0.837 | Z14: 0.822 | AA14: =Y14/20 -> 0.04185 | AB14: =Z14/'DIAMETRE (CR,CS)'!$F$6 -> 9.3074023 | AO14: 0.9 | AP14: 0.697 | AQ14: =AO14/20 -> 0.045 | AR14: =AP14/'DIAMETRE (CR,CS)'!$F$8 -> 14.824952 | AW14: 0.902 | AX14: 0.413 | AY14: =AW14/20 -> 0.0451 | AZ14: =AX14/'DIAMETRE (CR,CS)'!$F$9 -> 10.115573 | BE14: 0.948 | BF14: 4.97 | BG14: =BE14/20 -> 0.0474 | BH14: =BF14/'DIAMETRE (CR,CS)'!$F$10 -> 201.22677 | BU14: 0.935 | BV14: 3.573 | BW14: =BU14/20 -> 0.04675 | BX14: =BV14/'DIAMETRE (CR,CS)'!$F$12 -> 149.68637 | CS14: 0.99 | CT14: 4.855 | CU14: =CS14/20 -> 0.0495 | CV14: =CT14/'DIAMETRE (CR,CS)'!$F$15 -> 161.46026 | DI14: 0.925 | DJ14: 2.974 | DK14: =DI14/20 -> 0.04625 | DL14: =DJ14/'DIAMETRE (CR,CS)'!$F$17 -> 405.22627 | DQ14: 0.915 | DR14: 3.567 | DS14: =DQ14/20 -> 0.04575 | DT14: =DR14/'DIAMETRE (CR,CS)'!$F$18 -> 428.09364 | DY14: 0.915 | DZ14: 2.237 | EA14: =DY14/20 -> 0.04575 | EB14: =DZ14/'DIAMETRE (CR,CS)'!$F$19 -> 147.41664
AO15: 0.972 | AP15: 0.7 | AQ15: =AO15/20 -> 0.0486 | AR15: =AP15/'DIAMETRE (CR,CS)'!$F$8 -> 14.888761 | BE15: 1.019 | BF15: 5.47 | BG15: =BE15/20 -> 0.05095 | BH15: =BF15/'DIAMETRE (CR,CS)'!$F$10 -> 221.47091 | BU15: 1.005 | BV15: 3.896 | BW15: =BU15/20 -> 0.05025 | BX15: =BV15/'DIAMETRE (CR,CS)'!$F$12 -> 163.21806 | CS15: 1.055 | CT15: 4.159 | CU15: =CS15/20 -> 0.05275 | CV15: =CT15/'DIAMETRE (CR,CS)'!$F$15 -> 138.31375 | DI15: 0.994 | DJ15: 3.183 | DK15: =DI15/20 -> 0.0497 | DL15: =DJ15/'DIAMETRE (CR,CS)'!$F$17 -> 433.70384 | DQ15: 0.98 | DR15: 3.644 | DS15: =DQ15/20 -> 0.049 | DT15: =DR15/'DIAMETRE (CR,CS)'!$F$18 -> 437.3348 | DY15: 0.976 | DZ15: 1.555 | EA15: =DY15/20 -> 0.0488 | EB15: =DZ15/'DIAMETRE (CR,CS)'!$F$19 -> 102.47334
BE16: 1.093 | BF16: 6.101 | BG16: =BE16/20 -> 0.05465 | BH16: =BF16/'DIAMETRE (CR,CS)'!$F$10 -> 247.01902 | BU16: 1.08 | BV16: 3.47 | BW16: =BU16/20 -> 0.054 | BX16: =BV16/'DIAMETRE (CR,CS)'!$F$12 -> 145.37132 | CS16: 1.118 | CT16: 3.283 | CU16: =CS16/20 -> 0.0559 | CV16: =CT16/'DIAMETRE (CR,CS)'!$F$15 -> 109.18106 | DI16: 1.06 | DJ16: 3.394 | DK16: =DI16/20 -> 0.053 | DL16: =DJ16/'DIAMETRE (CR,CS)'!$F$17 -> 462.45393 | DQ16: 1.042 | DR16: 2.864 | DS16: =DQ16/20 -> 0.0521 | DT16: =DR16/'DIAMETRE (CR,CS)'!$F$18 -> 343.72307 | DY16: 1.055 | DZ16: 0.812 | EA16: =DY16/20 -> 0.05275 | EB16: =DZ16/'DIAMETRE (CR,CS)'!$F$19 -> 53.510197
BE17: 1.166 | BF17: 6.083 | BG17: =BE17/20 -> 0.0583 | BH17: =BF17/'DIAMETRE (CR,CS)'!$F$10 -> 246.29023 | BU17: 1.159 | BV17: 2.78 | BW17: =BU17/20 -> 0.05795 | BX17: =BV17/'DIAMETRE (CR,CS)'!$F$12 -> 116.46463 | CS17: 1.18 | CT17: 2.3 | CU17: =CS17/20 -> 0.059 | CV17: =CT17/'DIAMETRE (CR,CS)'!$F$15 -> 76.48993 | DI17: 1.115 | DJ17: 3.575 | DK17: =DI17/20 -> 0.05575 | DL17: =DJ17/'DIAMETRE (CR,CS)'!$F$17 -> 487.11632 | DQ17: 1.107 | DR17: 2.236 | DS17: =DQ17/20 -> 0.05535 | DT17: =DR17/'DIAMETRE (CR,CS)'!$F$18 -> 268.35363
BE18: 1.239 | BF18: 4.945 | BG18: =BE18/20 -> 0.06195 | BH18: =BF18/'DIAMETRE (CR,CS)'!$F$10 -> 200.21456 | BU18: 1.235 | BV18: 1.991 | BW18: =BU18/20 -> 0.06175 | BX18: =BV18/'DIAMETRE (CR,CS)'!$F$12 -> 83.410459 | CS18: 1.262 | CT18: 1.241 | CU18: =CS18/20 -> 0.0631 | CV18: =CT18/'DIAMETRE (CR,CS)'!$F$15 -> 41.271306 | DI18: 1.18 | DJ18: 3.772 | DK18: =DI18/20 -> 0.059 | DL18: =DJ18/'DIAMETRE (CR,CS)'!$F$17 -> 513.95881 | DQ18: 1.179 | DR18: 1.545 | DS18: =DQ18/20 -> 0.05895 | DT18: =DR18/'DIAMETRE (CR,CS)'!$F$18 -> 185.42323
BE19: 1.307 | BF19: 3.707 | BG19: =BE19/20 -> 0.06535 | BH19: =BF19/'DIAMETRE (CR,CS)'!$F$10 -> 150.09007 | BU19: 1.31 | BV19: 1.138 | BW19: =BU19/20 -> 0.0655 | BX19: =BV19/'DIAMETRE (CR,CS)'!$F$12 -> 47.675089 | DI19: 1.18 | DJ19: 3.921 | DK19: =DI19/20 -> 0.059 | DL19: =DJ19/'DIAMETRE (CR,CS)'!$F$17 -> 534.261
BE20: 1.372 | BF20: 2.42 | BG20: =BE20/20 -> 0.0686 | BH20: =BF20/'DIAMETRE (CR,CS)'!$F$10 -> 97.981646 | BU20: 1.387 | BV20: 0.222 | BW20: =BU20/20 -> 0.06935 | BX20: =BV20/'DIAMETRE (CR,CS)'!$F$12 -> 9.3004128 | DI20: 1.3 | DJ20: 3.198 | DK20: =DI20/20 -> 0.065 | DL20: =DJ20/'DIAMETRE (CR,CS)'!$F$17 -> 435.74769
DI21: 1.38 | DJ21: 2.437 | DK21: =DI21/20 -> 0.069 | DL21: =DJ21/'DIAMETRE (CR,CS)'!$F$17 -> 332.05663
DI22: 1.461 | DJ22: 1.655 | DK22: =DI22/20 -> 0.07305 | DL22: =DJ22/'DIAMETRE (CR,CS)'!$F$17 -> 225.5042

Sheet COSOU
A1: Elong.(mm) - ECH1 | B1: Force(N) - ECH1 | C1: Def | D1: Cont | E1: Cont(max) | F1: Def rupt | G1: E(mpa) | I1: Elong.(mm) - ECH2 | J1: Force(N) - ECH2 | K1: Def | L1: Cont | M1: Cont(max) | N1: Def rupt | O1: E(mpa) | Q1: Elong.(mm) - ECH3 | R1: Force(N) - ECH3 | S1: Def | T1: Cont | U1: Cont(max) | V1: Def rupt | W1: E(mpa) | Y1: Elong.(mm) - ECH4 | Z1: Force(N) - ECH4 | AA1: Def | AB1: Cont | AC1: Cont(max) | AD1: Def rupt | AE1: E(mpa) | AG1: Elong.(mm) - ECH5 | AH1: Force(N) - ECH5 | AI1: Def | AJ1: Cont | AK1: Cont(max) | AL1: Def rupt | AM1: E(mpa) | AO1: Elong.(mm) - ECH6 | AP1: Force(N) - ECH6 | AQ1: Def | AR1: Cont | AS1: Cont(max) | AT1: Def rupt | AU1: E(mpa) | AW1: Elong.(mm) - ECH7 | AX1: Force(N) - ECH7 | AY1: Def | AZ1: Cont | BA1: Cont(max) | BB1: Def rupt | BC1: E(mpa) | BE1: Elong.(mm) - ECH8 | BF1: Force(N) - ECH8 | BG1: Def | BH1: Cont | BI1: Cont(max) | BJ1: Def rupt | BK1: E(mpa) | BM1: Elong.(mm) - ECH9 | BN1: Force(N) - ECH9 | BO1: Def | BP1: Cont | BQ1: Cont(max) | BR1: Def rupt | BS1: E(mpa) | BU1: Elong.(mm) - ECH10 | BV1: Force(N) - ECH10 | BW1: Def | BX1: Cont | BY1: Cont(max) | BZ1: Def rupt | CA1: E(mpa) | CC1: Elong.(mm) - ECH11 | CD1: Force(N) - ECH11 | CE1: Def | CF1: Cont | CG1: Cont(max) | CH1: Def rupt | CI1: E(mpa) | CK1: Elong.(mm) - ECH12 | CL1: Force(N) - ECH12 | CM1: Def | CN1: Cont | CO1: Cont(max) | CP1: Def rupt | CQ1: E(mpa) | CS1: Elong.(mm) - ECH13 | CT1: Force(N) - ECH13 | CU1: Def | CV1: Cont | CW1: Cont(max) | CX1: Def rupt | CY1: E(mpa) | DA1: Elong.(mm) - ECH14 | DB1: Force(N) - ECH14 | DC1: Def | DD1: Cont | DE1: Cont(max) | DF1: Def rupt | DG1: E(mpa) | DI1: Elong.(mm) - ECH15 | DJ1: Force(N) - ECH15 | DK1: Def | DL1: Cont | DM1: Cont(max) | DN1: Def rupt | DO1: E(mpa) | DQ1: Elong.(mm) - ECH16 | DR1: Force(N) - ECH16 | DS1: Def | DT1: Cont | DU1: Cont(max) | DV1: Def rupt | DW1: E(mpa) | DY1: Elong.(mm) - ECH17 | DZ1: Force(N) - ECH17 | EA1: Def | EB1: Cont | EC1: Cont(max) | ED1: Def rupt | EE1: E(mpa) | EG1: Elong.(mm) - ECH18 | EH1: Force(N) - ECH18 | EI1: Def | EJ1: Cont | EK1: Cont(max) | EL1: Def rupt | EM1: E(mpa) | EO1: Elong.(mm) - ECH19 | EP1: Force(N) - ECH19 | EQ1: Def | ER1: Cont | ES1: Cont(max) | ET1: Def rupt | EU1: E(mpa) | EW1: Elong.(mm) - ECH20 | EX1: Force(N) - ECH20 | EY1: Def | EZ1: Cont | FA1: Cont(max) | FB1: Def rupt | FC1: E(mpa) | FE1: Elong.(mm) - ECH21 | FF1: Force(N) - ECH21 | FG1: Def | FH1: Cont | FI1: Cont(max) | FJ1: Def rupt | FK1: E(mpa) | FM1: Elong.(mm) - ECH22 | FN1: Force(N) - ECH22 | FO1: Def | FP1: Cont | FQ1: Cont(max) | FR1: Def rupt | FS1: E(mpa)
A2: 0 | B2: 0 | C2: =A2/20 -> 0 | D2: =B2/'DIAMETRE (CR,CS)'!$N$3 -> 0 | E2: =MAX(D2:D17) -> 15.720869 | F2: =INDEX(C2:C17,MATCH(E2,D2:D17,0)) -> 0.04995 | G2: =SLOPE(D3:D12,C3:C12) -> 422.84782 | I2: 0 | J2: 0 | K2: =I2/20 -> 0 | L2: =J2/'DIAMETRE (CR,CS)'!$N$4 -> 0 | M2: =MAX(L2:L16) -> 18.971906 | N2: =INDEX(K2:K16,MATCH(M2,L2:L16,0)) -> 0.04185 | O2: =SLOPE(L3:L12,K3:K12) -> 612.3389 | Q2: 0 | R2: 0 | S2: =Q2/20 -> 0 | T2: =R2/'DIAMETRE (CR,CS)'!$N$5 -> 0 | U2: =MAX(T2:T14) -> 51.599359 | V2: =INDEX(S2:S14,MATCH(U2,T2:T14,0)) -> 0.0349 | W2: =SLOPE(T3:T11,S3:S11) -> 1923.5672 | Y2: 0 | Z2: 0 | AA2: =Y2/20 -> 0 | AB2: =Z2/'DIAMETRE (CR,CS)'!$N$6 -> 0 | AC2: =MAX(AB2:AB13) -> 360.66395 | AD2: =INDEX(AA2:AA13,MATCH(AC2,AB2:AB13,0)) -> 0.03135 | AE2: =SLOPE(AB3:AB10,AA3:AA10) -> 15131.257 | AG2: 0 | AH2: 0 | AI2: =AG2/20 -> 0 | AJ2: =AH2/'DIAMETRE (CR,CS)'!$N$7 -> 0 | AK2: =MAX(AJ2:AJ13) -> 68.6515 | AL2: =INDEX(AI2:AI13,MATCH(AK2,AJ2:AJ13,0)) -> 0.03605 | AM2: =SLOPE(AJ3:AJ11,AI3:AI11) -> 2448.4982 | AO2: 0 | AP2: 0 | AQ2: =AO2/20 -> 0 | AR2: =AP2/'DIAMETRE (CR,CS)'!$N$8 -> 0 | AS2: =MAX(AR2:AR14) -> 41.981176 | AT2: =INDEX(AQ2:AQ14,MATCH(AS2,AR2:AR14,0)) -> 0.03595 | AU2: =SLOPE(AR3:AR11,AQ3:AQ11) -> 1414.9227 | AW2: 0 | AX2: 0 | AY2: =AW2/20 -> 0 | AZ2: =AX2/'DIAMETRE (CR,CS)'!$N$9 -> 0 | BA2: =MAX(AZ2:AZ21) -> 11.616486 | BB2: =INDEX(AY2:AY21,MATCH(BA2,AZ2:AZ21,0)) -> 0.0675 | BC2: =SLOPE(AZ2:AZ11,AY2:AY11) -> 159.68738 | BE2: 0 | BF2: 0 | BG2: =BE2/20 -> 0 | BH2: =BF2/'DIAMETRE (CR,CS)'!$N$10 -> 0 | BI2: =MAX(BH2:BH10) -> 15.098917 | BJ2: =INDEX(BG2:BG10,MATCH(BI2,BH2:BH10,0)) -> 0.02285 | BK2: =SLOPE(BH3:BH7,BG3:BG7) -> 922.21893 | BM2: 0 | BN2: 0 | BO2: =BM2/20 -> 0 | BP2: =BN2/'DIAMETRE (CR,CS)'!$N$11 -> 0 | BQ2: =MAX(BP2:BP19) -> 879.78236 | BR2: =INDEX(BO2:BO19,MATCH(BQ2,BP2:BP19,0)) -> 0.05675 | BS2: =SLOPE(BP2:BP11,BO2:BO11) -> 18292.63 | BU2: 0 | BV2: 0 | BW2: =BU2/20 -> 0 | BX2: =BV2/'DIAMETRE (CR,CS)'!$N$12 -> 0 | BY2: =MAX(BX2:BX14) -> 68.73578 | BZ2: =INDEX(BW2:BW14,MATCH(BY2,BX2:BX14,0)) -> 0.03585 | CA2: =SLOPE(BX3:BX11,BW3:BW11) -> 2313.6453 | CC2: 0 | CD2: 0 | CE2: =CC2/20 -> 0 | CF2: =CD2/'DIAMETRE (CR,CS)'!$N$13 -> 0 | CG2: =MAX(CF2:CF16) -> 52.133155 | CH2: =INDEX(CE2:CE16,MATCH(CG2,CF2:CF16,0)) -> 0.0405 | CI2: =SLOPE(CF3:CF9,CE3:CE9) -> 2093.93 | CK2: 0 | CL2: 0 | CM2: =CK2/20 -> 0 | CN2: =CL2/'DIAMETRE (CR,CS)'!$N$14 -> 0 | CO2: =MAX(CN2:CN13) -> 56.347327 | CP2: =INDEX(CM2:CM13,MATCH(CO2,CN2:CN13,0)) -> 0.04085 | CQ2: =SLOPE(CN2:CN11,CM2:CM11) -> 1380.9072 | CS2: 0 | CT2: 0 | CU2: =CS2/20 -> 0 | CV2: =CT2/'DIAMETRE (CR,CS)'!$N$15 -> 0 | CW2: =MAX(CV2:CV11) -> 15.145314 | CX2: =INDEX(CU2:CU11,MATCH(CW2,CV2:CV11,0)) -> 0.03275 | CY2: =SLOPE(CV2:CV11,CU2:CU11) -> 483.74676 | DA2: 0 | DB2: 0 | DC2: =DA2/20 -> 0 | DD2: =DB2/'DIAMETRE (CR,CS)'!$N$16 -> 0 | DE2: =MAX(DD2:DD14) -> 9.6116063 | DF2: =INDEX(DC2:DC14,MATCH(DE2,DD2:DD14,0)) -> 0.034 | DG2: =SLOPE(DD3:DD11,DC3:DC11) -> 341.48345 | DI2: 0 | DJ2: 0 | DK2: =DI2/20 -> 0 | DL2: =DJ2/'DIAMETRE (CR,CS)'!$N$17 -> 0 | DM2: =MAX(DL2:DL10) -> 55.071886 | DN2: =INDEX(DK2:DK10,MATCH(DM2,DL2:DL10,0)) -> 0.0207 | DO2: =SLOPE(DL3:DL7,DK3:DK7) -> 3914.0947 | DQ2: 0 | DR2: 0 | DS2: =DQ2/20 -> 0 | DT2: =DR2/'DIAMETRE (CR,CS)'!$N$18 -> 0 | DU2: =MAX(DT2:DT13) -> 6.2016734 | DV2: =INDEX(DS2:DS13,MATCH(DU2,DT2:DT13,0)) -> 0.0326 | DW2: =SLOPE(DT3:DT10,DS3:DS10) -> 247.33842 | DY2: 0 | DZ2: 0 | EA2: =DY2/20 -> 0 | EB2: =DZ2/'DIAMETRE (CR,CS)'!$N$19 -> 0 | EC2: =MAX(EB2:EB13) -> 15.229906 | ED2: =INDEX(EA2:EA13,MATCH(EC2,EB2:EB13,0)) -> 0.03135 | EE2: =SLOPE(EB3:EB10,EA3:EA10) -> 645.34635 | EG2: 0 | EH2: 0 | EI2: =EG2/20 -> 0 | EJ2: =EH2/'DIAMETRE (CR,CS)'!$N$20 -> 0 | EK2: =MAX(EJ2:EJ16) -> 189.56215 | EL2: =INDEX(EI2:EI16,MATCH(EK2,EJ2:EJ16,0)) -> 0.0525 | EM2: =SLOPE(EJ2:EJ11,EI2:EI11) -> 4157.0268 | EO2: 0 | EP2: 0 | EQ2: =EO2/20 -> 0 | ER2: =EP2/'DIAMETRE (CR,CS)'!$N$21 -> 0 | ES2: =MAX(ER2:ER15) -> 3.2927108 | ET2: =INDEX(EQ2:EQ15,MATCH(ES2,ER2:ER15,0)) -> 0.0403 | EU2: =SLOPE(ER3:ER11,EQ3:EQ11) -> 113.16677 | EW2: 0 | EX2: 0 | EY2: =EW2/20 -> 0 | EZ2: =EX2/'DIAMETRE (CR,CS)'!$N$22 -> 0 | FA2: =MAX(EZ2:EZ12) -> 49.954635 | FB2: =INDEX(EY2:EY12,MATCH(FA2,EZ2:EZ12,0)) -> 0.03985 | FC2: =SLOPE(EZ5:EZ12,EY5:EY12) -> 1272.1985 | FE2: 0 | FF2: 0 | FG2: =FE2/20 -> 0 | FH2: =FF2/'DIAMETRE (CR,CS)'!$N$23 -> 0 | FI2: =MAX(FH2:FH12) -> 21.353473 | FJ2: =INDEX(FG2:FG12,MATCH(FI2,FH2:FH12,0)) -> 0.03055 | FK2: =SLOPE(FH3:FH9,FG3:FG9) -> 924.40875 | FM2: 0 | FN2: 0 | FO2: =FM2/20 -> 0 | FP2: =FN2/'DIAMETRE (CR,CS)'!$N$24 -> 0 | FQ2: =MAX(FP2:FP13) -> 179.25529 | FR2: =INDEX(FO2:FO13,MATCH(FQ2,FP2:FP13,0)) -> 0.02985 | FS2: =SLOPE(FP3:FP10,FO3:FO10) -> 7348.7803
A3: 0.277 | B3: 0.094 | C3: =A3/20 -> 0.01385 | D3: =B3/'DIAMETRE (CR,CS)'!$N$3 -> 0.91163585 | I3: 0.237 | J3: 0.13 | K3: =I3/20 -> 0.01185 | L3: =J3/'DIAMETRE (CR,CS)'!$N$4 -> 1.0141233 | Q3: 0.15 | R3: 0.172 | S3: =Q3/20 -> 0.0075 | T3: =R3/'DIAMETRE (CR,CS)'!$N$5 -> 2.7215853 | Y3: 0.155 | Z3: 0.113 | AA3: =Y3/20 -> 0.00775 | AB3: =Z3/'DIAMETRE (CR,CS)'!$N$6 -> 15.083281 | AG3: 0.15 | AH3: 0.155 | AI3: =AG3/20 -> 0.0075 | AJ3: =AH3/'DIAMETRE (CR,CS)'!$N$7 -> 2.8970821 | AO3: 0.145 | AP3: 0.162 | AQ3: =AO3/20 -> 0.00725 | AR3: =AP3/'DIAMETRE (CR,CS)'!$N$8 -> 2.6309287 | AW3: 0.081 | AX3: 0.089 | AY3: =AW3/20 -> 0.00405 | AZ3: =AX3/'DIAMETRE (CR,CS)'!$N$9 -> 0.76582761 | BE3: 0.161 | BF3: 0.126 | BG3: =BE3/20 -> 0.00805 | BH3: =BF3/'DIAMETRE (CR,CS)'!$N$10 -> 1.8434724 | BM3: 0.155 | BN3: 0.217 | BO3: =BM3/20 -> 0.00775 | BP3: =BN3/'DIAMETRE (CR,CS)'!$N$11 -> 40.43049 | BU3: 0.152 | BV3: 0.118 | BW3: =BU3/20 -> 0.0076 | BX3: =BV3/'DIAMETRE (CR,CS)'!$N$12 -> 6.0438316 | CC3: 0.201 | CD3: 0.199 | CE3: =CC3/20 -> 0.01005 | CF3: =CD3/'DIAMETRE (CR,CS)'!$N$13 -> 4.6273407 | CK3: 0.109 | CL3: 0.098 | CM3: =CK3/20 -> 0.00545 | CN3: =CL3/'DIAMETRE (CR,CS)'!$N$14 -> 7.1252104 | CS3: 0.142 | CT3: 0.069 | CU3: =CS3/20 -> 0.0071 | CV3: =CT3/'DIAMETRE (CR,CS)'!$N$15 -> 1.7772563 | DA3: 0.148 | DB3: 0.101 | DC3: =DA3/20 -> 0.0074 | DD3: =DB3/'DIAMETRE (CR,CS)'!$N$16 -> 0.83687262 | DI3: 0.15 | DJ3: 0.179 | DK3: =DI3/20 -> 0.0075 | DL3: =DJ3/'DIAMETRE (CR,CS)'!$N$17 -> 5.8330577 | DQ3: 0.152 | DR3: 0.059 | DS3: =DQ3/20 -> 0.0076 | DT3: =DR3/'DIAMETRE (CR,CS)'!$N$18 -> 0.3655332 | DY3: 0.152 | DZ3: 0.054 | EA3: =DY3/20 -> 0.0076 | EB3: =DZ3/'DIAMETRE (CR,CS)'!$N$19 -> 1.0041696 | EG3: 0.163 | EH3: 0.094 | EI3: =EG3/20 -> 0.00815 | EJ3: =EH3/'DIAMETRE (CR,CS)'!$N$20 -> 7.2670646 | EO3: 0.19 | EP3: 0.113 | EQ3: =EO3/20 -> 0.0095 | ER3: =EP3/'DIAMETRE (CR,CS)'!$N$21 -> 0.30103263 | EW3: 0.154 | EX3: 0.067 | EY3: =EW3/20 -> 0.0077 | EZ3: =EX3/'DIAMETRE (CR,CS)'!$N$22 -> 4.7273454 | FE3: 0.16 | FF3: 0.089 | FG3: =FE3/20 -> 0.008 | FH3: =FF3/'DIAMETRE (CR,CS)'!$N$23 -> 1.2789092 | FM3: 0.092 | FN3: 0.064 | FO3: =FM3/20 -> 0.0046 | FP3: =FN3/'DIAMETRE (CR,CS)'!$N$24 -> 9.6976658
A4: 0.343 | B4: 0.218 | C4: =A4/20 -> 0.01715 | D4: =B4/'DIAMETRE (CR,CS)'!$N$3 -> 2.1142193 | I4: 0.301 | J4: 0.32 | K4: =I4/20 -> 0.01505 | L4: =J4/'DIAMETRE (CR,CS)'!$N$4 -> 2.4963034 | Q4: 0.219 | R4: 0.434 | S4: =Q4/20 -> 0.01095 | T4: =R4/'DIAMETRE (CR,CS)'!$N$5 -> 6.867256 | Y4: 0.221 | Z4: 0.302 | AA4: =Y4/20 -> 0.01105 | AB4: =Z4/'DIAMETRE (CR,CS)'!$N$6 -> 40.31107 | AG4: 0.224 | AH4: 0.41 | AI4: =AG4/20 -> 0.0112 | AJ4: =AH4/'DIAMETRE (CR,CS)'!$N$7 -> 7.6632494 | AO4: 0.212 | AP4: 0.391 | AQ4: =AO4/20 -> 0.0106 | AR4: =AP4/'DIAMETRE (CR,CS)'!$N$8 -> 6.3499574 | AW4: 0.17 | AX4: 0.154 | AY4: =AW4/20 -> 0.0085 | AZ4: =AX4/'DIAMETRE (CR,CS)'!$N$9 -> 1.3251399 | BE4: 0.229 | BF4: 0.302 | BG4: =BE4/20 -> 0.01145 | BH4: =BF4/'DIAMETRE (CR,CS)'!$N$10 -> 4.4184814 | BM4: 0.219 | BN4: 0.53 | BO4: =BM4/20 -> 0.01095 | BP4: =BN4/'DIAMETRE (CR,CS)'!$N$11 -> 98.747279 | BU4: 0.222 | BV4: 0.268 | BW4: =BU4/20 -> 0.0111 | BX4: =BV4/'DIAMETRE (CR,CS)'!$N$12 -> 13.726668 | CC4: 0.267 | CD4: 0.464 | CE4: =CC4/20 -> 0.01335 | CF4: =CD4/'DIAMETRE (CR,CS)'!$N$13 -> 10.789377 | CK4: 0.207 | CL4: 0.161 | CM4: =CK4/20 -> 0.01035 | CN4: =CL4/'DIAMETRE (CR,CS)'!$N$14 -> 11.705703 | CS4: 0.211 | CT4: 0.121 | CU4: =CS4/20 -> 0.01055 | CV4: =CT4/'DIAMETRE (CR,CS)'!$N$15 -> 3.1166378 | DA4: 0.215 | DB4: 0.229 | DC4: =DA4/20 -> 0.01075 | DD4: =DB4/'DIAMETRE (CR,CS)'!$N$16 -> 1.8974637 | DI4: 0.215 | DJ4: 0.472 | DK4: =DI4/20 -> 0.01075 | DL4: =DJ4/'DIAMETRE (CR,CS)'!$N$17 -> 15.381024 | DQ4: 0.224 | DR4: 0.157 | DS4: =DQ4/20 -> 0.0112 | DT4: =DR4/'DIAMETRE (CR,CS)'!$N$18 -> 0.97269003 | DY4: 0.222 | DZ4: 0.145 | EA4: =DY4/20 -> 0.0111 | EB4: =DZ4/'DIAMETRE (CR,CS)'!$N$19 -> 2.6963814 | EG4: 0.229 | EH4: 0.238 | EI4: =EG4/20 -> 0.01145 | EJ4: =EH4/'DIAMETRE (CR,CS)'!$N$20 -> 18.399589 | EO4: 0.262 | EP4: 0.261 | EQ4: =EO4/20 -> 0.0131 | ER4: =EP4/'DIAMETRE (CR,CS)'!$N$21 -> 0.69530545 | EW4: 0.221 | EX4: 0.067 | EY4: =EW4/20 -> 0.01105 | EZ4: =EX4/'DIAMETRE (CR,CS)'!$N$22 -> 4.7273454 | FE4: 0.242 | FF4: 0.238 | FG4: =FE4/20 -> 0.0121 | FH4: =FF4/'DIAMETRE (CR,CS)'!$N$23 -> 3.4200044 | FM4: 0.186 | FN4: 0.189 | FO4: =FM4/20 -> 0.0093 | FP4: =FN4/'DIAMETRE (CR,CS)'!$N$24 -> 28.638419
A5: 0.407 | B5: 0.369 | C5: =A5/20 -> 0.02035 | D5: =B5/'DIAMETRE (CR,CS)'!$N$3 -> 3.5786556 | I5: 0.379 | J5: 0.559 | K5: =I5/20 -> 0.01895 | L5: =J5/'DIAMETRE (CR,CS)'!$N$4 -> 4.36073 | Q5: 0.219 | R5: 0.696 | S5: =Q5/20 -> 0.01095 | T5: =R5/'DIAMETRE (CR,CS)'!$N$5 -> 11.012927 | Y5: 0.283 | Z5: 0.562 | AA5: =Y5/20 -> 0.01415 | AB5: =Z5/'DIAMETRE (CR,CS)'!$N$6 -> 75.015965 | AG5: 0.282 | AH5: 0.741 | AI5: =AG5/20 -> 0.0141 | AJ5: =AH5/'DIAMETRE (CR,CS)'!$N$7 -> 13.849922 | AO5: 0.286 | AP5: 0.664 | AQ5: =AO5/20 -> 0.0143 | AR5: =AP5/'DIAMETRE (CR,CS)'!$N$8 -> 10.783559 | AW5: 0.235 | AX5: 0.233 | AY5: =AW5/20 -> 0.01175 | AZ5: =AX5/'DIAMETRE (CR,CS)'!$N$9 -> 2.0049195 | BE5: 0.3 | BF5: 0.54 | BG5: =BE5/20 -> 0.015 | BH5: =BF5/'DIAMETRE (CR,CS)'!$N$10 -> 7.9005959 | BM5: 0.285 | BN5: 0.919 | BO5: =BM5/20 -> 0.01425 | BP5: =BN5/'DIAMETRE (CR,CS)'!$N$11 -> 171.22405 | BU5: 0.285 | BV5: 0.442 | BW5: =BU5/20 -> 0.01425 | BX5: =BV5/'DIAMETRE (CR,CS)'!$N$12 -> 22.638759 | CC5: 0.333 | CD5: 0.758 | CE5: =CC5/20 -> 0.01665 | CF5: =CD5/'DIAMETRE (CR,CS)'!$N$13 -> 17.62575 | CK5: 0.27 | CL5: 0.232 | CM5: =CK5/20 -> 0.0135 | CN5: =CL5/'DIAMETRE (CR,CS)'!$N$14 -> 16.867845 | CS5: 0.263 | CT5: 0.193 | CU5: =CS5/20 -> 0.01315 | CV5: =CT5/'DIAMETRE (CR,CS)'!$N$15 -> 4.971166 | DA5: 0.299 | DB5: 0.385 | DC5: =DA5/20 -> 0.01495 | DD5: =DB5/'DIAMETRE (CR,CS)'!$N$16 -> 3.190059 | DI5: 0.28 | DJ5: 0.888 | DK5: =DI5/20 -> 0.014 | DL5: =DJ5/'DIAMETRE (CR,CS)'!$N$17 -> 28.93718 | DQ5: 0.29 | DR5: 0.288 | DS5: =DQ5/20 -> 0.0145 | DT5: =DR5/'DIAMETRE (CR,CS)'!$N$18 -> 1.7842976 | DY5: 0.282 | DZ5: 0.265 | EA5: =DY5/20 -> 0.0141 | EB5: =DZ5/'DIAMETRE (CR,CS)'!$N$19 -> 4.9278694 | EG5: 0.299 | EH5: 0.435 | EI5: =EG5/20 -> 0.01495 | EJ5: =EH5/'DIAMETRE (CR,CS)'!$N$20 -> 33.629501 | EO5: 0.325 | EP5: 0.418 | EQ5: =EO5/20 -> 0.01625 | ER5: =EP5/'DIAMETRE (CR,CS)'!$N$21 -> 1.1135543 | EW5: 0.221 | EX5: 0.211 | EY5: =EW5/20 -> 0.01105 | EZ5: =EX5/'DIAMETRE (CR,CS)'!$N$22 -> 14.88761 | FE5: 0.311 | FF5: 0.435 | FG5: =FE5/20 -> 0.01555 | FH5: =FF5/'DIAMETRE (CR,CS)'!$N$23 -> 6.2508484 | FM5: 0.263 | FN5: 0.364 | FO5: =FM5/20 -> 0.01315 | FP5: =FN5/'DIAMETRE (CR,CS)'!$N$24 -> 55.155474
A6: 0.49 | B6: 0.55 | C6: =A6/20 -> 0.0245 | D6: =B6/'DIAMETRE (CR,CS)'!$N$3 -> 5.3340395 | I6: 0.449 | J6: 0.856 | K6: =I6/20 -> 0.02245 | L6: =J6/'DIAMETRE (CR,CS)'!$N$4 -> 6.6776116 | Q6: 0.34 | R6: 1.134 | S6: =Q6/20 -> 0.017 | T6: =R6/'DIAMETRE (CR,CS)'!$N$5 -> 17.943475 | Y6: 0.345 | Z6: 0.903 | AA6: =Y6/20 -> 0.01725 | AB6: =Z6/'DIAMETRE (CR,CS)'!$N$6 -> 120.53277 | AG6: 0.342 | AH6: 1.163 | AI6: =AG6/20 -> 0.0171 | AJ6: =AH6/'DIAMETRE (CR,CS)'!$N$7 -> 21.737461 | AO6: 0.372 | AP6: 1.015 | AQ6: =AO6/20 -> 0.0186 | AR6: =AP6/'DIAMETRE (CR,CS)'!$N$8 -> 16.483905 | AW6: 0.314 | AX6: 0.304 | AY6: =AW6/20 -> 0.0157 | AZ6: =AX6/'DIAMETRE (CR,CS)'!$N$9 -> 2.6158606 | BE6: 0.384 | BF6: 0.841 | BG6: =BE6/20 -> 0.0192 | BH6: =BF6/'DIAMETRE (CR,CS)'!$N$10 -> 12.304447 | BM6: 0.345 | BN6: 1.369 | BO6: =BM6/20 -> 0.01725 | BP6: =BN6/'DIAMETRE (CR,CS)'!$N$11 -> 255.06608 | BU6: 0.343 | BV6: 0.629 | BW6: =BU6/20 -> 0.01715 | BX6: =BV6/'DIAMETRE (CR,CS)'!$N$12 -> 32.216695 | CC6: 0.387 | CD6: 1.079 | CE6: =CC6/20 -> 0.01935 | CF6: =CD6/'DIAMETRE (CR,CS)'!$N$13 -> 25.089953 | CK6: 0.341 | CL6: 0.301 | CM6: =CK6/20 -> 0.01705 | CN6: =CL6/'DIAMETRE (CR,CS)'!$N$14 -> 21.884575 | CS6: 0.335 | CT6: 0.243 | CU6: =CS6/20 -> 0.01675 | CV6: =CT6/'DIAMETRE (CR,CS)'!$N$15 -> 6.2590329 | DA6: 0.34 | DB6: 0.564 | DC6: =DA6/20 -> 0.017 | DD6: =DB6/'DIAMETRE (CR,CS)'!$N$16 -> 4.6732293 | DI6: 0.351 | DJ6: 1.432 | DK6: =DI6/20 -> 0.01755 | DL6: =DJ6/'DIAMETRE (CR,CS)'!$N$17 -> 46.664462 | DQ6: 0.365 | DR6: 0.454 | DS6: =DQ6/20 -> 0.01825 | DT6: =DR6/'DIAMETRE (CR,CS)'!$N$18 -> 2.812747 | DY6: 0.342 | DZ6: 0.398 | EA6: =DY6/20 -> 0.0171 | EB6: =DZ6/'DIAMETRE (CR,CS)'!$N$19 -> 7.401102 | EG6: 0.36 | EH6: 0.665 | EI6: =EG6/20 -> 0.018 | EJ6: =EH6/'DIAMETRE (CR,CS)'!$N$20 -> 51.410617 | EO6: 0.395 | EP6: 0.609 | EQ6: =EO6/20 -> 0.01975 | ER6: =EP6/'DIAMETRE (CR,CS)'!$N$21 -> 1.6223794 | EW6: 0.365 | EX6: 0.288 | EY6: =EW6/20 -> 0.01825 | EZ6: =EX6/'DIAMETRE (CR,CS)'!$N$22 -> 20.32053 | FE6: 0.39 | FF6: 0.683 | FG6: =FE6/20 -> 0.0195 | FH6: =FF6/'DIAMETRE (CR,CS)'!$N$23 -> 9.8145505 | FM6: 0.337 | FN6: 0.57 | FO6: =FM6/20 -> 0.01685 | FP6: =FN6/'DIAMETRE (CR,CS)'!$N$24 -> 86.369836
A7: 0.565 | B7: 0.76 | C7: =A7/20 -> 0.02825 | D7: =B7/'DIAMETRE (CR,CS)'!$N$3 -> 7.3706728 | I7: 0.51 | J7: 1.192 | K7: =I7/20 -> 0.0255 | L7: =J7/'DIAMETRE (CR,CS)'!$N$4 -> 9.2987301 | Q7: 0.41 | R7: 1.672 | S7: =Q7/20 -> 0.0205 | T7: =R7/'DIAMETRE (CR,CS)'!$N$5 -> 26.456341 | Y7: 0.422 | Z7: 1.356 | AA7: =Y7/20 -> 0.0211 | AB7: =Z7/'DIAMETRE (CR,CS)'!$N$6 -> 180.99938 | AG7: 0.435 | AH7: 1.721 | AI7: =AG7/20 -> 0.02175 | AJ7: =AH7/'DIAMETRE (CR,CS)'!$N$7 -> 32.166957 | AO7: 0.44 | AP7: 1.425 | AQ7: =AO7/20 -> 0.022 | AR7: =AP7/'DIAMETRE (CR,CS)'!$N$8 -> 23.142428 | AW7: 0.385 | AX7: 0.367 | AY7: =AW7/20 -> 0.01925 | AZ7: =AX7/'DIAMETRE (CR,CS)'!$N$9 -> 3.1579633 | BE7: 0.457 | BF7: 1.032 | BG7: =BE7/20 -> 0.02285 | BH7: =BF7/'DIAMETRE (CR,CS)'!$N$10 -> 15.098917 | BM7: 0.426 | BN7: 1.888 | BO7: =BM7/20 -> 0.0213 | BP7: =BN7/'DIAMETRE (CR,CS)'!$N$11 -> 351.76389 | BU7: 0.42 | BV7: 0.849 | BW7: =BU7/20 -> 0.021 | BX7: =BV7/'DIAMETRE (CR,CS)'!$N$12 -> 43.484856 | CC7: 0.45 | CD7: 1.435 | CE7: =CC7/20 -> 0.0225 | CF7: =CD7/'DIAMETRE (CR,CS)'!$N$13 -> 33.36801 | CK7: 0.41 | CL7: 0.363 | CM7: =CK7/20 -> 0.0205 | CN7: =CL7/'DIAMETRE (CR,CS)'!$N$14 -> 26.392361 | CS7: 0.385 | CT7: 0.308 | CU7: =CS7/20 -> 0.01925 | CV7: =CT7/'DIAMETRE (CR,CS)'!$N$15 -> 7.9332598 | DA7: 0.42 | DB7: 0.753 | DC7: =DA7/20 -> 0.021 | DD7: =DB7/'DIAMETRE (CR,CS)'!$N$16 -> 6.2392582 | DI7: 0.414 | DJ7: 1.69 | DK7: =DI7/20 -> 0.0207 | DL7: =DJ7/'DIAMETRE (CR,CS)'!$N$17 -> 55.071886 | DQ7: 0.437 | DR7: 0.633 | DS7: =DQ7/20 -> 0.02185 | DT7: =DR7/'DIAMETRE (CR,CS)'!$N$18 -> 3.9217375 | DY7: 0.427 | DZ7: 0.557 | EA7: =DY7/20 -> 0.02135 | EB7: =DZ7/'DIAMETRE (CR,CS)'!$N$19 -> 10.357824 | EG7: 0.418 | EH7: 0.925 | EI7: =EG7/20 -> 0.0209 | EJ7: =EH7/'DIAMETRE (CR,CS)'!$N$20 -> 71.511008 | EO7: 0.48 | EP7: 0.824 | EQ7: =EO7/20 -> 0.024 | ER7: =EP7/'DIAMETRE (CR,CS)'!$N$21 -> 2.1951406 | EW7: 0.442 | EX7: 0.346 | EY7: =EW7/20 -> 0.0221 | EZ7: =EX7/'DIAMETRE (CR,CS)'!$N$22 -> 24.412859 | FE7: 0.469 | FF7: 0.993 | FG7: =FE7/20 -> 0.02345 | FH7: =FF7/'DIAMETRE (CR,CS)'!$N$23 -> 14.269178 | FM7: 0.407 | FN7: 0.795 | FO7: =FM7/20 -> 0.02035 | FP7: =FN7/'DIAMETRE (CR,CS)'!$N$24 -> 120.46319
A8: 0.651 | B8: 0.903 | C8: =A8/20 -> 0.03255 | D8: =B8/'DIAMETRE (CR,CS)'!$N$3 -> 8.7575231 | I8: 0.582 | J8: 1.452 | K8: =I8/20 -> 0.0291 | L8: =J8/'DIAMETRE (CR,CS)'!$N$4 -> 11.326977 | Q8: 0.475 | R8: 2.136 | S8: =Q8/20 -> 0.02375 | T8: =R8/'DIAMETRE (CR,CS)'!$N$5 -> 33.798292 | Y8: 0.485 | Z8: 1.782 | AA8: =Y8/20 -> 0.02425 | AB8: =Z8/'DIAMETRE (CR,CS)'!$N$6 -> 237.86201 | AG8: 0.507 | AH8: 2.266 | AI8: =AG8/20 -> 0.02535 | AJ8: =AH8/'DIAMETRE (CR,CS)'!$N$7 -> 42.353471 | AO8: 0.44 | AP8: 1.672 | AQ8: =AO8/20 -> 0.022 | AR8: =AP8/'DIAMETRE (CR,CS)'!$N$8 -> 27.153782 | AW8: 0.448 | AX8: 0.434 | AY8: =AW8/20 -> 0.0224 | AZ8: =AX8/'DIAMETRE (CR,CS)'!$N$9 -> 3.7344852 | BE8: 0.527 | BF8: 0.91 | BG8: =BE8/20 -> 0.02635 | BH8: =BF8/'DIAMETRE (CR,CS)'!$N$10 -> 13.313967 | BM8: 0.495 | BN8: 2.229 | BO8: =BM8/20 -> 0.02475 | BP8: =BN8/'DIAMETRE (CR,CS)'!$N$11 -> 415.29752 | BU8: 0.499 | BV8: 0.984 | BW8: =BU8/20 -> 0.02495 | BX8: =BV8/'DIAMETRE (CR,CS)'!$N$12 -> 50.399409 | CC8: 0.51 | CD8: 1.624 | CE8: =CC8/20 -> 0.0255 | CF8: =CD8/'DIAMETRE (CR,CS)'!$N$13 -> 37.762821 | CK8: 0.472 | CL8: 0.436 | CM8: =CK8/20 -> 0.0236 | CN8: =CL8/'DIAMETRE (CR,CS)'!$N$14 -> 31.699915 | CS8: 0.45 | CT8: 0.392 | CU8: =CS8/20 -> 0.0225 | CV8: =CT8/'DIAMETRE (CR,CS)'!$N$15 -> 10.096876 | DA8: 0.495 | DB8: 0.866 | DC8: =DA8/20 -> 0.02475 | DD8: =DB8/'DIAMETRE (CR,CS)'!$N$16 -> 7.1755613 | DI8: 0.5 | DJ8: 1.513 | DK8: =DI8/20 -> 0.025 | DL8: =DJ8/'DIAMETRE (CR,CS)'!$N$17 -> 49.304002 | DQ8: 0.504 | DR8: 0.778 | DS8: =DQ8/20 -> 0.0252 | DT8: =DR8/'DIAMETRE (CR,CS)'!$N$18 -> 4.8200818 | DY8: 0.495 | DZ8: 0.682 | EA8: =DY8/20 -> 0.02475 | EB8: =DZ8/'DIAMETRE (CR,CS)'!$N$19 -> 12.68229 | EG8: 0.502 | EH8: 1.133 | EI8: =EG8/20 -> 0.0251 | EJ8: =EH8/'DIAMETRE (CR,CS)'!$N$20 -> 87.591322 | EO8: 0.545 | EP8: 0.962 | EQ8: =EO8/20 -> 0.02725 | ER8: =EP8/'DIAMETRE (CR,CS)'!$N$21 -> 2.5627733 | EW8: 0.5 | EX8: 0.428 | EY8: =EW8/20 -> 0.025 | EZ8: =EX8/'DIAMETRE (CR,CS)'!$N$22 -> 30.198565 | FE8: 0.545 | FF8: 1.27 | FG8: =FE8/20 -> 0.02725 | FH8: =FF8/'DIAMETRE (CR,CS)'!$N$23 -> 18.249603 | FM8: 0.474 | FN8: 0.994 | FO8: =FM8/20 -> 0.0237 | FP8: =FN8/'DIAMETRE (CR,CS)'!$N$24 -> 150.61687
